efault","exc_info":"Traceback (most recent call last):\n  File \"/usr/local/lib/python3.9/site-packages/apscheduler/executors/base.py\", line 125, in run_job\n    retval = job.func(*job.args, **job.kwargs)\n  File \"/src/ericsson/server/monitor/features.py\", line 311, in monitor\n    for server_id, status in get_server_status(session, server_url, timeout=timeout):\n  File \"/src/ericsson/server/monitor/utils.py\", line 62, in get_server_status\n    resp.raise_for_status()\n  File \"/usr/local/lib/python3.9/site-packages/requests/models.py\", line 1021, in raise_for_status\n    raise HTTPError(http_error_msg, response=self)\nrequests.exceptions.HTTPError: 503 Server Error: Service Unavailable for url: http://server-api:8001/api/servers?fields=status","host":"server-monitor-7f8444fd47-gblcm","pname":"server-monitor","file":{"name":"base.py","line":131}}
{"time":"2024-02-01T20:59:53.922Z","msg":"An error occurred while fetching server statuses","pid":1,"tid":140175485155072,"pri":"WARN","tname":"ThreadPoolExecutor-0_0","subsys":"ericsson.server.monitor.utils","exc_info":"Traceback (most recent call last):\n  File \"/src/ericsson/server/monitor/utils.py\", line 62, in get_server_status\n    resp.raise_for_status()\n  File \"/usr/local/lib/python3.9/site-packages/requests/models.py\", line 1021, in raise_for_status\n    raise HTTPError(http_error_msg, response=self)\nrequests.exceptions.HTTPError: 503 Server Error: Service Unavailable for url: http://server-api:8001/api/servers?fields=status","host":"server-monitor-7f8444fd47-gblcm","pname":"server-monitor","file":{"name":"utils.py","line":66}}
{"time":"2024-02-01T20:59:53.923Z","msg":"Job \"monitor (trigger: interval[0:00:01], next run at: 2024-02-01 20:59:54 UTC)\" raised an exception","pid":1,"tid":140175485155072,"pri":"ERROR","tname":"ThreadPoolExecutor-0_0","subsys":"apscheduler.executors.default","exc_info":"Traceback (most recent call last):\n  File \"/usr/local/lib/python3.9/site-packages/apscheduler/executors/base.py\", line 125, in run_job\n    retval = job.func(*job.args, **job.kwargs)\n  File \"/src/ericsson/server/monitor/features.py\", line 311, in monitor\n    for server_id, status in get_server_status(session, server_url, timeout=timeout):\n  File \"/src/ericsson/server/monitor/utils.py\", line 62, in get_server_status\n    resp.raise_for_status()\n  File \"/usr/local/lib/python3.9/site-packages/requests/models.py\", line 1021, in raise_for_status\n    raise HTTPError(http_error_msg, response=self)\nrequests.exceptions.HTTPError: 503 Server Error: Service Unavailable for url: http://server-api:8001/api/servers?fields=status","host":"server-monitor-7f8444fd47-gblcm","pname":"server-monitor","file":{"name":"base.py","line":131}}
{"time":"2024-02-01T20:59:54.922Z","msg":"An error occurred while fetching server statuses","pid":1,"tid":140175476762368,"pri":"WARN","tname":"ThreadPoolExecutor-0_1","subsys":"ericsson.server.monitor.utils","exc_info":"Traceback (most recent call last):\n  File \"/src/ericsson/server/monitor/utils.py\", line 62, in get_server_status\n    resp.raise_for_status()\n  File \"/usr/local/lib/python3.9/site-packages/requests/models.py\", line 1021, in raise_for_status\n    raise HTTPError(http_error_msg, response=self)\nrequests.exceptions.HTTPError: 503 Server Error: Service Unavailable for url: http://server-api:8001/api/servers?fields=status","host":"server-monitor-7f8444fd47-gblcm","pname":"server-monitor","file":{"name":"utils.py","line":66}}
{"time":"2024-02-01T20:59:54.923Z","msg":"Job \"monitor (trigger: interval[0:00:01], next run at: 2024-02-01 20:59:55 UTC)\" raised an exception","pid":1,"tid":140175476762368,"pri":"ERROR","tname":"ThreadPoolExecutor-0_1","subsys":"apscheduler.executors.default","exc_info":"Traceback (most recent call last):\n  File \"/usr/local/lib/python3.9/site-packages/apscheduler/executors/base.py\", line 125, in run_job\n    retval = job.func(*job.args, **job.kwargs)\n  File \"/src/ericsson/server/monitor/features.py\", line 311, in monitor\n    for server_id, status in get_server_status(session, server_url, timeout=timeout):\n  File \"/src/ericsson/server/monitor/utils.py\", line 62, in get_server_status\n    resp.raise_for_status()\n  File \"/usr/local/lib/python3.9/site-packages/requests/models.py\", line 1021, in raise_for_status\n    raise HTTPError(http_error_msg, response=self)\nrequests.exceptions.HTTPError: 503 Server Error: Service Unavailable for url: http://server-api:8001/api/servers?fields=status","host":"server-monitor-7f8444fd47-gblcm","pname":"server-monitor","file":{"name":"base.py","line":131}}
{"time":"2024-02-01T20:59:55.921Z","msg":"An error occurred while fetching server statuses","pid":1,"tid":140175485155072,"pri":"WARN","tname":"ThreadPoolExecutor-0_0","subsys":"ericsson.server.monitor.utils","exc_info":"Traceback (most recent call last):\n  File \"/src/ericsson/server/monitor/utils.py\", line 62, in get_server_status\n    resp.raise_for_status()\n  File \"/usr/local/lib/python3.9/site-packages/requests/models.py\", line 1021, in raise_for_status\n    raise HTTPError(http_error_msg, response=self)\nrequests.exceptions.HTTPError: 503 Server Error: Service Unavailable for url: http://server-api:8001/api/servers?fields=status","host":"server-monitor-7f8444fd47-gblcm","pname":"server-monitor","file":{"name":"utils.py","line":66}}
{"time":"2024-02-01T20:59:55.922Z","msg":"Job \"monitor (trigger: interval[0:00:01], next run at: 2024-02-01 20:59:56 UTC)\" raised an exception","pid":1,"tid":140175485155072,"pri":"ERROR","tname":"ThreadPoolExecutor-0_0","subsys":"apscheduler.executors.default","exc_info":"Traceback (most recent call last):\n  File \"/usr/local/lib/python3.9/site-packages/apscheduler/executors/base.py\", line 125, in run_job\n    retval = job.func(*job.args, **job.kwargs)\n  File \"/src/ericsson/server/monitor/features.py\", line 311, in monitor\n    for server_id, status in get_server_status(session, server_url, timeout=timeout):\n  File \"/src/ericsson/server/monitor/utils.py\", line 62, in get_server_status\n    resp.raise_for_status()\n  File \"/usr/local/lib/python3.9/site-packages/requests/models.py\", line 1021, in raise_for_status\n    raise HTTPError(http_error_msg, response=self)\nrequests.exceptions.HTTPError: 503 Server Error: Service Unavailable for url: http://server-api:8001/api/servers?fields=status","host":"server-monitor-7f8444fd47-gblcm","pname":"server-monitor","file":{"name":"base.py","line":131}}
{"time":"2024-02-01T20:59:56.922Z","msg":"An error occurred while fetching server statuses","pid":1,"tid":140175476762368,"pri":"WARN","tname":"ThreadPoolExecutor-0_1","subsys":"ericsson.server.monitor.utils","exc_info":"Traceback (most recent call last):\n  File \"/src/ericsson/server/monitor/utils.py\", line 62, in get_server_status\n    resp.raise_for_status()\n  File \"/usr/local/lib/python3.9/site-packages/requests/models.py\", line 1021, in raise_for_status\n    raise HTTPError(http_error_msg, response=self)\nrequests.exceptions.HTTPError: 503 Server Error: Service Unavailable for url: http://server-api:8001/api/servers?fields=status","host":"server-monitor-7f8444fd47-gblcm","pname":"server-monitor","file":{"name":"utils.py","line":66}}
{"time":"2024-02-01T20:59:56.922Z","msg":"Job \"monitor (trigger: interval[0:00:01], next run at: 2024-02-01 20:59:57 UTC)\" raised an exception","pid":1,"tid":140175476762368,"pri":"ERROR","tname":"ThreadPoolExecutor-0_1","subsys":"apscheduler.executors.default","exc_info":"Traceback (most recent call last):\n  File \"/usr/local/lib/python3.9/site-packages/apscheduler/executors/base.py\", line 125, in run_job\n    retval = job.func(*job.args, **job.kwargs)\n  File \"/src/ericsson/server/monitor/features.py\", line 311, in monitor\n    for server_id, status in get_server_status(session, server_url, timeout=timeout):\n  File \"/src/ericsson/server/monitor/utils.py\", line 62, in get_server_status\n    resp.raise_for_status()\n  File \"/usr/local/lib/python3.9/site-packages/requests/models.py\", line 1021, in raise_for_status\n    raise HTTPError(http_error_msg, response=self)\nrequests.exceptions.HTTPError: 503 Server Error: Service Unavailable for url: http://server-api:8001/api/servers?fields=status","host":"server-monitor-7f8444fd47-gblcm","pname":"server-monitor","file":{"name":"base.py","line":131}}
{"time":"2024-02-01T20:59:57.921Z","msg":"An error occurred while fetching server statuses","pid":1,"tid":140175485155072,"pri":"WARN","tname":"ThreadPoolExecutor-0_0","subsys":"ericsson.server.monitor.utils","exc_info":"Traceback (most recent call last):\n  File \"/src/ericsson/server/monitor/utils.py\", line 62, in get_server_status\n    resp.raise_for_status()\n  File \"/usr/local/lib/python3.9/site-packages/requests/models.py\", line 1021, in raise_for_status\n    raise HTTPError(http_error_msg, response=self)\nrequests.exceptions.HTTPError: 503 Server Error: Service Unavailable for url: http://server-api:8001/api/servers?fields=status","host":"server-monitor-7f8444fd47-gblcm","pname":"server-monitor","file":{"name":"utils.py","line":66}}
{"time":"2024-02-01T20:59:57.922Z","msg":"Job \"monitor (trigger: interval[0:00:01], next run at: 2024-02-01 20:59:58 UTC)\" raised an exception","pid":1,"tid":140175485155072,"pri":"ERROR","tname":"ThreadPoolExecutor-0_0","subsys":"apscheduler.executors.default","exc_info":"Traceback (most recent call last):\n  File \"/usr/local/lib/python3.9/site-packages/apscheduler/executors/base.py\", line 125, in run_job\n    retval = job.func(*job.args, **job.kwargs)\n  File \"/src/ericsson/server/monitor/features.py\", line 311, in monitor\n    for server_id, status in get_server_status(session, server_url, timeout=timeout):\n  File \"/src/ericsson/server/monitor/utils.py\", line 62, in get_server_status\n    resp.raise_for_status()\n  File \"/usr/local/lib/python3.9/site-packages/requests/models.py\", line 1021, in raise_for_status\n    raise HTTPError(http_error_msg, response=self)\nrequests.exceptions.HTTPError: 503 Server Error: Service Unavailable for url: http://server-api:8001/api/servers?fields=status","host":"server-monitor-7f8444fd47-gblcm","pname":"server-monitor","file":{"name":"base.py","line":131}}
{"time":"2024-02-01T20:59:58.923Z","msg":"An error occurred while fetching server statuses","pid":1,"tid":140175476762368,"pri":"WARN","tname":"ThreadPoolExecutor-0_1","subsys":"ericsson.server.monitor.utils","exc_info":"Traceback (most recent call last):\n  File \"/src/ericsson/server/monitor/utils.py\", line 62, in get_server_status\n    resp.raise_for_status()\n  File \"/usr/local/lib/python3.9/site-packages/requests/models.py\", line 1021, in raise_for_status\n    raise HTTPError(http_error_msg, response=self)\nrequests.exceptions.HTTPError: 503 Server Error: Service Unavailable for url: http://server-api:8001/api/servers?fields=status","host":"server-monitor-7f8444fd47-gblcm","pname":"server-monitor","file":{"name":"utils.py","line":66}}
{"time":"2024-02-01T20:59:58.923Z","msg":"Job \"monitor (trigger: interval[0:00:01], next run at: 2024-02-01 20:59:59 UTC)\" raised an exception","pid":1,"tid":140175476762368,"pri":"ERROR","tname":"ThreadPoolExecutor-0_1","subsys":"apscheduler.executors.default","exc_info":"Traceback (most recent call last):\n  File \"/usr/local/lib/python3.9/site-packages/apscheduler/executors/base.py\", line 125, in run_job\n    retval = job.func(*job.args, **job.kwargs)\n  File \"/src/ericsson/server/monitor/features.py\", line 311, in monitor\n    for server_id, status in get_server_status(session, server_url, timeout=timeout):\n  File \"/src/ericsson/server/monitor/utils.py\", line 62, in get_server_status\n    resp.raise_for_status()\n  File \"/usr/local/lib/python3.9/site-packages/requests/models.py\", line 1021, in raise_for_status\n    raise HTTPError(http_error_msg, response=self)\nrequests.exceptions.HTTPError: 503 Server Error: Service Unavailable for url: http://server-api:8001/api/servers?fields=status","host":"server-monitor-7f8444fd47-gblcm","pname":"server-monitor","file":{"name":"base.py","line":131}}
{"time":"2024-02-01T20:59:59.921Z","msg":"An error occurred while fetching server statuses","pid":1,"tid":140175476762368,"pri":"WARN","tname":"ThreadPoolExecutor-0_1","subsys":"ericsson.server.monitor.utils","exc_info":"Traceback (most recent call last):\n  File \"/src/ericsson/server/monitor/utils.py\", line 62, in get_server_status\n    resp.raise_for_status()\n  File \"/usr/local/lib/python3.9/site-packages/requests/models.py\", line 1021, in raise_for_status\n    raise HTTPError(http_error_msg, response=self)\nrequests.exceptions.HTTPError: 503 Server Error: Service Unavailable for url: http://server-api:8001/api/servers?fields=status","host":"server-monitor-7f8444fd47-gblcm","pname":"server-monitor","file":{"name":"utils.py","line":66}}
{"time":"2024-02-01T20:59:59.921Z","msg":"Job \"monitor (trigger: interval[0:00:01], next run at: 2024-02-01 21:00:00 UTC)\" raised an exception","pid":1,"tid":140175476762368,"pri":"ERROR","tname":"ThreadPoolExecutor-0_1","subsys":"apscheduler.executors.default","exc_info":"Traceback (most recent call last):\n  File \"/usr/local/lib/python3.9/site-packages/apscheduler/executors/base.py\", line 125, in run_job\n    retval = job.func(*job.args, **job.kwargs)\n  File \"/src/ericsson/server/monitor/features.py\", line 311, in monitor\n    for server_id, status in get_server_status(session, server_url, timeout=timeout):\n  File \"/src/ericsson/server/monitor/utils.py\", line 62, in get_server_status\n    resp.raise_for_status()\n  File \"/usr/local/lib/python3.9/site-packages/requests/models.py\", line 1021, in raise_for_status\n    raise HTTPError(http_error_msg, response=self)\nrequests.exceptions.HTTPError: 503 Server Error: Service Unavailable for url: http://server-api:8001/api/servers?fields=status","host":"server-monitor-7f8444fd47-gblcm","pname":"server-monitor","file":{"name":"base.py","line":131}}
{"time":"2024-02-01T21:00:00.922Z","msg":"An error occurred while fetching server statuses","pid":1,"tid":140175485155072,"pri":"WARN","tname":"ThreadPoolExecutor-0_0","subsys":"ericsson.server.monitor.utils","exc_info":"Traceback (most recent call last):\n  File \"/src/ericsson/server/monitor/utils.py\", line 62, in get_server_status\n    resp.raise_for_status()\n  File \"/usr/local/lib/python3.9/site-packages/requests/models.py\", line 1021, in raise_for_status\n    raise HTTPError(http_error_msg, response=self)\nrequests.exceptions.HTTPError: 503 Server Error: Service Unavailable for url: http://server-api:8001/api/servers?fields=status","host":"server-monitor-7f8444fd47-gblcm","pname":"server-monitor","file":{"name":"utils.py","line":66}}
{"time":"2024-02-01T21:00:00.922Z","msg":"Job \"monitor (trigger: interval[0:00:01], next run at: 2024-02-01 21:00:01 UTC)\" raised an exception","pid":1,"tid":140175485155072,"pri":"ERROR","tname":"ThreadPoolExecutor-0_0","subsys":"apscheduler.executors.default","exc_info":"Traceback (most recent call last):\n  File \"/usr/local/lib/python3.9/site-packages/apscheduler/executors/base.py\", line 125, in run_job\n    retval = job.func(*job.args, **job.kwargs)\n  File \"/src/ericsson/server/monitor/features.py\", line 311, in monitor\n    for server_id, status in get_server_status(session, server_url, timeout=timeout):\n  File \"/src/ericsson/server/monitor/utils.py\", line 62, in get_server_status\n    resp.raise_for_status()\n  File \"/usr/local/lib/python3.9/site-packages/requests/models.py\", line 1021, in raise_for_status\n    raise HTTPError(http_error_msg, response=self)\nrequests.exceptions.HTTPError: 503 Server Error: Service Unavailable for url: http://server-api:8001/api/servers?fields=status","host":"server-monitor-7f8444fd47-gblcm","pname":"server-monitor","file":{"name":"base.py","line":131}}
{"time":"2024-02-01T21:00:01.921Z","msg":"An error occurred while fetching server statuses","pid":1,"tid":140175476762368,"pri":"WARN","tname":"ThreadPoolExecutor-0_1","subsys":"ericsson.server.monitor.utils","exc_info":"Traceback (most recent call last):\n  File \"/src/ericsson/server/monitor/utils.py\", line 62, in get_server_status\n    resp.raise_for_status()\n  File \"/usr/local/lib/python3.9/site-packages/requests/models.py\", line 1021, in raise_for_status\n    raise HTTPError(http_error_msg, response=self)\nreques{"time":"2024-02-01T20:59:05.542Z","msg":"Configuration: {'alarm.publisher_id': 'server-monitor', 'alarm.resync_attempt_interval': '5', 'alarm.resync_interval': '30', 'api.server_url': 'http://server-api:8001/api/servers', 'api.timeout': '2', 'api.wait_on_error': '30', 'general.exclude_itself': 'False', 'general.ready_file_path': '/var/run/ericsson/server-monitor/ready', 'general.server_id': '', 'messaging.config': '/src/ericsson/server/monitor/data/default_message_types.json', 'messaging.server_url': 'amqp://guest:guest@rabbitmq-ha:5672/?heartbeat=30', 'mongolock.collection': 'server-monitor', 'mongolock.db': 'mediakindMongolock', 'mongolock.key': 'server-monitor', 'mongolock.owner': 'server-monitor', 'storage.host': 'localhost', 'storage.name': 'envivioCluster', 'storage.port': '27017', 'storage.url': 'mongodb://10.69.8.31:27017,10.69.8.32:27017/envivioCluster?replicaSet=repldb', 'storage_lock.alias': 'mediakindMongolock', 'storage_lock.host': 'localhost', 'storage_lock.port': '27017', 'storage_lock.url': 'mongodb://10.69.8.31:27017,10.69.8.32:27017/mediakindMongolock?replicaSet=repldb', 'storage_lock.username': 'MediaKind', 'time.interval': '1', 'time.readiness_interval': '5'}","pid":1,"tid":140176351019264,"pri":"INFO","tname":"MainThread","subsys":"ericsson.server.monitor.app","host":"server-monitor-7f8444fd47-gblcm","pname":"server-monitor","file":{"name":"app.py","line":192}}
{"time":"2024-02-01T20:59:05.543Z","msg":"Connecting to MongoDB...","pid":1,"tid":140176351019264,"pri":"INFO","tname":"MainThread","subsys":"ericsson.server.monitor.app","host":"server-monitor-7f8444fd47-gblcm","pname":"server-monitor","file":{"name":"app.py","line":215}}
{"time":"2024-02-01T20:59:07.727Z","msg":"Failed to connect to mongodb, retry in 1 second(s)","pid":1,"tid":140176351019264,"pri":"WARN","tname":"MainThread","subsys":"ericsson.mongo.connection","host":"server-monitor-7f8444fd47-gblcm","pname":"server-monitor","file":{"name":"connection.py","line":61}}
{"time":"2024-02-01T20:59:10.768Z","msg":"Failed to connect to mongodb, retry in 1 second(s)","pid":1,"tid":140176351019264,"pri":"WARN","tname":"MainThread","subsys":"ericsson.mongo.connection","host":"server-monitor-7f8444fd47-gblcm","pname":"server-monitor","file":{"name":"connection.py","line":61}}
{"time":"2024-02-01T20:59:13.794Z","msg":"Failed to connect to mongodb, retry in 1 second(s)","pid":1,"tid":140176351019264,"pri":"WARN","tname":"MainThread","subsys":"ericsson.mongo.connection","host":"server-monitor-7f8444fd47-gblcm","pname":"server-monitor","file":{"name":"connection.py","line":61}}
{"time":"2024-02-01T20:59:16.834Z","msg":"Failed to connect to mongodb, retry in 1 second(s)","pid":1,"tid":140176351019264,"pri":"WARN","tname":"MainThread","subsys":"ericsson.mongo.connection","host":"server-monitor-7f8444fd47-gblcm","pname":"server-monitor","file":{"name":"connection.py","line":61}}
{"time":"2024-02-01T20:59:19.861Z","msg":"Failed to connect to mongodb, retry in 1 second(s)","pid":1,"tid":140176351019264,"pri":"WARN","tname":"MainThread","subsys":"ericsson.mongo.connection","host":"server-monitor-7f8444fd47-gblcm","pname":"server-monitor","file":{"name":"connection.py","line":61}}
{"time":"2024-02-01T20:59:22.876Z","msg":"Failed to connect to mongodb, retry in 1 second(s)","pid":1,"tid":140176351019264,"pri":"WARN","tname":"MainThread","subsys":"ericsson.mongo.connection","host":"server-monitor-7f8444fd47-gblcm","pname":"server-monitor","file":{"name":"connection.py","line":61}}
{"time":"2024-02-01T20:59:25.881Z","msg":"Failed to connect to mongodb, retry in 1 second(s)","pid":1,"tid":140176351019264,"pri":"WARN","tname":"MainThread","subsys":"ericsson.mongo.connection","host":"server-monitor-7f8444fd47-gblcm","pname":"server-monitor","file":{"name":"connection.py","line":61}}
{"time":"2024-02-01T20:59:29.103Z","msg":"Failed to connect to mongodb, retry in 1 second(s)","pid":1,"tid":140176351019264,"pri":"WARN","tname":"MainThread","subsys":"ericsson.mongo.connection","host":"server-monitor-7f8444fd47-gblcm","pname":"server-monitor","file":{"name":"connection.py","line":61}}
{"time":"2024-02-01T20:59:32.109Z","msg":"Failed to connect to mongodb, retry in 1 second(s)","pid":1,"tid":140176351019264,"pri":"WARN","tname":"MainThread","subsys":"ericsson.mongo.connection","host":"server-monitor-7f8444fd47-gblcm","pname":"server-monitor","file":{"name":"connection.py","line":61}}
{"time":"2024-02-01T20:59:35.114Z","msg":"Failed to connect to mongodb, retry in 1 second(s)","pid":1,"tid":140176351019264,"pri":"WARN","tname":"MainThread","subsys":"ericsson.mongo.connection","host":"server-monitor-7f8444fd47-gblcm","pname":"server-monitor","file":{"name":"connection.py","line":61}}
{"time":"2024-02-01T20:59:38.119Z","msg":"Failed to connect to mongodb, retry in 1 second(s)","pid":1,"tid":140176351019264,"pri":"WARN","tname":"MainThread","subsys":"ericsson.mongo.connection","host":"server-monitor-7f8444fd47-gblcm","pname":"server-monitor","file":{"name":"connection.py","line":61}}
{"time":"2024-02-01T20:59:41.124Z","msg":"Failed to connect to mongodb, retry in 1 second(s)","pid":1,"tid":140176351019264,"pri":"WARN","tname":"MainThread","subsys":"ericsson.mongo.connection","host":"server-monitor-7f8444fd47-gblcm","pname":"server-monitor","file":{"name":"connection.py","line":61}}
{"time":"2024-02-01T20:59:44.129Z","msg":"Failed to connect to mongodb, retry in 1 second(s)","pid":1,"tid":140176351019264,"pri":"WARN","tname":"MainThread","subsys":"ericsson.mongo.connection","host":"server-monitor-7f8444fd47-gblcm","pname":"server-monitor","file":{"name":"connection.py","line":61}}
{"time":"2024-02-01T20:59:47.134Z","msg":"Failed to connect to mongodb, retry in 1 second(s)","pid":1,"tid":140176351019264,"pri":"WARN","tname":"MainThread","subsys":"ericsson.mongo.connection","host":"server-monitor-7f8444fd47-gblcm","pname":"server-monitor","file":{"name":"connection.py","line":61}}
{"time":"2024-02-01T20:59:48.780Z","msg":"Connected to mongodb","pid":1,"tid":140176351019264,"pri":"INFO","tname":"MainThread","subsys":"root","host":"server-monitor-7f8444fd47-gblcm","pname":"server-monitor","file":{"name":"connection.py","line":67}}
{"time":"2024-02-01T20:59:48.781Z","msg":"Initializing in-memory cache from database...","pid":1,"tid":140176351019264,"pri":"INFO","tname":"MainThread","subsys":"ericsson.server.monitor.app","host":"server-monitor-7f8444fd47-gblcm","pname":"server-monitor","file":{"name":"app.py","line":218}}
{"time":"2024-02-01T20:59:48.800Z","msg":"Cache initialized.","pid":1,"tid":140176351019264,"pri":"INFO","tname":"MainThread","subsys":"ericsson.server.monitor.app","host":"server-monitor-7f8444fd47-gblcm","pname":"server-monitor","file":{"name":"app.py","line":221}}
{"time":"2024-02-01T20:59:48.801Z","msg":"Connecting to AMQP hosts: ['amqp://guest:**@rabbitmq-ha:5672/']","pid":1,"tid":140176351019264,"pri":"INFO","tname":"MainThread","subsys":"ericsson.messaging.connection","host":"server-monitor-7f8444fd47-gblcm","pname":"server-monitor","file":{"name":"connection.py","line":60}}
{"time":"2024-02-01T20:59:48.828Z","msg":"Successfully initialized RabbitMQ Messaging.","pid":1,"tid":140176351019264,"pri":"INFO","tname":"MainThread","subsys":"ericsson.server.monitor.app","host":"server-monitor-7f8444fd47-gblcm","pname":"server-monitor","file":{"name":"app.py","line":157}}
{"time":"2024-02-01T20:59:48.916Z","msg":"Adding job tentatively -- it will be properly scheduled when the scheduler starts","pid":1,"tid":140176351019264,"pri":"INFO","tname":"MainThread","subsys":"apscheduler.scheduler","host":"server-monitor-7f8444fd47-gblcm","pname":"server-monitor","file":{"name":"base.py","line":444}}
{"time":"2024-02-01T20:59:48.932Z","msg":"Connected to mongodb","pid":1,"tid":140176351019264,"pri":"INFO","tname":"MainThread","subsys":"root","host":"server-monitor-7f8444fd47-gblcm","pname":"server-monitor","file":{"name":"connection.py","line":67}}
{"time":"2024-02-01T20:59:48.932Z","msg":"Adding job tentatively -- it will be properly scheduled when the scheduler starts","pid":1,"tid":140176351019264,"pri":"INFO","tname":"MainThread","subsys":"apscheduler.scheduler","host":"server-monitor-7f8444fd47-gblcm","pname":"server-monitor","file":{"name":"base.py","line":444}}
{"time":"2024-02-01T20:59:48.933Z","msg":"Adding job tentatively -- it will be properly scheduled when the scheduler starts","pid":1,"tid":140176351019264,"pri":"INFO","tname":"MainThread","subsys":"apscheduler.scheduler","host":"server-monitor-7f8444fd47-gblcm","pname":"server-monitor","file":{"name":"base.py","line":444}}
{"time":"2024-02-01T20:59:48.934Z","msg":"Added job \"monitor\" to job store \"default\"","pid":1,"tid":140176351019264,"pri":"INFO","tname":"MainThread","subsys":"apscheduler.scheduler","host":"server-monitor-7f8444fd47-gblcm","pname":"server-monitor","file":{"name":"base.py","line":885}}
{"time":"2024-02-01T20:59:48.934Z","msg":"Added job \"send_resync_message\" to job store \"default\"","pid":1,"tid":140176351019264,"pri":"INFO","tname":"MainThread","subsys":"apscheduler.scheduler","host":"server-monitor-7f8444fd47-gblcm","pname":"server-monitor","file":{"name":"base.py","line":885}}
{"time":"2024-02-01T20:59:48.935Z","msg":"Added job \"check_readiness\" to job store \"default\"","pid":1,"tid":140176351019264,"pri":"INFO","tname":"MainThread","subsys":"apscheduler.scheduler","host":"server-monitor-7f8444fd47-gblcm","pname":"server-monitor","file":{"name":"base.py","line":885}}
{"time":"2024-02-01T20:59:48.935Z","msg":"Scheduler started","pid":1,"tid":140176351019264,"pri":"INFO","tname":"MainThread","subsys":"apscheduler.scheduler","host":"server-monitor-7f8444fd47-gblcm","pname":"server-monitor","file":{"name":"base.py","line":171}}
{"time":"2024-02-01T20:59:49.942Z","msg":"An error occurred while fetching server statuses","pid":1,"tid":140175485155072,"pri":"WARN","tname":"ThreadPoolExecutor-0_0","subsys":"ericsson.server.monitor.utils","exc_info":"Traceback (most recent call last):\n  File \"/src/ericsson/server/monitor/utils.py\", line 62, in get_server_status\n    resp.raise_for_status()\n  File \"/usr/local/lib/python3.9/site-packages/requests/models.py\", line 1021, in raise_for_status\n    raise HTTPError(http_error_msg, response=self)\nrequests.exceptions.HTTPError: 503 Server Error: Service Unavailable for url: http://server-api:8001/api/servers?fields=status","host":"server-monitor-7f8444fd47-gblcm","pname":"server-monitor","file":{"name":"utils.py","line":66}}
{"time":"2024-02-01T20:59:49.943Z","msg":"Job \"monitor (trigger: interval[0:00:01], next run at: 2024-02-01 20:59:50 UTC)\" raised an exception","pid":1,"tid":140175485155072,"pri":"ERROR","tname":"ThreadPoolExecutor-0_0","subsys":"apscheduler.executors.default","exc_info":"Traceback (most recent call last):\n  File \"/usr/local/lib/python3.9/site-packages/apscheduler/executors/base.py\", line 125, in run_job\n    retval = job.func(*job.args, **job.kwargs)\n  File \"/src/ericsson/server/monitor/features.py\", line 311, in monitor\n    for server_id, status in get_server_status(session, server_url, timeout=timeout):\n  File \"/src/ericsson/server/monitor/utils.py\", line 62, in get_server_status\n    resp.raise_for_status()\n  File \"/usr/local/lib/python3.9/site-packages/requests/models.py\", line 1021, in raise_for_status\n    raise HTTPError(http_error_msg, response=self)\nrequests.exceptions.HTTPError: 503 Server Error: Service Unavailable for url: http://server-api:8001/api/servers?fields=status","host":"server-monitor-7f8444fd47-gblcm","pname":"server-monitor","file":{"name":"base.py","line":131}}
{"time":"2024-02-01T20:59:50.921Z","msg":"An error occurred while fetching server statuses","pid":1,"tid":140175485155072,"pri":"WARN","tname":"ThreadPoolExecutor-0_0","subsys":"ericsson.server.monitor.utils","exc_info":"Traceback (most recent call last):\n  File \"/src/ericsson/server/monitor/utils.py\", line 62, in get_server_status\n    resp.raise_for_status()\n  File \"/usr/local/lib/python3.9/site-packages/requests/models.py\", line 1021, in raise_for_status\n    raise HTTPError(http_error_msg, response=self)\nrequests.exceptions.HTTPError: 503 Server Error: Service Unavailable for url: http://server-api:8001/api/servers?fields=status","host":"server-monitor-7f8444fd47-gblcm","pname":"server-monitor","file":{"name":"utils.py","line":66}}
{"time":"2024-02-01T20:59:50.922Z","msg":"Job \"monitor (trigger: interval[0:00:01], next run at: 2024-02-01 20:59:51 UTC)\" raised an exception","pid":1,"tid":140175485155072,"pri":"ERROR","tname":"ThreadPoolExecutor-0_0","subsys":"apscheduler.executors.default","exc_info":"Traceback (most recent call last):\n  File \"/usr/local/lib/python3.9/site-packages/apscheduler/executors/base.py\", line 125, in run_job\n    retval = job.func(*job.args, **job.kwargs)\n  File \"/src/ericsson/server/monitor/features.py\", line 311, in monitor\n    for server_id, status in get_server_status(session, server_url, timeout=timeout):\n  File \"/src/ericsson/server/monitor/utils.py\", line 62, in get_server_status\n    resp.raise_for_status()\n  File \"/usr/local/lib/python3.9/site-packages/requests/models.py\", line 1021, in raise_for_status\n    raise HTTPError(http_error_msg, response=self)\nrequests.exceptions.HTTPError: 503 Server Error: Service Unavailable for url: http://server-api:8001/api/servers?fields=status","host":"server-monitor-7f8444fd47-gblcm","pname":"server-monitor","file":{"name":"base.py","line":131}}
{"time":"2024-02-01T20:59:51.922Z","msg":"An error occurred while fetching server statuses","pid":1,"tid":140175485155072,"pri":"WARN","tname":"ThreadPoolExecutor-0_0","subsys":"ericsson.server.monitor.utils","exc_info":"Traceback (most recent call last):\n  File \"/src/ericsson/server/monitor/utils.py\", line 62, in get_server_status\n    resp.raise_for_status()\n  File \"/usr/local/lib/python3.9/site-packages/requests/models.py\", line 1021, in raise_for_status\n    raise HTTPError(http_error_msg, response=self)\nrequests.exceptions.HTTPError: 503 Server Error: Service Unavailable for url: http://server-api:8001/api/servers?fields=status","host":"server-monitor-7f8444fd47-gblcm","pname":"server-monitor","file":{"name":"utils.py","line":66}}
{"time":"2024-02-01T20:59:51.922Z","msg":"Job \"monitor (trigger: interval[0:00:01], next run at: 2024-02-01 20:59:52 UTC)\" raised an exception","pid":1,"tid":140175485155072,"pri":"ERROR","tname":"ThreadPoolExecutor-0_0","subsys":"apscheduler.executors.default","exc_info":"Traceback (most recent call last):\n  File \"/usr/local/lib/python3.9/site-packages/apscheduler/executors/base.py\", line 125, in run_job\n    retval = job.func(*job.args, **job.kwargs)\n  File \"/src/ericsson/server/monitor/features.py\", line 311, in monitor\n    for server_id, status in get_server_status(session, server_url, timeout=timeout):\n  File \"/src/ericsson/server/monitor/utils.py\", line 62, in get_server_status\n    resp.raise_for_status()\n  File \"/usr/local/lib/python3.9/site-packages/requests/models.py\", line 1021, in raise_for_status\n    raise HTTPError(http_error_msg, response=self)\nrequests.exceptions.HTTPError: 503 Server Error: Service Unavailable for url: http://server-api:8001/api/servers?fields=status","host":"server-monitor-7f8444fd47-gblcm","pname":"server-monitor","file":{"name":"base.py","line":131}}
{"time":"2024-02-01T20:59:52.921Z","msg":"An error occurred while fetching server statuses","pid":1,"tid":140175485155072,"pri":"WARN","tname":"ThreadPoolExecutor-0_0","subsys":"ericsson.server.monitor.utils","exc_info":"Traceback (most recent call last):\n  File \"/src/ericsson/server/monitor/utils.py\", line 62, in get_server_status\n    resp.raise_for_status()\n  File \"/usr/local/lib/python3.9/site-packages/requests/models.py\", line 1021, in raise_for_status\n    raise HTTPError(http_error_msg, response=self)\nrequests.exceptions.HTTPError: 503 Server Error: Service Unavailable for url: http://server-api:8001/api/servers?fields=status","host":"server-monitor-7f8444fd47-gblcm","pname":"server-monitor","file":{"name":"utils.py","line":66}}
{"time":"2024-02-01T20:59:52.921Z","msg":"Job \"monitor (trigger: interval[0:00:01], next run at: 2024-02-01 20:59:53 UTC)\" raised an exception","pid":1,"tid":140175485155072,"pri":"ERROR","tname":"ThreadPoolExecutor-0_0","subsys":"apscheduler.executors.dts.exceptions.HTTPError: 503 Server Error: Service Unavailable for url: http://server-api:8001/api/servers?fields=status","host":"server-monitor-7f8444fd47-gblcm","pname":"server-monitor","file":{"name":"utils.py","line":66}}
{"time":"2024-02-01T21:00:01.922Z","msg":"Job \"monitor (trigger: interval[0:00:01], next run at: 2024-02-01 21:00:02 UTC)\" raised an exception","pid":1,"tid":140175476762368,"pri":"ERROR","tname":"ThreadPoolExecutor-0_1","subsys":"apscheduler.executors.default","exc_info":"Traceback (most recent call last):\n  File \"/usr/local/lib/python3.9/site-packages/apscheduler/executors/base.py\", line 125, in run_job\n    retval = job.func(*job.args, **job.kwargs)\n  File \"/src/ericsson/server/monitor/features.py\", line 311, in monitor\n    for server_id, status in get_server_status(session, server_url, timeout=timeout):\n  File \"/src/ericsson/server/monitor/utils.py\", line 62, in get_server_status\n    resp.raise_for_status()\n  File \"/usr/local/lib/python3.9/site-packages/requests/models.py\", line 1021, in raise_for_status\n    raise HTTPError(http_error_msg, response=self)\nrequests.exceptions.HTTPError: 503 Server Error: Service Unavailable for url: http://server-api:8001/api/servers?fields=status","host":"server-monitor-7f8444fd47-gblcm","pname":"server-monitor","file":{"name":"base.py","line":131}}
{"time":"2024-02-01T21:00:02.921Z","msg":"An error occurred while fetching server statuses","pid":1,"tid":140175485155072,"pri":"WARN","tname":"ThreadPoolExecutor-0_0","subsys":"ericsson.server.monitor.utils","exc_info":"Traceback (most recent call last):\n  File \"/src/ericsson/server/monitor/utils.py\", line 62, in get_server_status\n    resp.raise_for_status()\n  File \"/usr/local/lib/python3.9/site-packages/requests/models.py\", line 1021, in raise_for_status\n    raise HTTPError(http_error_msg, response=self)\nrequests.exceptions.HTTPError: 503 Server Error: Service Unavailable for url: http://server-api:8001/api/servers?fields=status","host":"server-monitor-7f8444fd47-gblcm","pname":"server-monitor","file":{"name":"utils.py","line":66}}
{"time":"2024-02-01T21:00:02.921Z","msg":"Job \"monitor (trigger: interval[0:00:01], next run at: 2024-02-01 21:00:03 UTC)\" raised an exception","pid":1,"tid":140175485155072,"pri":"ERROR","tname":"ThreadPoolExecutor-0_0","subsys":"apscheduler.executors.default","exc_info":"Traceback (most recent call last):\n  File \"/usr/local/lib/python3.9/site-packages/apscheduler/executors/base.py\", line 125, in run_job\n    retval = job.func(*job.args, **job.kwargs)\n  File \"/src/ericsson/server/monitor/features.py\", line 311, in monitor\n    for server_id, status in get_server_status(session, server_url, timeout=timeout):\n  File \"/src/ericsson/server/monitor/utils.py\", line 62, in get_server_status\n    resp.raise_for_status()\n  File \"/usr/local/lib/python3.9/site-packages/requests/models.py\", line 1021, in raise_for_status\n    raise HTTPError(http_error_msg, response=self)\nrequests.exceptions.HTTPError: 503 Server Error: Service Unavailable for url: http://server-api:8001/api/servers?fields=status","host":"server-monitor-7f8444fd47-gblcm","pname":"server-monitor","file":{"name":"base.py","line":131}}
{"time":"2024-02-01T21:00:03.921Z","msg":"An error occurred while fetching server statuses","pid":1,"tid":140175476762368,"pri":"WARN","tname":"ThreadPoolExecutor-0_1","subsys":"ericsson.server.monitor.utils","exc_info":"Traceback (most recent call last):\n  File \"/src/ericsson/server/monitor/utils.py\", line 62, in get_server_status\n    resp.raise_for_status()\n  File \"/usr/local/lib/python3.9/site-packages/requests/models.py\", line 1021, in raise_for_status\n    raise HTTPError(http_error_msg, response=self)\nrequests.exceptions.HTTPError: 503 Server Error: Service Unavailable for url: http://server-api:8001/api/servers?fields=status","host":"server-monitor-7f8444fd47-gblcm","pname":"server-monitor","file":{"name":"utils.py","line":66}}
{"time":"2024-02-01T21:00:03.922Z","msg":"Job \"monitor (trigger: interval[0:00:01], next run at: 2024-02-01 21:00:04 UTC)\" raised an exception","pid":1,"tid":140175476762368,"pri":"ERROR","tname":"ThreadPoolExecutor-0_1","subsys":"apscheduler.executors.default","exc_info":"Traceback (most recent call last):\n  File \"/usr/local/lib/python3.9/site-packages/apscheduler/executors/base.py\", line 125, in run_job\n    retval = job.func(*job.args, **job.kwargs)\n  File \"/src/ericsson/server/monitor/features.py\", line 311, in monitor\n    for server_id, status in get_server_status(session, server_url, timeout=timeout):\n  File \"/src/ericsson/server/monitor/utils.py\", line 62, in get_server_status\n    resp.raise_for_status()\n  File \"/usr/local/lib/python3.9/site-packages/requests/models.py\", line 1021, in raise_for_status\n    raise HTTPError(http_error_msg, response=self)\nrequests.exceptions.HTTPError: 503 Server Error: Service Unavailable for url: http://server-api:8001/api/servers?fields=status","host":"server-monitor-7f8444fd47-gblcm","pname":"server-monitor","file":{"name":"base.py","line":131}}
{"time":"2024-02-01T21:00:04.922Z","msg":"An error occurred while fetching server statuses","pid":1,"tid":140175476762368,"pri":"WARN","tname":"ThreadPoolExecutor-0_1","subsys":"ericsson.server.monitor.utils","exc_info":"Traceback (most recent call last):\n  File \"/src/ericsson/server/monitor/utils.py\", line 62, in get_server_status\n    resp.raise_for_status()\n  File \"/usr/local/lib/python3.9/site-packages/requests/models.py\", line 1021, in raise_for_status\n    raise HTTPError(http_error_msg, response=self)\nrequests.exceptions.HTTPError: 503 Server Error: Service Unavailable for url: http://server-api:8001/api/servers?fields=status","host":"server-monitor-7f8444fd47-gblcm","pname":"server-monitor","file":{"name":"utils.py","line":66}}
{"time":"2024-02-01T21:00:04.923Z","msg":"Job \"monitor (trigger: interval[0:00:01], next run at: 2024-02-01 21:00:05 UTC)\" raised an exception","pid":1,"tid":140175476762368,"pri":"ERROR","tname":"ThreadPoolExecutor-0_1","subsys":"apscheduler.executors.default","exc_info":"Traceback (most recent call last):\n  File \"/usr/local/lib/python3.9/site-packages/apscheduler/executors/base.py\", line 125, in run_job\n    retval = job.func(*job.args, **job.kwargs)\n  File \"/src/ericsson/server/monitor/features.py\", line 311, in monitor\n    for server_id, status in get_server_status(session, server_url, timeout=timeout):\n  File \"/src/ericsson/server/monitor/utils.py\", line 62, in get_server_status\n    resp.raise_for_status()\n  File \"/usr/local/lib/python3.9/site-packages/requests/models.py\", line 1021, in raise_for_status\n    raise HTTPError(http_error_msg, response=self)\nrequests.exceptions.HTTPError: 503 Server Error: Service Unavailable for url: http://server-api:8001/api/servers?fields=status","host":"server-monitor-7f8444fd47-gblcm","pname":"server-monitor","file":{"name":"base.py","line":131}}
{"time":"2024-02-01T21:00:05.922Z","msg":"An error occurred while fetching server statuses","pid":1,"tid":140175485155072,"pri":"WARN","tname":"ThreadPoolExecutor-0_0","subsys":"ericsson.server.monitor.utils","exc_info":"Traceback (most recent call last):\n  File \"/src/ericsson/server/monitor/utils.py\", line 62, in get_server_status\n    resp.raise_for_status()\n  File \"/usr/local/lib/python3.9/site-packages/requests/models.py\", line 1021, in raise_for_status\n    raise HTTPError(http_error_msg, response=self)\nrequests.exceptions.HTTPError: 503 Server Error: Service Unavailable for url: http://server-api:8001/api/servers?fields=status","host":"server-monitor-7f8444fd47-gblcm","pname":"server-monitor","file":{"name":"utils.py","line":66}}
{"time":"2024-02-01T21:00:05.922Z","msg":"Job \"monitor (trigger: interval[0:00:01], next run at: 2024-02-01 21:00:06 UTC)\" raised an exception","pid":1,"tid":140175485155072,"pri":"ERROR","tname":"ThreadPoolExecutor-0_0","subsys":"apscheduler.executors.default","exc_info":"Traceback (most recent call last):\n  File \"/usr/local/lib/python3.9/site-packages/apscheduler/executors/base.py\", line 125, in run_job\n    retval = job.func(*job.args, **job.kwargs)\n  File \"/src/ericsson/server/monitor/features.py\", line 311, in monitor\n    for server_id, status in get_server_status(session, server_url, timeout=timeout):\n  File \"/src/ericsson/server/monitor/utils.py\", line 62, in get_server_status\n    resp.raise_for_status()\n  File \"/usr/local/lib/python3.9/site-packages/requests/models.py\", line 1021, in raise_for_status\n    raise HTTPError(http_error_msg, response=self)\nrequests.exceptions.HTTPError: 503 Server Error: Service Unavailable for url: http://server-api:8001/api/servers?fields=status","host":"server-monitor-7f8444fd47-gblcm","pname":"server-monitor","file":{"name":"base.py","line":131}}
{"time":"2024-02-01T21:00:06.921Z","msg":"An error occurred while fetching server statuses","pid":1,"tid":140175476762368,"pri":"WARN","tname":"ThreadPoolExecutor-0_1","subsys":"ericsson.server.monitor.utils","exc_info":"Traceback (most recent call last):\n  File \"/src/ericsson/server/monitor/utils.py\", line 62, in get_server_status\n    resp.raise_for_status()\n  File \"/usr/local/lib/python3.9/site-packages/requests/models.py\", line 1021, in raise_for_status\n    raise HTTPError(http_error_msg, response=self)\nrequests.exceptions.HTTPError: 503 Server Error: Service Unavailable for url: http://server-api:8001/api/servers?fields=status","host":"server-monitor-7f8444fd47-gblcm","pname":"server-monitor","file":{"name":"utils.py","line":66}}
{"time":"2024-02-01T21:00:06.921Z","msg":"Job \"monitor (trigger: interval[0:00:01], next run at: 2024-02-01 21:00:07 UTC)\" raised an exception","pid":1,"tid":140175476762368,"pri":"ERROR","tname":"ThreadPoolExecutor-0_1","subsys":"apscheduler.executors.default","exc_info":"Traceback (most recent call last):\n  File \"/usr/local/lib/python3.9/site-packages/apscheduler/executors/base.py\", line 125, in run_job\n    retval = job.func(*job.args, **job.kwargs)\n  File \"/src/ericsson/server/monitor/features.py\", line 311, in monitor\n    for server_id, status in get_server_status(session, server_url, timeout=timeout):\n  File \"/src/ericsson/server/monitor/utils.py\", line 62, in get_server_status\n    resp.raise_for_status()\n  File \"/usr/local/lib/python3.9/site-packages/requests/models.py\", line 1021, in raise_for_status\n    raise HTTPError(http_error_msg, response=self)\nrequests.exceptions.HTTPError: 503 Server Error: Service Unavailable for url: http://server-api:8001/api/servers?fields=status","host":"server-monitor-7f8444fd47-gblcm","pname":"server-monitor","file":{"name":"base.py","line":131}}
{"time":"2024-02-01T21:00:07.922Z","msg":"An error occurred while fetching server statuses","pid":1,"tid":140175485155072,"pri":"WARN","tname":"ThreadPoolExecutor-0_0","subsys":"ericsson.server.monitor.utils","exc_info":"Traceback (most recent call last):\n  File \"/src/ericsson/server/monitor/utils.py\", line 62, in get_server_status\n    resp.raise_for_status()\n  File \"/usr/local/lib/python3.9/site-packages/requests/models.py\", line 1021, in raise_for_status\n    raise HTTPError(http_error_msg, response=self)\nrequests.exceptions.HTTPError: 503 Server Error: Service Unavailable for url: http://server-api:8001/api/servers?fields=status","host":"server-monitor-7f8444fd47-gblcm","pname":"server-monitor","file":{"name":"utils.py","line":66}}
{"time":"2024-02-01T21:00:07.923Z","msg":"Job \"monitor (trigger: interval[0:00:01], next run at: 2024-02-01 21:00:08 UTC)\" raised an exception","pid":1,"tid":140175485155072,"pri":"ERROR","tname":"ThreadPoolExecutor-0_0","subsys":"apscheduler.executors.default","exc_info":"Traceback (most recent call last):\n  File \"/usr/local/lib/python3.9/site-packages/apscheduler/executors/base.py\", line 125, in run_job\n    retval = job.func(*job.args, **job.kwargs)\n  File \"/src/ericsson/server/monitor/features.py\", line 311, in monitor\n    for server_id, status in get_server_status(session, server_url, timeout=timeout):\n  File \"/src/ericsson/server/monitor/utils.py\", line 62, in get_server_status\n    resp.raise_for_status()\n  File \"/usr/local/lib/python3.9/site-packages/requests/models.py\", line 1021, in raise_for_status\n    raise HTTPError(http_error_msg, response=self)\nrequests.exceptions.HTTPError: 503 Server Error: Service Unavailable for url: http://server-api:8001/api/servers?fields=status","host":"server-monitor-7f8444fd47-gblcm","pname":"server-monitor","file":{"name":"base.py","line":131}}
{"time":"2024-02-01T21:00:08.921Z","msg":"An error occurred while fetching server statuses","pid":1,"tid":140175476762368,"pri":"WARN","tname":"ThreadPoolExecutor-0_1","subsys":"ericsson.server.monitor.utils","exc_info":"Traceback (most recent call last):\n  File \"/src/ericsson/server/monitor/utils.py\", line 62, in get_server_status\n    resp.raise_for_status()\n  File \"/usr/local/lib/python3.9/site-packages/requests/models.py\", line 1021, in raise_for_status\n    raise HTTPError(http_error_msg, response=self)\nrequests.exceptions.HTTPError: 503 Server Error: Service Unavailable for url: http://server-api:8001/api/servers?fields=status","host":"server-monitor-7f8444fd47-gblcm","pname":"server-monitor","file":{"name":"utils.py","line":66}}
{"time":"2024-02-01T21:00:08.921Z","msg":"Job \"monitor (trigger: interval[0:00:01], next run at: 2024-02-01 21:00:09 UTC)\" raised an exception","pid":1,"tid":140175476762368,"pri":"ERROR","tname":"ThreadPoolExecutor-0_1","subsys":"apscheduler.executors.default","exc_info":"Traceback (most recent call last):\n  File \"/usr/local/lib/python3.9/site-packages/apscheduler/executors/base.py\", line 125, in run_job\n    retval = job.func(*job.args, **job.kwargs)\n  File \"/src/ericsson/server/monitor/features.py\", line 311, in monitor\n    for server_id, status in get_server_status(session, server_url, timeout=timeout):\n  File \"/src/ericsson/server/monitor/utils.py\", line 62, in get_server_status\n    resp.raise_for_status()\n  File \"/usr/local/lib/python3.9/site-packages/requests/models.py\", line 1021, in raise_for_status\n    raise HTTPError(http_error_msg, response=self)\nrequests.exceptions.HTTPError: 503 Server Error: Service Unavailable for url: http://server-api:8001/api/servers?fields=status","host":"server-monitor-7f8444fd47-gblcm","pname":"server-monitor","file":{"name":"base.py","line":131}}
{"time":"2024-02-01T21:00:09.921Z","msg":"An error occurred while fetching server statuses","pid":1,"tid":140175476762368,"pri":"WARN","tname":"ThreadPoolExecutor-0_1","subsys":"ericsson.server.monitor.utils","exc_info":"Traceback (most recent call last):\n  File \"/src/ericsson/server/monitor/utils.py\", line 62, in get_server_status\n    resp.raise_for_status()\n  File \"/usr/local/lib/python3.9/site-packages/requests/models.py\", line 1021, in raise_for_status\n    raise HTTPError(http_error_msg, response=self)\nrequests.exceptions.HTTPError: 503 Server Error: Service Unavailable for url: http://server-api:8001/api/servers?fields=status","host":"server-monitor-7f8444fd47-gblcm","pname":"server-monitor","file":{"name":"utils.py","line":66}}
{"time":"2024-02-01T21:00:09.922Z","msg":"Job \"monitor (trigger: interval[0:00:01], next run at: 2024-02-01 21:00:10 UTC)\" raised an exception","pid":1,"tid":140175476762368,"pri":"ERROR","tname":"ThreadPoolExecutor-0_1","subsys":"apscheduler.executors.default","exc_info":"Traceback (most recent call last):\n  File \"/usr/local/lib/python3.9/site-packages/apscheduler/executors/base.py\", line 125, in run_job\n    retval = job.func(*job.args, **job.kwargs)\n  File \"/src/ericsson/server/monitor/features.py\", line 311, in monitor\n    for server_id, status in get_server_status(session, server_url, timeout=timeout):\n  File \"/src/ericsson/server/monitor/utils.py\", line 62, in get_server_status\n    resp.raise_for_status()\n  File \"/usr/local/lib/python3.9/site-packages/requests/models.py\", line 1021, in raise_for_status\n    raise HTTPError(http_error_msg, response=self)\nrequests.exceptions.HTTPError: 503 Server Error: Service Unavailable for url: http://server-api:8001/api/servers?fields=status","host":"server-monitor-7f8444fd47-gblcm","pname":"server-monitor","file":{"name":"base.py","line":131}}
{"time":"2024-02-04T11:00:03.916Z","msg":"Execution of job \"monitor (trigger: interval[0:00:01], next run at: 2024-02-04 11:00:03 UTC)\" skipped: maximum number of running instances reached (1)","pid":1,"tid":140175493547776,"pri":"WARN","tname":"APScheduler","subsys":"apscheduler.scheduler","host":"server-monitor-7f8444fd47-gblcm","pname":"server-monitor","file":{"name":"base.py","line":980}}
{"time":"2024-02-04T11:00:04.916Z","msg":"Execution of job \"monitor (trigger: interval[0:00:01], next run at: 2024-02-04 11:00:04 UTC)\" skipped: maximum number of running instances reached (1)","pid":1,"tid":140175493547776,"pri":"WARN","tname":"APScheduler","subsys":"apscheduler.scheduler","host":"server-monitor-7f8444fd47-gblcm","pname":"server-monitor","file":{"name":"base.py","line":980}}
{"time":"2024-02-04T11:00:04.919Z","msg":"An error occurred while fetching server statuses","pid":1,"tid":140175476762368,"pri":"WARN","tname":"ThreadPoolExecutor-0_1","subsys":"ericsson.server.monitor.utils","exc_info":"Traceback (most recent call last):\n  File \"/usr/local/lib/python3.9/site-packages/urllib3/connectionpool.py\", line 449, in _make_request\n    six.raise_from(e, None)\n  File \"<string>\", line 3, in raise_from\n  File \"/usr/local/lib/python3.9/site-packages/urllib3/connectionpool.py\", line 444, in _make_request\n    httplib_response = conn.getresponse()\n  File \"/usr/lib64/python3.9/http/client.py\", line 1349, in getresponse\n    response.begin()\n  File \"/usr/lib64/python3.9/http/client.py\", line 316, in begin\n    version, status, reason = self._read_status()\n  File \"/usr/lib64/python3.9/http/client.py\", line 277, in _read_status\n    line = str(self.fp.readline(_MAXLINE + 1), \"iso-8859-1\")\n  File \"/usr/lib64/python3.9/socket.py\", line 704, in readinto\n    return self._sock.recv_into(b)\nsocket.timeout: timed out\n\nDuring handling of the above exception, another exception occurred:\n\nTraceback (most recent call last):\n  File \"/usr/local/lib/python3.9/site-packages/requests/adapters.py\", line 489, in send\n    resp = conn.urlopen(\n  File \"/usr/local/lib/python3.9/site-packages/urllib3/connectionpool.py\", line 787, in urlopen\n    retries = retries.increment(\n  File \"/usr/local/lib/python3.9/site-packages/urllib3/util/retry.py\", line 550, in increment\n    raise six.reraise(type(error), error, _stacktrace)\n  File \"/usr/local/lib/python3.9/site-packages/urllib3/packages/six.py\", line 770, in reraise\n    raise value\n  File \"/usr/local/lib/python3.9/site-packages/urllib3/connectionpool.py\", line 703, in urlopen\n    httplib_response = self._make_request(\n  File \"/usr/local/lib/python3.9/site-packages/urllib3/connectionpool.py\", line 451, in _make_request\n    self._raise_timeout(err=e, url=url, timeout_value=read_timeout)\n  File \"/usr/local/lib/python3.9/site-packages/urllib3/connectionpool.py\", line 340, in _raise_timeout\n    raise ReadTimeoutError(\nurllib3.exceptions.ReadTimeoutError: HTTPConnectionPool(host='server-api', port=8001): Read timed out. (read timeout=2)\n\nDuring handling of the above exception, another exception occurred:\n\nTraceback (most recent call last):\n  File \"/src/ericsson/server/monitor/utils.py\", line 61, in get_server_status\n    resp = session.get(server_url + \"?fields=status\", timeout=timeout)\n  File \"/usr/local/lib/python3.9/site-packages/requests/sessions.py\", line 600, in get\n    return self.request(\"GET\", url, **kwargs)\n  File \"/usr/local/lib/python3.9/site-packages/requests/sessions.py\", line 587, in request\n    resp = self.send(prep, **send_kwargs)\n  File \"/usr/local/lib/python3.9/site-packages/requests/sessions.py\", line 701, in send\n    r = adapter.send(request, **kwargs)\n  File \"/usr/local/lib/python3.9/site-packages/requests/adapters.py\", line 578, in send\n    raise ReadTimeout(e, request=request)\nrequests.exceptions.ReadTimeout: HTTPConnectionPool(host='server-api', port=8001): Read timed out. (read timeout=2)","host":"server-monitor-7f8444fd47-gblcm","pname":"server-monitor","file":{"name":"utils.py","line":66}}
{"time":"2024-02-04T11:00:04.922Z","msg":"Job \"monitor (trigger: interval[0:00:01], next run at: 2024-02-04 11:00:05 UTC)\" raised an exception","pid":1,"tid":140175476762368,"pri":"ERROR","tname":"ThreadPoolExecutor-0_1","subsys":"apscheduler.executors.default","exc_info":"Traceback (most recent call last):\n  File \"/usr/local/lib/python3.9/site-packages/urllib3/connectionpool.py\", line 449, in _make_request\n    six.raise_from(e, None)\n  File \"<string>\", line 3, in raise_from\n  File \"/usr/local/lib/python3.9/site-packages/urllib3/connectionpool.py\", line 444, in _make_request\n    httplib_response = conn.getresponse()\n  File \"/usr/lib64/python3.9/http/client.py\", line 1349, in getresponse\n    response.begin()\n  File \"/usr/lib64/python3.9/http/client.py\", line 316, in begin\n    version, status, reason = self._read_status()\n  File \"/usr/lib64/python3.9/http/client.py\", line 277, in _read_status\n    line = str(self.fp.readline(_MAXLINE + 1), \"iso-8859-1\")\n  File \"/usr/lib64/python3.9/socket.py\", line 704, in readinto\n    return self._sock.recv_into(b)\nsocket.timeout: timed out\n\nDuring handling of the above exception, another exception occurred:\n\nTraceback (most recent call last):\n  File \"/usr/local/lib/python3.9/site-packages/requests/adapters.py\", line 489, in send\n    resp = conn.urlopen(\n  File \"/usr/local/lib/python3.9/site-packages/urllib3/connectionpool.py\", line 787, in urlopen\n    retries = retries.increment(\n  File \"/usr/local/lib/python3.9/site-packages/urllib3/util/retry.py\", line 550, in increment\n    raise six.reraise(type(error), error, _stacktrace)\n  File \"/usr/local/lib/python3.9/site-packages/urllib3/packages/six.py\", line 770, in reraise\n    raise value\n  File \"/usr/local/lib/python3.9/site-packages/urllib3/connectionpool.py\", line 703, in urlopen\n    httplib_response = self._make_request(\n  File \"/usr/local/lib/python3.9/site-packages/urllib3/connectionpool.py\", line 451, in _make_request\n    self._raise_timeout(err=e, url=url, timeout_value=read_timeout)\n  File \"/usr/local/lib/python3.9/site-packages/urllib3/connectionpool.py\", line 340, in _raise_timeout\n    raise ReadTimeoutError(\nurllib3.exceptions.ReadTimeoutError: HTTPConnectionPool(host='server-api', port=8001): Read timed out. (read timeout=2)\n\nDuring handling of the above exception, another exception occurred:\n\nTraceback (most recent call last):\n  File \"/usr/local/lib/python3.9/site-packages/apscheduler/executors/base.py\", line 125, in run_job\n    retval = job.func(*job.args, **job.kwargs)\n  File \"/src/ericsson/server/monitor/features.py\", line 311, in monitor\n    for server_id, status in get_server_status(session, server_url, timeout=timeout):\n  File \"/src/ericsson/server/monitor/utils.py\", line 61, in get_server_status\n    resp = session.get(server_url + \"?fields=status\", timeout=timeout)\n  File \"/usr/local/lib/python3.9/site-packages/requests/sessions.py\", line 600, in get\n    return self.request(\"GET\", url, **kwargs)\n  File \"/usr/local/lib/python3.9/site-packages/requests/sessions.py\", line 587, in request\n    resp = self.send(prep, **send_kwargs)\n  File \"/usr/local/lib/python3.9/site-packages/requests/sessions.py\", line 701, in send\n    r = adapter.send(request, **kwargs)\n  File \"/usr/local/lib/python3.9/site-packages/requests/adapters.py\", line 578, in send\n    raise ReadTimeout(e, request=request)\nrequests.exceptions.ReadTimeout: HTTPConnectionPool(host='server-api', port=8001): Read timed out. (read timeout=2)","host":"server-monitor-7f8444fd47-gblcm","pname":"server-monitor","file":{"name":"base.py","line":131}}
{"time":"2024-02-04T11:00:06.401Z","msg":"Readiness: Could not contact MongoDB","pid":1,"tid":140175485155072,"pri":"ERROR","tname":"ThreadPoolExecutor-0_0","subsys":"ericsson.server.monitor.readiness","host":"server-monitor-7f8444fd47-gblcm","pname":"server-monitor","file":{"name":"readiness.py","line":26}}
{"time":"2024-02-04T11:00:06.412Z","msg":"Job \"send_resync_message (trigger: interval[0:00:05], next run at: 2024-02-04 11:00:08 UTC)\" raised an exception","pid":1,"tid":140175468369664,"pri":"ERROR","tname":"ThreadPoolExecutor-0_2","subsys":"apscheduler.executors.default","exc_info":"Traceback (most recent call last):\n  File \"/usr/local/lib/python3.9/site-packages/apscheduler/executors/base.py\", line 125, in run_job\n    retval = job.func(*job.args, **job.kwargs)\n  File \"/src/ericsson/server/monitor/features.py\", line 361, in send_resync_message\n    have_lock = mongo_lock.lock(\n  File \"/usr/local/lib/python3.9/site-packages/mongolock.py\", line 68, in lock\n    self.collection.insert({\n  File \"/usr/local/lib64/python3.9/site-packages/pymongo/collection.py\", line 3339, in insert\n    return self._insert(doc_or_docs, not continue_on_error,\n  File \"/usr/local/lib64/python3.9/site-packages/pymongo/collection.py\", line 620, in _insert\n    return self._insert_one(\n  File \"/usr/local/lib64/python3.9/site-packages/pymongo/collection.py\", line 609, in _insert_one\n    self.__database.client._retryable_write(\n  File \"/usr/local/lib64/python3.9/site-packages/pymongo/mongo_client.py\", line 1552, in _retryable_write\n    return self._retry_with_session(retryable, func, s, None)\n  File \"/usr/local/lib64/python3.9/site-packages/pymongo/mongo_client.py\", line 1438, in _retry_with_session\n    return self._retry_internal(retryable, func, session, bulk)\n  File \"/usr/local/lib64/python3.9/site-packages/pymongo/mongo_client.py\", line 1458, in _retry_internal\n    server = self._select_server(writable_server_selector, session)\n  File \"/usr/local/lib64/python3.9/site-packages/pymongo/mongo_client.py\", line 1346, in _select_server\n    server = topology.select_server(server_selector)\n  File \"/usr/local/lib64/python3.9/site-packages/pymongo/topology.py\", line 244, in select_server\n    return random.choice(self.select_servers(selector,\n  File \"/usr/local/lib64/python3.9/site-packages/pymongo/topology.py\", line 202, in select_servers\n    server_descriptions = self._select_servers_loop(\n  File \"/usr/local/lib64/python3.9/site-packages/pymongo/topology.py\", line 218, in _select_servers_loop\n    raise ServerSelectionTimeoutError(\npymongo.errors.ServerSelectionTimeoutError: No primary available for writes, Timeout: 2.0s, Topology Description: <TopologyDescription id: 65bc0644f1550c84996fd0a2, topology_type: ReplicaSetNoPrimary, servers: [<ServerDescription ('10.69.8.201', 27018) server_type: Unknown, rtt: None, error=AutoReconnect('10.69.8.201:27018: [Errno 111] Connection refused')>, <ServerDescription ('10.69.8.31', 27017) server_type: RSSecondary, rtt: 0.0003304486932230561>, <ServerDescription ('10.69.8.32', 27017) server_type: Unknown, rtt: None, error=AutoReconnect('10.69.8.32:27017: [Errno 111] Connection refused')>]>","host":"server-monitor-7f8444fd47-gblcm","pname":"server-monitor","file":{"name":"base.py","line":131}}
{"time":"2024-02-04T11:00:06.916Z","msg":"Execution of job \"monitor (trigger: interval[0:00:01], next run at: 2024-02-04 11:00:06 UTC)\" skipped: maximum number of running instances reached (1)","pid":1,"tid":140175493547776,"pri":"WARN","tname":"APScheduler","subsys":"apscheduler.scheduler","host":"server-monitor-7f8444fd47-gblcm","pname":"server-monitor","file":{"name":"base.py","line":980}}
{"time":"2024-02-04T11:00:07.141Z","msg":"An error occurred while fetching server statuses","pid":1,"tid":140175476762368,"pri":"WARN","tname":"ThreadPoolExecutor-0_1","subsys":"ericsson.server.monitor.utils","exc_info":"Traceback (most recent call last):\n  File \"/src/ericsson/server/monitor/utils.py\", line 62, in get_server_status\n    resp.raise_for_status()\n  File \"/usr/local/lib/python3.9/site-packages/requests/models.py\", line 1021, in raise_for_status\n    raise HTTPError(http_error_msg, response=self)\nrequests.exceptions.HTTPError: 503 Server Error: Service Unavailable for url: http://server-api:8001/api/servers?fields=status","host":"server-monitor-7f8444fd47-gblcm","pname":"server-monitor","file":{"name":"utils.py","line":66}}
{"time":"2024-02-04T11:00:07.142Z","msg":"Job \"monitor (trigger: interval[0:00:01], next run at: 2024-02-04 11:00:07 UTC)\" raised an exception","pid":1,"tid":140175476762368,"pri":"ERROR","tname":"ThreadPoolExecutor-0_1","subsys":"apscheduler.executors.default","exc_info":"Traceback (most recent call last):\n  File \"/usr/local/lib/python3.9/site-packages/apscheduler/executors/base.py\", line 125, in run_job\n    retval = job.func(*job.args, **job.kwargs)\n  File \"/src/ericsson/server/monitor/features.py\", line 311, in monitor\n    for server_id, status in get_server_status(session, server_url, timeout=timeout):\n  File \"/src/ericsson/server/monitor/utils.py\", line 62, in get_server_status\n    resp.raise_for_status()\n  File \"/usr/local/lib/python3.9/site-packages/requests/models.py\", line 1021, in raise_for_status\n    raise HTTPError(http_error_msg, response=self)\nrequests.exceptions.HTTPError: 503 Server Error: Service Unavailable for url: http://server-api:8001/api/servers?fields=status","host":"server-monitor-7f8444fd47-gblcm","pname":"server-monitor","file":{"name":"base.py","line":131}}
{"time":"2024-02-04T11:00:07.921Z","msg":"Server mksp1 status has changed from in-memory cache. Was: up, now: unknown","pid":1,"tid":140175485155072,"pri":"INFO","tname":"ThreadPoolExecutor-0_0","subsys":"ericsson.server.monitor.features","host":"server-monitor-7f8444fd47-gblcm","pname":"server-monitor","file":{"name":"features.py","line":106}}
{"time":"2024-02-04T11:00:07.927Z","msg":"Server mksp1 status unknown modified/inserted in shared database? True/False","pid":1,"tid":140175485155072,"pri":"INFO","tname":"ThreadPoolExecutor-0_0","subsys":"ericsson.server.monitor.features","host":"server-monitor-7f8444fd47-gblcm","pname":"server-monitor","file":{"name":"features.py","line":188}}
{"time":"2024-02-04T11:00:07.927Z","msg":"Server mksp2 status has changed from in-memory cache. Was: down, now: unknown","pid":1,"tid":140175485155072,"pri":"INFO","tname":"ThreadPoolExecutor-0_0","subsys":"ericsson.server.monitor.features","host":"server-monitor-7f8444fd47-gblcm","pname":"server-monitor","file":{"name":"features.py","line":106}}
{"time":"2024-02-04T11:00:07.928Z","msg":"Server mksp2 status unknown modified/inserted in shared database? True/False","pid":1,"tid":140175485155072,"pri":"INFO","tname":"ThreadPoolExecutor-0_0","subsys":"ericsson.server.monitor.features","host":"server-monitor-7f8444fd47-gblcm","pname":"server-monitor","file":{"name":"features.py","line":188}}
{"time":"2024-02-04T11:00:10.921Z","msg":"Server mksp1 status has changed from in-memory cache. Was: unknown, now: up","pid":1,"tid":140175485155072,"pri":"INFO","tname":"ThreadPoolExecutor-0_0","subsys":"ericsson.server.monitor.features","host":"server-monitor-7f8444fd47-gblcm","pname":"server-monitor","file":{"name":"features.py","line":106}}
{"time":"2024-02-04T11:00:10.923Z","msg":"Server mksp1 status up modified/inserted in shared database? True/False","pid":1,"tid":140175485155072,"pri":"INFO","tname":"ThreadPoolExecutor-0_0","subsys":"ericsson.server.monitor.features","host":"server-monitor-7f8444fd47-gblcm","pname":"server-monitor","file":{"name":"features.py","line":188}}
{"time":"2024-02-04T11:00:10.923Z","msg":"mksp1 alarm published for server cleared with timestamp of 2024-02-04T11:00:10.922000+00:00","pid":1,"tid":140175485155072,"pri":"INFO","tname":"ThreadPoolExecutor-0_0","subsys":"ericsson.server.monitor.features","host":"server-monitor-7f8444fd47-gblcm","pname":"server-monitor","file":{"name":"features.py","line":336}}
{"time":"2024-02-04T11:00:17.922Z","msg":"Server mksp2 status has changed from in-memory cache. Was: unknown, now: down","pid":1,"tid":140175485155072,"pri":"INFO","tname":"ThreadPoolExecutor-0_0","subsys":"ericsson.server.monitor.features","host":"server-monitor-7f8444fd47-gblcm","pname":"server-monitor","file":{"name":"features.py","line":106}}
{"time":"2024-02-04T11:00:17.923Z","msg":"Server mksp2 status down modified/inserted in shared database? True/False","pid":1,"tid":140175485155072,"pri":"INFO","tname":"ThreadPoolExecutor-0_0","subsys":"ericsson.server.monitor.features","host":"server-monitor-7f8444fd47-gblcm","pname":"server-monitor","file":{"name":"features.py","line":188}}
{"time":"2024-02-04T11:00:17.924Z","msg":"mksp2 alarm published for server raised with timestamp of 2024-02-04T11:00:17.923000+00:00","pid":1,"tid":140175485155072,"pri":"INFO","tname":"ThreadPoolExecutor-0_0","subsys":"ericsson.server.monitor.features","host":"server-monitor-7f8444fd47-gblcm","pname":"server-monitor","file":{"name":"features.py","line":336}}
{"time":"2024-02-06T08:36:13.548Z","msg":"Configuration: {'alarm.publisher_id': 'server-monitor', 'alarm.resync_attempt_interval': '5', 'alarm.resync_interval': '30', 'api.server_url': 'http://server-api:8001/api/servers', 'api.timeout': '2', 'api.wait_on_error': '30', 'general.exclude_itself': 'False', 'general.ready_file_path': '/var/run/ericsson/server-monitor/ready', 'general.server_id': '', 'messaging.config': '/src/ericsson/server/monitor/data/default_message_types.json', 'messaging.server_url': 'amqp://guest:guest@rabbitmq-ha:5672/?heartbeat=30', 'mongolock.collection': 'server-monitor', 'mongolock.db': 'mediakindMongolock', 'mongolock.key': 'server-monitor', 'mongolock.owner': 'server-monitor', 'storage.host': 'localhost', 'storage.name': 'envivioCluster', 'storage.port': '27017', 'storage.url': 'mongodb://10.69.8.31:27017,10.69.8.32:27017/envivioCluster?replicaSet=repldb', 'storage_lock.alias': 'mediakindMongolock', 'storage_lock.host': 'localhost', 'storage_lock.port': '27017', 'storage_lock.url': 'mongodb://10.69.8.31:27017,10.69.8.32:27017/mediakindMongolock?replicaSet=repldb', 'storage_lock.username': 'MediaKind', 'time.interval': '1', 'time.readiness_interval': '5'}","pid":1,"tid":140275261387008,"pri":"INFO","tname":"MainThread","subsys":"ericsson.server.monitor.app","host":"server-monitor-7f8444fd47-gblcm","pname":"server-monitor","file":{"name":"app.py","line":192}}
{"time":"2024-02-06T08:36:13.548Z","msg":"Connecting to MongoDB...","pid":1,"tid":140275261387008,"pri":"INFO","tname":"MainThread","subsys":"ericsson.server.monitor.app","host":"server-monitor-7f8444fd47-gblcm","pname":"server-monitor","file":{"name":"app.py","line":215}}
{"time":"2024-02-06T08:36:15.610Z","msg":"Failed to connect to mongodb, retry in 1 second(s)","pid":1,"tid":140275261387008,"pri":"WARN","tname":"MainThread","subsys":"ericsson.mongo.connection","host":"server-monitor-7f8444fd47-gblcm","pname":"server-monitor","file":{"name":"connection.py","line":61}}
{"time":"2024-02-06T08:36:18.625Z","msg":"Failed to connect to mongodb, retry in 1 second(s)","pid":1,"tid":140275261387008,"pri":"WARN","tname":"MainThread","subsys":"ericsson.mongo.connection","host":"server-monitor-7f8444fd47-gblcm","pname":"server-monitor","file":{"name":"connection.py","line":61}}
{"time":"2024-02-06T08:36:21.701Z","msg":"Failed to connect to mongodb, retry in 1 second(s)","pid":1,"tid":140275261387008,"pri":"WARN","tname":"MainThread","subsys":"ericsson.mongo.connection","host":"server-monitor-7f8444fd47-gblcm","pname":"server-monitor","file":{"name":"connection.py","line":61}}
{"time":"2024-02-06T08:36:24.726Z","msg":"Failed to connect to mongodb, retry in 1 second(s)","pid":1,"tid":140275261387008,"pri":"WARN","tname":"MainThread","subsys":"ericsson.mongo.connection","host":"server-monitor-7f8444fd47-gblcm","pname":"server-monitor","file":{"name":"connection.py","line":61}}
{"time":"2024-02-06T08:36:27.731Z","msg":"Failed to connect to mongodb, retry in 1 second(s)","pid":1,"tid":140275261387008,"pri":"WARN","tname":"MainThread","subsys":"ericsson.mongo.connection","host":"server-monitor-7f8444fd47-gblcm","pname":"server-monitor","file":{"name":"connection.py","line":61}}
{"time":"2024-02-06T08:36:30.736Z","msg":"Failed to connect to mongodb, retry in 1 second(s)","pid":1,"tid":140275261387008,"pri":"WARN","tname":"MainThread","subsys":"ericsson.mongo.connection","host":"server-monitor-7f8444fd47-gblcm","pname":"server-monitor","file":{"name":"connection.py","line":61}}
{"time":"2024-02-06T08:36:33.740Z","msg":"Failed to connect to mongodb, retry in 1 second(s)","pid":1,"tid":140275261387008,"pri":"WARN","tname":"MainThread","subsys":"ericsson.mongo.connection","host":"server-monitor-7f8444fd47-gblcm","pname":"server-monitor","file":{"name":"connection.py","line":61}}
{"time":"2024-02-06T08:36:36.745Z","msg":"Failed to connect to mongodb, retry in 1 second(s)","pid":1,"tid":140275261387008,"pri":"WARN","tname":"MainThread","subsys":"ericsson.mongo.connection","host":"server-monitor-7f8444fd47-gblcm","pname":"server-monitor","file":{"name":"connection.py","line":61}}
{"time":"2024-02-06T08:36:39.749Z","msg":"Failed to connect to mongodb, retry in 1 second(s)","pid":1,"tid":140275261387008,"pri":"WARN","tname":"MainThread","subsys":"ericsson.mongo.connection","host":"server-monitor-7f8444fd47-gblcm","pname":"server-monitor","file":{"name":"connection.py","line":61}}
{"time":"2024-02-06T08:36:42.754Z","msg":"Failed to connect to mongodb, retry in 1 second(s)","pid":1,"tid":140275261387008,"pri":"WARN","tname":"MainThread","subsys":"ericsson.mongo.connection","host":"server-monitor-7f8444fd47-gblcm","pname":"server-monitor","file":{"name":"connection.py","line":61}}
{"time":"2024-02-06T08:36:45.759Z","msg":"Failed to connect to mongodb, retry in 1 second(s)","pid":1,"tid":140275261387008,"pri":"WARN","tname":"MainThread","subsys":"ericsson.mongo.connection","host":"server-monitor-7f8444fd47-gblcm","pname":"server-monitor","file":{"name":"connection.py","line":61}}
{"time":"2024-02-06T08:36:48.763Z","msg":"Failed to connect to mongodb, retry in 1 second(s)","pid":1,"tid":140275261387008,"pri":"WARN","tname":"MainThread","subsys":"ericsson.mongo.connection","host":"server-monitor-7f8444fd47-gblcm","pname":"server-monitor","file":{"name":"connection.py","line":61}}
{"time":"2024-02-06T08:36:51.449Z","msg":"Connected to mongodb","pid":1,"tid":140275261387008,"pri":"INFO","tname":"MainThread","subsys":"root","host":"server-monitor-7f8444fd47-gblcm","pname":"server-monitor","file":{"name":"connection.py","line":67}}
{"time":"2024-02-06T08:36:51.449Z","msg":"Initializing in-memory cache from database...","pid":1,"tid":140275261387008,"pri":"INFO","tname":"MainThread","subsys":"ericsson.server.monitor.app","host":"server-monitor-7f8444fd47-gblcm","pname":"server-monitor","file":{"name":"app.py","line":218}}
{"time":"2024-02-06T08:36:51.487Z","msg":"Cache initialized.","pid":1,"tid":140275261387008,"pri":"INFO","tname":"MainThread","subsys":"ericsson.server.monitor.app","host":"server-monitor-7f8444fd47-gblcm","pname":"server-monitor","file":{"name":"app.py","line":221}}
{"time":"2024-02-06T08:36:51.488Z","msg":"Connecting to AMQP hosts: ['amqp://guest:**@rabbitmq-ha:5672/']","pid":1,"tid":140275261387008,"pri":"INFO","tname":"MainThread","subsys":"ericsson.messaging.connection","host":"server-monitor-7f8444fd47-gblcm","pname":"server-monitor","file":{"name":"connection.py","line":60}}
{"time":"2024-02-06T08:36:55.540Z","msg":"Could not connect to RabbitMQ: [Errno 111] Connection refused","pid":1,"tid":140275261387008,"pri":"ERROR","tname":"MainThread","subsys":"ericsson.messaging.connection","host":"server-monitor-7f8444fd47-gblcm","pname":"server-monitor","file":{"name":"connection.py","line":93}}
{"time":"2024-02-06T08:36:55.540Z","msg":"Retrying connection in 5 seconds...","pid":1,"tid":140275261387008,"pri":"INFO","tname":"MainThread","subsys":"ericsson.messaging.connection","host":"server-monitor-7f8444fd47-gblcm","pname":"server-monitor","file":{"name":"connection.py","line":94}}
{"time":"2024-02-06T08:37:00.548Z","msg":"Successfully initialized RabbitMQ Messaging.","pid":1,"tid":140275261387008,"pri":"INFO","tname":"MainThread","subsys":"ericsson.server.monitor.app","host":"server-monitor-7f8444fd47-gblcm","pname":"server-monitor","file":{"name":"app.py","line":157}}
{"time":"2024-02-06T08:37:00.619Z","msg":"Adding job tentatively -- it will be properly scheduled when the scheduler starts","pid":1,"tid":140275261387008,"pri":"INFO","tname":"MainThread","subsys":"apscheduler.scheduler","host":"server-monitor-7f8444fd47-gblcm","pname":"server-monitor","file":{"name":"base.py","line":444}}
{"time":"2024-02-06T08:37:00.641Z","msg":"Connected to mongodb","pid":1,"tid":140275261387008,"pri":"INFO","tname":"MainThread","subsys":"root","host":"server-monitor-7f8444fd47-gblcm","pname":"server-monitor","file":{"name":"connection.py","line":67}}
{"time":"2024-02-06T08:37:00.641Z","msg":"Adding job tentatively -- it will be properly scheduled when the scheduler starts","pid":1,"tid":140275261387008,"pri":"INFO","tname":"MainThread","subsys":"apscheduler.scheduler","host":"server-monitor-7f8444fd47-gblcm","pname":"server-monitor","file":{"name":"base.py","line":444}}
{"time":"2024-02-06T08:37:00.641Z","msg":"Adding job tentatively -- it will be properly scheduled when the scheduler starts","pid":1,"tid":140275261387008,"pri":"INFO","tname":"MainThread","subsys":"apscheduler.scheduler","host":"server-monitor-7f8444fd47-gblcm","pname":"server-monitor","file":{"name":"base.py","line":444}}
{"time":"2024-02-06T08:37:00.644Z","msg":"Added job \"monitor\" to job store \"default\"","pid":1,"tid":140275261387008,"pri":"INFO","tname":"MainThread","subsys":"apscheduler.scheduler","host":"server-monitor-7f8444fd47-gblcm","pname":"server-monitor","file":{"name":"base.py","line":885}}
{"time":"2024-02-06T08:37:00.644Z","msg":"Added job \"send_resync_message\" to job store \"default\"","pid":1,"tid":140275261387008,"pri":"INFO","tname":"MainThread","subsys":"apscheduler.scheduler","host":"server-monitor-7f8444fd47-gblcm","pname":"server-monitor","file":{"name":"base.py","line":885}}
{"time":"2024-02-06T08:37:00.644Z","msg":"Added job \"check_readiness\" to job store \"default\"","pid":1,"tid":140275261387008,"pri":"INFO","tname":"MainThread","subsys":"apscheduler.scheduler","host":"server-monitor-7f8444fd47-gblcm","pname":"server-monitor","file":{"name":"base.py","line":885}}
{"time":"2024-02-06T08:37:00.644Z","msg":"Scheduler started","pid":1,"tid":140275261387008,"pri":"INFO","tname":"MainThread","subsys":"apscheduler.scheduler","host":"server-monitor-7f8444fd47-gblcm","pname":"server-monitor","file":{"name":"base.py","line":171}}
{"time":"2024-02-06T08:37:01.628Z","msg":"An error occurred while fetching server statuses","pid":1,"tid":140274462336768,"pri":"WARN","tname":"ThreadPoolExecutor-0_0","subsys":"ericsson.server.monitor.utils","exc_info":"Traceback (most recent call last):\n  File \"/src/ericsson/server/monitor/utils.py\", line 62, in get_server_status\n    resp.raise_for_status()\n  File \"/usr/local/lib/python3.9/site-packages/requests/models.py\", line 1021, in raise_for_status\n    raise HTTPError(http_error_msg, response=self)\nrequests.exceptions.HTTPError: 503 Server Error: Service Unavailable for url: http://server-api:8001/api/servers?fields=status","host":"server-monitor-7f8444fd47-gblcm","pname":"server-monitor","file":{"name":"utils.py","line":66}}
{"time":"2024-02-06T08:37:01.629Z","msg":"Job \"monitor (trigger: interval[0:00:01], next run at: 2024-02-06 08:37:02 UTC)\" raised an exception","pid":1,"tid":140274462336768,"pri":"ERROR","tname":"ThreadPoolExecutor-0_0","subsys":"apscheduler.executors.default","exc_info":"Traceback (most recent call last):\n  File \"/usr/local/lib/python3.9/site-packages/apscheduler/executors/base.py\", line 125, in run_job\n    retval = job.func(*job.args, **job.kwargs)\n  File \"/src/ericsson/server/monitor/features.py\", line 311, in monitor\n    for server_id, status in get_server_status(session, server_url, timeout=timeout):\n  File \"/src/ericsson/server/monitor/utils.py\", line 62, in get_server_status\n    resp.raise_for_status()\n  File \"/usr/local/lib/python3.9/site-packages/requests/models.py\", line 1021, in raise_for_status\n    raise HTTPError(http_error_msg, response=self)\nrequests.exceptions.HTTPError: 503 Server Error: Service Unavailable for url: http://server-api:8001/api/servers?fields=status","host":"server-monitor-7f8444fd47-gblcm","pname":"server-monitor","file":{"name":"base.py","line":131}}
{"time":"2024-02-06T08:37:02.625Z","msg":"An error occurred while fetching server statuses","pid":1,"tid":140274462336768,"pri":"WARN","tname":"ThreadPoolExecutor-0_0","subsys":"ericsson.server.monitor.utils","exc_info":"Traceback (most recent call last):\n  File \"/src/ericsson/server/monitor/utils.py\", line 62, in get_server_status\n    resp.raise_for_status()\n  File \"/usr/local/lib/python3.9/site-packages/requests/models.py\", line 1021, in raise_for_status\n    raise HTTPError(http_error_msg, response=self)\nrequests.exceptions.HTTPError: 503 Server Error: Service Unavailable for url: http://server-api:8001/api/servers?fields=status","host":"server-monitor-7f8444fd47-gblcm","pname":"server-monitor","file":{"name":"utils.py","line":66}}
{"time":"2024-02-06T08:37:02.625Z","msg":"Job \"monitor (trigger: interval[0:00:01], next run at: 2024-02-06 08:37:03 UTC)\" raised an exception","pid":1,"tid":140274462336768,"pri":"ERROR","tname":"ThreadPoolExecutor-0_0","subsys":"apscheduler.executors.default","exc_info":"Traceback (most recent call last):\n  File \"/usr/local/lib/python3.9/site-packages/apscheduler/executors/base.py\", line 125, in run_job\n    retval = job.func(*job.args, **job.kwargs)\n  File \"/src/ericsson/server/monitor/features.py\", line 311, in monitor\n    for server_id, status in get_server_status(session, server_url, timeout=timeout):\n  File \"/src/ericsson/server/monitor/utils.py\", line 62, in get_server_status\n    resp.raise_for_status()\n  File \"/usr/local/lib/python3.9/site-packages/requests/models.py\", line 1021, in raise_for_status\n    raise HTTPError(http_error_msg, response=self)\nrequests.exceptions.HTTPError: 503 Server Error: Service Unavailable for url: http://server-api:8001/api/servers?fields=status","host":"server-monitor-7f8444fd47-gblcm","pname":"server-monitor","file":{"name":"base.py","line":131}}
{"time":"2024-02-06T08:37:03.626Z","msg":"An error occurred while fetching server statuses","pid":1,"tid":140274462336768,"pri":"WARN","tname":"ThreadPoolExecutor-0_0","subsys":"ericsson.server.monitor.utils","exc_info":"Traceback (most recent call last):\n  File \"/src/ericsson/server/monitor/utils.py\", line 62, in get_server_status\n    resp.raise_for_status()\n  File \"/usr/local/lib/python3.9/site-packages/requests/models.py\", line 1021, in raise_for_status\n    raise HTTPError(http_error_msg, response=self)\nrequests.exceptions.HTTPError: 503 Server Error: Service Unavailable for url: http://server-api:8001/api/servers?fields=status","host":"server-monitor-7f8444fd47-gblcm","pname":"server-monitor","file":{"name":"utils.py","line":66}}
{"time":"2024-02-06T08:37:03.626Z","msg":"Job \"monitor (trigger: interval[0:00:01], next run at: 2024-02-06 08:37:04 UTC)\" raised an exception","pid":1,"tid":140274462336768,"pri":"ERROR","tname":"ThreadPoolExecutor-0_0","subsys":"apscheduler.executors.default","exc_info":"Traceback (most recent call last):\n  File \"/usr/local/lib/python3.9/site-packages/apscheduler/executors/base.py\", line 125, in run_job\n    retval = job.func(*job.args, **job.kwargs)\n  File \"/src/ericsson/server/monitor/features.py\", line 311, in monitor\n    for server_id, status in get_server_status(session, server_url, timeout=timeout):\n  File \"/src/ericsson/server/monitor/utils.py\", line 62, in get_server_status\n    resp.raise_for_status()\n  File \"/usr/local/lib/python3.9/site-packages/requests/models.py\", line 1021, in raise_for_status\n    raise HTTPError(http_error_msg, response=self)\nrequests.exceptions.HTTPError: 503 Server Error: Service Unavailable for url: http://server-api:8001/api/servers?fields=status","host":"server-monitor-7f8444fd47-gblcm","pname":"server-monitor","file":{"name":"base.py","line":131}}
{"time":"2024-02-06T08:37:04.625Z","msg":"An error occurred while fetching server statuses","pid":1,"tid":140274462336768,"pri":"WARN","tname":"ThreadPoolExecutor-0_0","subsys":"ericsson.server.monitor.utils","exc_info":"Traceback (most recent call last):\n  File \"/src/ericsson/server/monitor/utils.py\", line 62, in get_server_status\n    resp.raise_for_status()\n  File \"/usr/local/lib/python3.9/site-packages/requests/models.py\", line 1021, in raise_for_status\n    raise HTTPError(http_error_msg, response=self)\nrequests.exceptions.HTTPError: 503 Server Error: Service Unavailable for url: http://server-api:8001/api/servers?fields=status","host":"server-monitor-7f8444fd47-gblcm","pname":"server-monitor","file":{"name":"utils.py","line":66}}
{"time":"2024-02-06T08:37:04.625Z","msg":"Job \"monitor (trigger: interval[0:00:01], next run at: 2024-02-06 08:37:05 UTC)\" raised an exception","pid":1,"tid":140274462336768,"pri":"ERROR","tname":"ThreadPoolExecutor-0_0","subsys":"apscheduler.executors.default","exc_info":"Traceback (most recent call last):\n  File \"/usr/local/lib/python3.9/site-packages/apscheduler/executors/base.py\", line 125, in run_job\n    retval = job.func(*job.args, **job.kwargs)\n  File \"/src/ericsson/server/monitor/features.py\", line 311, in monitor\n    for server_id, status in get_server_status(session, server_url, timeout=timeout):\n  File \"/src/ericsson/server/monitor/utils.py\", line 62, in get_server_status\n    resp.raise_for_status()\n  File \"/usr/local/lib/python3.9/site-packages/requests/models.py\", line 1021, in raise_for_status\n    raise HTTPError(http_error_msg, response=self)\nrequests.exceptions.HTTPError: 503 Server Error: Service Unavailable for url: http://server-api:8001/api/servers?fields=status","host":"server-monitor-7f8444fd47-gblcm","pname":"server-monitor","file":{"name":"base.py","line":131}}
{"time":"2024-02-06T08:37:05.625Z","msg":"An error occurred while fetching server statuses","pid":1,"tid":140274462336768,"pri":"WARN","tname":"ThreadPoolExecutor-0_0","subsys":"ericsson.server.monitor.utils","exc_info":"Traceback (most recent call last):\n  File \"/src/ericsson/server/monitor/utils.py\", line 62, in get_server_status\n    resp.raise_for_status()\n  File \"/usr/local/lib/python3.9/site-packages/requests/models.py\", line 1021, in raise_for_status\n    raise HTTPError(http_error_msg, response=self)\nrequests.exceptions.HTTPError: 503 Server Error: Service Unavailable for url: http://server-api:8001/api/servers?fields=status","host":"server-monitor-7f8444fd47-gblcm","pname":"server-monitor","file":{"name":"utils.py","line":66}}
{"time":"2024-02-06T08:37:05.625Z","msg":"Job \"monitor (trigger: interval[0:00:01], next run at: 2024-02-06 08:37:06 UTC)\" raised an exception","pid":1,"tid":140274462336768,"pri":"ERROR","tname":"ThreadPoolExecutor-0_0","subsys":"apscheduler.executors.default","exc_info":"Traceback (most recent call last):\n  File \"/usr/local/lib/python3.9/site-packages/apscheduler/executors/base.py\", line 125, in run_job\n    retval = job.func(*job.args, **job.kwargs)\n  File \"/src/ericsson/server/monitor/features.py\", line 311, in monitor\n    for server_id, status in get_server_status(session, server_url, timeout=timeout):\n  File \"/src/ericsson/server/monitor/utils.py\", line 62, in get_server_status\n    resp.raise_for_status()\n  File \"/usr/local/lib/python3.9/site-packages/requests/models.py\", line 1021, in raise_for_status\n    raise HTTPError(http_error_msg, response=self)\nrequests.exceptions.HTTPError: 503 Server Error: Service Unavailable for url: http://server-api:8001/api/servers?fields=status","host":"server-monitor-7f8444fd47-gblcm","pname":"server-monitor","file":{"name":"base.py","line":131}}
{"time":"2024-02-06T08:37:06.626Z","msg":"An error occurred while fetching server statuses","pid":1,"tid":140274453944064,"pri":"WARN","tname":"ThreadPoolExecutor-0_1","subsys":"ericsson.server.monitor.utils","exc_info":"Traceback (most recent call last):\n  File \"/src/ericsson/server/monitor/utils.py\", line 62, in get_server_status\n    resp.raise_for_status()\n  File \"/usr/local/lib/python3.9/site-packages/requests/models.py\", line 1021, in raise_for_status\n    raise HTTPError(http_error_msg, response=self)\nrequests.exceptions.HTTPError: 503 Server Error: Service Unavailable for url: http://server-api:8001/api/servers?fields=status","host":"server-monitor-7f8444fd47-gblcm","pname":"server-monitor","file":{"name":"utils.py","line":66}}
{"time":"2024-02-06T08:37:06.626Z","msg":"Job \"monitor (trigger: interval[0:00:01], next run at: 2024-02-06 08:37:07 UTC)\" raised an exception","pid":1,"tid":140274453944064,"pri":"ERROR","tname":"ThreadPoolExecutor-0_1","subsys":"apscheduler.executors.default","exc_info":"Traceback (most recent call last):\n  File \"/usr/local/lib/python3.9/site-packages/apscheduler/executors/base.py\", line 125, in run_job\n    retval = job.func(*job.args, **job.kwargs)\n  File \"/src/ericsson/server/monitor/features.py\", line 311, in monitor\n    for server_id, status in get_server_status(session, server_url, timeout=timeout):\n  File \"/src/ericsson/server/monitor/utils.py\", line 62, in get_server_status\n    resp.raise_for_status()\n  File \"/usr/local/lib/python3.9/site-packages/requests/models.py\", line 1021, in raise_for_status\n    raise HTTPError(http_error_msg, response=self)\nrequests.exceptions.HTTPError: 503 Server Error: Service Unavailable for url: http://server-api:8001/api/servers?fields=status","host":"server-monitor-7f8444fd47-gblcm","pname":"server-monitor","file":{"name":"base.py","line":131}}
{"time":"2024-02-06T08:37:07.625Z","msg":"An error occurred while fetching server statuses","pid":1,"tid":140274462336768,"pri":"WARN","tname":"ThreadPoolExecutor-0_0","subsys":"ericsson.server.monitor.utils","exc_info":"Traceback (most recent call last):\n  File \"/src/ericsson/server/monitor/utils.py\", line 62, in get_server_status\n    resp.raise_for_status()\n  File \"/usr/local/lib/python3.9/site-packages/requests/models.py\", line 1021, in raise_for_status\n    raise HTTPError(http_error_msg, response=self)\nrequests.exceptions.HTTPError: 503 Server Error: Service Unavailable for url: http://server-api:8001/api/servers?fields=status","host":"server-monitor-7f8444fd47-gblcm","pname":"server-monitor","file":{"name":"utils.py","line":66}}
{"time":"2024-02-06T08:37:07.626Z","msg":"Job \"monitor (trigger: interval[0:00:01], next run at: 2024-02-06 08:37:08 UTC)\" raised an exception","pid":1,"tid":140274462336768,"pri":"ERROR","tname":"ThreadPoolExecutor-0_0","subsys":"apscheduler.executors.default","exc_info":"Traceback (most recent call last):\n  File \"/usr/local/lib/python3.9/site-packages/apscheduler/executors/base.py\", line 125, in run_job\n    retval = job.func(*job.args, **job.kwargs)\n  File \"/src/ericsson/server/monitor/features.py\", line 311, in monitor\n    for server_id, status in get_server_status(session, server_url, timeout=timeout):\n  File \"/src/ericsson/server/monitor/utils.py\", line 62, in get_server_status\n    resp.raise_for_status()\n  File \"/usr/local/lib/python3.9/site-packages/requests/models.py\", line 1021, in raise_for_status\n    raise HTTPError(http_error_msg, response=self)\nrequests.exceptions.HTTPError: 503 Server Error: Service Unavailable for url: http://server-api:8001/api/servers?fields=status","host":"server-monitor-7f8444fd47-gblcm","pname":"server-monitor","file":{"name":"base.py","line":131}}
{"time":"2024-02-06T08:37:08.625Z","msg":"An error occurred while fetching server statuses","pid":1,"tid":140274453944064,"pri":"WARN","tname":"ThreadPoolExecutor-0_1","subsys":"ericsson.server.monitor.utils","exc_info":"Traceback (most recent call last):\n  File \"/src/ericsson/server/monitor/utils.py\", line 62, in get_server_status\n    resp.raise_for_status()\n  File \"/usr/local/lib/python3.9/site-packages/requests/models.py\", line 1021, in raise_for_status\n    raise HTTPError(http_error_msg, response=self)\nrequests.exceptions.HTTPError: 503 Server Error: Service Unavailable for url: http://server-api:8001/api/servers?fields=status","host":"server-monitor-7f8444fd47-gblcm","pname":"server-monitor","file":{"name":"utils.py","line":66}}
{"time":"2024-02-06T08:37:08.626Z","msg":"Job \"monitor (trigger: interval[0:00:01], next run at: 2024-02-06 08:37:09 UTC)\" raised an exception","pid":1,"tid":140274453944064,"pri":"ERROR","tname":"ThreadPoolExecutor-0_1","subsys":"apscheduler.executors.default","exc_info":"Traceback (most recent call last):\n  File \"/usr/local/lib/python3.9/site-packages/apscheduler/executors/base.py\", line 125, in run_job\n    retval = job.func(*job.args, **job.kwargs)\n  File \"/src/ericsson/server/monitor/features.py\", line 311, in monitor\n    for server_id, status in get_server_status(session, server_url, timeout=timeout):\n  File \"/src/ericsson/server/monitor/utils.py\", line 62, in get_server_status\n    resp.raise_for_status()\n  File \"/usr/local/lib/python3.9/site-packages/requests/models.py\", line 1021, in raise_for_status\n    raise HTTPError(http_error_msg, response=self)\nrequests.exceptions.HTTPError: 503 Server Error: Service Unavailable for url: http://server-api:8001/api/servers?fields=status","host":"server-monitor-7f8444fd47-gblcm","pname":"server-monitor","file":{"name":"base.py","line":131}}
{"time":"2024-02-06T08:37:09.624Z","msg":"An error occurred while fetching server statuses","pid":1,"tid":140274462336768,"pri":"WARN","tname":"ThreadPoolExecutor-0_0","subsys":"ericsson.server.monitor.utils","exc_info":"Traceback (most recent call last):\n  File \"/src/ericsson/server/monitor/utils.py\", line 62, in get_server_status\n    resp.raise_for_status()\n  File \"/usr/local/lib/python3.9/site-packages/requests/models.py\", line 1021, in raise_for_status\n    raise HTTPError(http_error_msg, response=self)\nrequests.exceptions.HTTPError: 503 Server Error: Service Unavailable for url: http://server-api:8001/api/servers?fields=status","host":"server-monitor-7f8444fd47-gblcm","pname":"server-monitor","file":{"name":"utils.py","line":66}}
{"time":"2024-02-06T08:37:09.625Z","msg":"Job \"monitor (trigger: interval[0:00:01], next run at: 2024-02-06 08:37:10 UTC)\" raised an exception","pid":1,"tid":140274462336768,"pri":"ERROR","tname":"ThreadPoolExecutor-0_0","subsys":"apscheduler.executors.default","exc_info":"Traceback (most recent call last):\n  File \"/usr/local/lib/python3.9/site-packages/apscheduler/executors/base.py\", line 125, in run_job\n    retval = job.func(*job.args, **job.kwargs)\n  File \"/src/ericsson/server/monitor/features.py\", line 311, in monitor\n    for server_id, status in get_server_status(session, server_url, timeout=timeout):\n  File \"/src/ericsson/server/monitor/utils.py\", line 62, in get_server_status\n    resp.raise_for_status()\n  File \"/usr/local/lib/python3.9/site-packages/requests/models.py\", line 1021, in raise_for_status\n    raise HTTPError(http_error_msg, response=self)\nrequests.exceptions.HTTPError: 503 Server Error: Service Unavailable for url: http://server-api:8001/api/servers?fields=status","host":"server-monitor-7f8444fd47-gblcm","pname":"server-monitor","file":{"name":"base.py","line":131}}
{"time":"2024-02-06T08:37:10.624Z","msg":"An error occurred while fetching server statuses","pid":1,"tid":140274453944064,"pri":"WARN","tname":"ThreadPoolExecutor-0_1","subsys":"ericsson.server.monitor.utils","exc_info":"Traceback (most recent call last):\n  File \"/src/ericsson/server/monitor/utils.py\", line 62, in get_server_status\n    resp.raise_for_status()\n  File \"/usr/local/lib/python3.9/site-packages/requests/models.py\", line 1021, in raise_for_status\n    raise HTTPError(http_error_msg, response=self)\nrequests.exceptions.HTTPError: 503 Server Error: Service Unavailable for url: http://server-api:8001/api/servers?fields=status","host":"server-monitor-7f8444fd47-gblcm","pname":"server-monitor","file":{"name":"utils.py","line":66}}
{"time":"2024-02-06T08:37:10.624Z","msg":"Job \"monitor (trigger: interval[0:00:01], next run at: 2024-02-06 08:37:11 UTC)\" raised an exception","pid":1,"tid":140274453944064,"pri":"ERROR","tname":"ThreadPoolExecutor-0_1","subsys":"apscheduler.executors.default","exc_info":"Traceback (most recent call last):\n  File \"/usr/local/lib/python3.9/site-packages/apscheduler/executors/base.py\", line 125, in run_job\n    retval = job.func(*job.args, **job.kwargs)\n  File \"/src/ericsson/server/monitor/features.py\", line 311, in monitor\n    for server_id, status in get_server_status(session, server_url, timeout=timeout):\n  File \"/src/ericsson/server/monitor/utils.py\", line 62, in get_server_status\n    resp.raise_for_status()\n  File \"/usr/local/lib/python3.9/site-packages/requests/models.py\", line 1021, in raise_for_status\n    raise HTTPError(http_error_msg, response=self)\nrequests.exceptions.HTTPError: 503 Server Error: Service Unavailable for url: http://server-api:8001/api/servers?fields=status","host":"server-monitor-7f8444fd47-gblcm","pname":"server-monitor","file":{"name":"base.py","line":131}}
{"time":"2024-02-06T08:37:11.624Z","msg":"An error occurred while fetching server statuses","pid":1,"tid":140274453944064,"pri":"WARN","tname":"ThreadPoolExecutor-0_1","subsys":"ericsson.server.monitor.utils","exc_info":"Traceback (most recent call last):\n  File \"/src/ericsson/server/monitor/utils.py\", line 62, in get_server_status\n    resp.raise_for_status()\n  File \"/usr/local/lib/python3.9/site-packages/requests/models.py\", line 1021, in raise_for_status\n    raise HTTPError(http_error_msg, response=self)\nrequests.exceptions.HTTPError: 503 Server Error: Service Unavailable for url: http://server-api:8001/api/servers?fields=status","host":"server-monitor-7f8444fd47-gblcm","pname":"server-monitor","file":{"name":"utils.py","line":66}}
{"time":"2024-02-06T08:37:11.624Z","msg":"Job \"monitor (trigger: interval[0:00:01], next run at: 2024-02-06 08:37:12 UTC)\" raised an exception","pid":1,"tid":140274453944064,"pri":"ERROR","tname":"ThreadPoolExecutor-0_1","subsys":"apscheduler.executors.default","exc_info":"Traceback (most recent call last):\n  File \"/usr/local/lib/python3.9/site-packages/apscheduler/executors/base.py\", line 125, in run_job\n    retval = job.func(*job.args, **job.kwargs)\n  File \"/src/ericsson/server/monitor/features.py\", line 311, in monitor\n    for server_id, status in get_server_status(session, server_url, timeout=timeout):\n  File \"/src/ericsson/server/monitor/utils.py\", line 62, in get_server_status\n    resp.raise_for_status()\n  File \"/usr/local/lib/python3.9/site-packages/requests/models.py\", line 1021, in raise_for_status\n    raise HTTPError(http_error_msg, response=self)\nrequests.exceptions.HTTPError: 503 Server Error: Service Unavailable for url: http://server-api:8001/api/servers?fields=status","host":"server-monitor-7f8444fd47-gblcm","pname":"server-monitor","file":{"name":"base.py","line":131}}
{"time":"2024-02-06T08:37:12.624Z","msg":"An error occurred while fetching server statuses","pid":1,"tid":140274462336768,"pri":"WARN","tname":"ThreadPoolExecutor-0_0","subsys":"ericsson.server.monitor.utils","exc_info":"Traceback (most recent call last):\n  File \"/src/ericsson/server/monitor/utils.py\", line 62, in get_server_status\n    resp.raise_for_status()\n  File \"/usr/local/lib/python3.9/site-packages/requests/models.py\", line 1021, in raise_for_status\n    raise HTTPError(http_error_msg, response=self)\nrequests.exceptions.HTTPError: 503 Server Error: Service Unavailable for url: http://server-api:8001/api/servers?fields=status","host":"server-monitor-7f8444fd47-gblcm","pname":"server-monitor","file":{"name":"utils.py","line":66}}
{"time":"2024-02-06T08:37:12.624Z","msg":"Job \"monitor (trigger: interval[0:00:01], next run at: 2024-02-06 08:37:13 UTC)\" raised an exception","pid":1,"tid":140274462336768,"pri":"ERROR","tname":"ThreadPoolExecutor-0_0","subsys":"apscheduler.executors.default","exc_info":"Traceback (most recent call last):\n  File \"/usr/local/lib/python3.9/site-packages/apscheduler/executors/base.py\", line 125, in run_job\n    retval = job.func(*job.args, **job.kwargs)\n  File \"/src/ericsson/server/monitor/features.py\", line 311, in monitor\n    for server_id, status in get_server_status(session, server_url, timeout=timeout):\n  File \"/src/ericsson/server/monitor/utils.py\", line 62, in get_server_status\n    resp.raise_for_status()\n  File \"/usr/local/lib/python3.9/site-packages/requests/models.py\", line 1021, in raise_for_status\n    raise HTTPError(http_error_msg, response=self)\nrequests.exceptions.HTTPError: 503 Server Error: Service Unavailable for url: http://server-api:8001/api/servers?fields=status","host":"server-monitor-7f8444fd47-gblcm","pname":"server-monitor","file":{"name":"base.py","line":131}}
{"time":"2024-02-06T08:37:13.626Z","msg":"An error occurred while fetching server statuses","pid":1,"tid":140274453944064,"pri":"WARN","tname":"ThreadPoolExecutor-0_1","subsys":"ericsson.server.monitor.utils","exc_info":"Traceback (most recent call last):\n  File \"/src/ericsson/server/monitor/utils.py\", line 62, in get_server_status\n    resp.raise_for_status()\n  File \"/usr/local/lib/python3.9/site-packages/requests/models.py\", line 1021, in raise_for_status\n    raise HTTPError(http_error_msg, response=self)\nrequests.exceptions.HTTPError: 503 Server Error: Service Unavailable for url: http://server-api:8001/api/servers?fields=status","host":"server-monitor-7f8444fd47-gblcm","pname":"server-monitor","file":{"name":"utils.py","line":66}}
{"time":"2024-02-06T08:37:13.626Z","msg":"Job \"monitor (trigger: interval[0:00:01], next run at: 2024-02-06 08:37:14 UTC)\" raised an exception","pid":1,"tid":140274453944064,"pri":"ERROR","tname":"ThreadPoolExecutor-0_1","subsys":"apscheduler.executors.default","exc_info":"Traceback (most recent call last):\n  File \"/usr/local/lib/python3.9/site-packages/apscheduler/executors/base.py\", line 125, in run_job\n    retval = job.func(*job.args, **job.kwargs)\n  File \"/src/ericsson/server/monitor/features.py\", line 311, in monitor\n    for server_id, status in get_server_status(session, server_url, timeout=timeout):\n  File \"/src/ericsson/server/monitor/utils.py\", line 62, in get_server_status\n    resp.raise_for_status()\n  File \"/usr/local/lib/python3.9/site-packages/requests/models.py\", line 1021, in raise_for_status\n    raise HTTPError(http_error_msg, response=self)\nrequests.exceptions.HTTPError: 503 Server Error: Service Unavailable for url: http://server-api:8001/api/servers?fields=status","host":"server-monitor-7f8444fd47-gblcm","pname":"server-monitor","file":{"name":"base.py","line":131}}
{"time":"2024-02-06T08:37:14.624Z","msg":"An error occurred while fetching server statuses","pid":1,"tid":140274462336768,"pri":"WARN","tname":"ThreadPoolExecutor-0_0","subsys":"ericsson.server.monitor.utils","exc_info":"Traceback (most recent call last):\n  File \"/src/ericsson/server/monitor/utils.py\", line 62, in get_server_status\n    resp.raise_for_status()\n  File \"/usr/local/lib/python3.9/site-packages/requests/models.py\", line 1021, in raise_for_status\n    raise HTTPError(http_error_msg, response=self)\nrequests.exceptions.HTTPError: 503 Server Error: Service Unavailable for url: http://server-api:8001/api/servers?fields=status","host":"server-monitor-7f8444fd47-gblcm","pname":"server-monitor","file":{"name":"utils.py","line":66}}
{"time":"2024-02-06T08:37:14.625Z","msg":"Job \"monitor (trigger: interval[0:00:01], next run at: 2024-02-06 08:37:15 UTC)\" raised an exception","pid":1,"tid":140274462336768,"pri":"ERROR","tname":"ThreadPoolExecutor-0_0","subsys":"apscheduler.executors.default","exc_info":"Traceback (most recent call last):\n  File \"/usr/local/lib/python3.9/site-packages/apscheduler/executors/base.py\", line 125, in run_job\n    retval = job.func(*job.args, **job.kwargs)\n  File \"/src/ericsson/server/monitor/features.py\", line 311, in monitor\n    for server_id, status in get_server_status(session, server_url, timeout=timeout):\n  File \"/src/ericsson/server/monitor/utils.py\", line 62, in get_server_status\n    resp.raise_for_status()\n  File \"/usr/local/lib/python3.9/site-packages/requests/models.py\", line 1021, in raise_for_status\n    raise HTTPError(http_error_msg, response=self)\nrequests.exceptions.HTTPError: 503 Server Error: Service Unavailable for url: http://server-api:8001/api/servers?fields=status","host":"server-monitor-7f8444fd47-gblcm","pname":"server-monitor","file":{"name":"base.py","line":131}}
{"time":"2024-02-06T08:37:15.624Z","msg":"An error occurred while fetching server statuses","pid":1,"tid":140274453944064,"pri":"WARN","tname":"ThreadPoolExecutor-0_1","subsys":"ericsson.server.monitor.utils","exc_info":"Traceback (most recent call last):\n  File \"/src/ericsson/server/monitor/utils.py\", line 62, in get_server_status\n    resp.raise_for_status()\n  File \"/usr/local/lib/python3.9/site-packages/requests/models.py\", line 1021, in raise_for_status\n    raise HTTPError(http_error_msg, response=self)\nrequests.exceptions.HTTPError: 503 Server Error: Service Unavailable for url: http://server-api:8001/api/servers?fields=status","host":"server-monitor-7f8444fd47-gblcm","pname":"server-monitor","file":{"name":"utils.py","line":66}}
{"time":"2024-02-06T08:37:15.625Z","msg":"Job \"monitor (trigger: interval[0:00:01], next run at: 2024-02-06 08:37:16 UTC)\" raised an exception","pid":1,"tid":140274453944064,"pri":"ERROR","tname":"ThreadPoolExecutor-0_1","subsys":"apscheduler.executors.default","exc_info":"Traceback (most recent call last):\n  File \"/usr/local/lib/python3.9/site-packages/apscheduler/executors/base.py\", line 125, in run_job\n    retval = job.func(*job.args, **job.kwargs)\n  File \"/src/ericsson/server/monitor/features.py\", line 311, in monitor\n    for server_id, status in get_server_status(session, server_url, timeout=timeout):\n  File \"/src/ericsson/server/monitor/utils.py\", line 62, in get_server_status\n    resp.raise_for_status()\n  File \"/usr/local/lib/python3.9/site-packages/requests/models.py\", line 1021, in raise_for_status\n    raise HTTPError(http_error_msg, response=self)\nrequests.exceptions.HTTPError: 503 Server Error: Service Unavailable for url: http://server-api:8001/api/servers?fields=status","host":"server-monitor-7f8444fd47-gblcm","pname":"server-monitor","file":{"name":"base.py","line":131}}
{"time":"2024-02-06T08:37:16.624Z","msg":"An error occurred while fetching server statuses","pid":1,"tid":140274453944064,"pri":"WARN","tname":"ThreadPoolExecutor-0_1","subsys":"ericsson.server.monitor.utils","exc_info":"Traceback (most recent call last):\n  File \"/src/ericsson/server/monitor/utils.py\", line 62, in get_server_status\n    resp.raise_for_status()\n  File \"/usr/local/lib/python3.9/site-packages/requests/models.py\", line 1021, in raise_for_status\n    raise HTTPError(http_error_msg, response=self)\nrequests.exceptions.HTTPError: 503 Server Error: Service Unavailable for url: http://server-api:8001/api/servers?fields=status","host":"server-monitor-7f8444fd47-gblcm","pname":"server-monitor","file":{"name":"utils.py","line":66}}
{"time":"2024-02-06T08:37:16.624Z","msg":"Job \"monitor (trigger: interval[0:00:01], next run at: 2024-02-06 08:37:17 UTC)\" raised an exception","pid":1,"tid":140274453944064,"pri":"ERROR","tname":"ThreadPoolExecutor-0_1","subsys":"apscheduler.executors.default","exc_info":"Traceback (most recent call last):\n  File \"/usr/local/lib/python3.9/site-packages/apscheduler/executors/base.py\", line 125, in run_job\n    retval = job.func(*job.args, **job.kwargs)\n  File \"/src/ericsson/server/monitor/features.py\", line 311, in monitor\n    for server_id, status in get_server_status(session, server_url, timeout=timeout):\n  File \"/src/ericsson/server/monitor/utils.py\", line 62, in get_server_status\n    resp.raise_for_status()\n  File \"/usr/local/lib/python3.9/site-packages/requests/models.py\", line 1021, in raise_for_status\n    raise HTTPError(http_error_msg, response=self)\nrequests.exceptions.HTTPError: 503 Server Error: Service Unavailable for url: http://server-api:8001/api/servers?fields=status","host":"server-monitor-7f8444fd47-gblcm","pname":"server-monitor","file":{"name":"base.py","line":131}}
{"time":"2024-02-06T13:28:32.648Z","msg":"Configuration: {'alarm.publisher_id': 'server-monitor', 'alarm.resync_attempt_interval': '5', 'alarm.resync_interval': '30', 'api.server_url': 'http://server-api:8001/api/servers', 'api.timeout': '2', 'api.wait_on_error': '30', 'general.exclude_itself': 'False', 'general.ready_file_path': '/var/run/ericsson/server-monitor/ready', 'general.server_id': '', 'messaging.config': '/src/ericsson/server/monitor/data/default_message_types.json', 'messaging.server_url': 'amqp://guest:guest@rabbitmq-ha:5672/?heartbeat=30', 'mongolock.collection': 'server-monitor', 'mongolock.db': 'mediakindMongolock', 'mongolock.key': 'server-monitor', 'mongolock.owner': 'server-monitor', 'storage.host': 'localhost', 'storage.name': 'envivioCluster', 'storage.port': '27017', 'storage.url': 'mongodb://10.69.8.31:27017,10.69.8.32:27017/envivioCluster?replicaSet=repldb', 'storage_lock.alias': 'mediakindMongolock', 'storage_lock.host': 'localhost', 'storage_lock.port': '27017', 'storage_lock.url': 'mongodb://10.69.8.31:27017,10.69.8.32:27017/mediakindMongolock?replicaSet=repldb', 'storage_lock.username': 'MediaKind', 'time.interval': '1', 'time.readiness_interval': '5'}","pid":1,"tid":139707373060352,"pri":"INFO","tname":"MainThread","subsys":"ericsson.server.monitor.app","host":"server-monitor-7f8444fd47-gblcm","pname":"server-monitor","file":{"name":"app.py","line":192}}
{"time":"2024-02-06T13:28:32.648Z","msg":"Connecting to MongoDB...","pid":1,"tid":139707373060352,"pri":"INFO","tname":"MainThread","subsys":"ericsson.server.monitor.app","host":"server-monitor-7f8444fd47-gblcm","pname":"server-monitor","file":{"name":"app.py","line":215}}
{"time":"2024-02-06T13:28:34.721Z","msg":"Failed to connect to mongodb, retry in 1 second(s)","pid":1,"tid":139707373060352,"pri":"WARN","tname":"MainThread","subsys":"ericsson.mongo.connection","host":"server-monitor-7f8444fd47-gblcm","pname":"server-monitor","file":{"name":"connection.py","line":61}}
{"time":"2024-02-06T13:28:37.746Z","msg":"Failed to connect to mongodb, retry in 1 second(s)","pid":1,"tid":139707373060352,"pri":"WARN","tname":"MainThread","subsys":"ericsson.mongo.connection","host":"server-monitor-7f8444fd47-gblcm","pname":"server-monitor","file":{"name":"connection.py","line":61}}
{"time":"2024-02-06T13:28:40.778Z","msg":"Failed to connect to mongodb, retry in 1 second(s)","pid":1,"tid":139707373060352,"pri":"WARN","tname":"MainThread","subsys":"ericsson.mongo.connection","host":"server-monitor-7f8444fd47-gblcm","pname":"server-monitor","file":{"name":"connection.py","line":61}}
{"time":"2024-02-06T13:28:43.838Z","msg":"Failed to connect to mongodb, retry in 1 second(s)","pid":1,"tid":139707373060352,"pri":"WARN","tname":"MainThread","subsys":"ericsson.mongo.connection","host":"server-monitor-7f8444fd47-gblcm","pname":"server-monitor","file":{"name":"connection.py","line":61}}
{"time":"2024-02-06T13:28:46.906Z","msg":"Failed to connect to mongodb, retry in 1 second(s)","pid":1,"tid":139707373060352,"pri":"WARN","tname":"MainThread","subsys":"ericsson.mongo.connection","host":"server-monitor-7f8444fd47-gblcm","pname":"server-monitor","file":{"name":"connection.py","line":61}}
{"time":"2024-02-06T13:28:49.911Z","msg":"Failed to connect to mongodb, retry in 1 second(s)","pid":1,"tid":139707373060352,"pri":"WARN","tname":"MainThread","subsys":"ericsson.mongo.connection","host":"server-monitor-7f8444fd47-gblcm","pname":"server-monitor","file":{"name":"connection.py","line":61}}
{"time":"2024-02-06T13:28:52.916Z","msg":"Failed to connect to mongodb, retry in 1 second(s)","pid":1,"tid":139707373060352,"pri":"WARN","tname":"MainThread","subsys":"ericsson.mongo.connection","host":"server-monitor-7f8444fd47-gblcm","pname":"server-monitor","file":{"name":"connection.py","line":61}}
{"time":"2024-02-06T13:28:55.921Z","msg":"Failed to connect to mongodb, retry in 1 second(s)","pid":1,"tid":139707373060352,"pri":"WARN","tname":"MainThread","subsys":"ericsson.mongo.connection","host":"server-monitor-7f8444fd47-gblcm","pname":"server-monitor","file":{"name":"connection.py","line":61}}
{"time":"2024-02-06T13:28:58.926Z","msg":"Failed to connect to mongodb, retry in 1 second(s)","pid":1,"tid":139707373060352,"pri":"WARN","tname":"MainThread","subsys":"ericsson.mongo.connection","host":"server-monitor-7f8444fd47-gblcm","pname":"server-monitor","file":{"name":"connection.py","line":61}}
{"time":"2024-02-06T13:29:01.931Z","msg":"Failed to connect to mongodb, retry in 1 second(s)","pid":1,"tid":139707373060352,"pri":"WARN","tname":"MainThread","subsys":"ericsson.mongo.connection","host":"server-monitor-7f8444fd47-gblcm","pname":"server-monitor","file":{"name":"connection.py","line":61}}
{"time":"2024-02-06T13:29:04.936Z","msg":"Failed to connect to mongodb, retry in 1 second(s)","pid":1,"tid":139707373060352,"pri":"WARN","tname":"MainThread","subsys":"ericsson.mongo.connection","host":"server-monitor-7f8444fd47-gblcm","pname":"server-monitor","file":{"name":"connection.py","line":61}}
{"time":"2024-02-06T13:29:07.940Z","msg":"Failed to connect to mongodb, retry in 1 second(s)","pid":1,"tid":139707373060352,"pri":"WARN","tname":"MainThread","subsys":"ericsson.mongo.connection","host":"server-monitor-7f8444fd47-gblcm","pname":"server-monitor","file":{"name":"connection.py","line":61}}
{"time":"2024-02-06T13:29:09.016Z","msg":"Connected to mongodb","pid":1,"tid":139707373060352,"pri":"INFO","tname":"MainThread","subsys":"root","host":"server-monitor-7f8444fd47-gblcm","pname":"server-monitor","file":{"name":"connection.py","line":67}}
{"time":"2024-02-06T13:29:09.016Z","msg":"Initializing in-memory cache from database...","pid":1,"tid":139707373060352,"pri":"INFO","tname":"MainThread","subsys":"ericsson.server.monitor.app","host":"server-monitor-7f8444fd47-gblcm","pname":"server-monitor","file":{"name":"app.py","line":218}}
{"time":"2024-02-06T13:29:09.065Z","msg":"Cache initialized.","pid":1,"tid":139707373060352,"pri":"INFO","tname":"MainThread","subsys":"ericsson.server.monitor.app","host":"server-monitor-7f8444fd47-gblcm","pname":"server-monitor","file":{"name":"app.py","line":221}}
{"time":"2024-02-06T13:29:09.066Z","msg":"Connecting to AMQP hosts: ['amqp://guest:**@rabbitmq-ha:5672/']","pid":1,"tid":139707373060352,"pri":"INFO","tname":"MainThread","subsys":"ericsson.messaging.connection","host":"server-monitor-7f8444fd47-gblcm","pname":"server-monitor","file":{"name":"connection.py","line":60}}
{"time":"2024-02-06T13:29:09.107Z","msg":"Successfully initialized RabbitMQ Messaging.","pid":1,"tid":139707373060352,"pri":"INFO","tname":"MainThread","subsys":"ericsson.server.monitor.app","host":"server-monitor-7f8444fd47-gblcm","pname":"server-monitor","file":{"name":"app.py","line":157}}
{"time":"2024-02-06T13:29:09.211Z","msg":"Adding job tentatively -- it will be properly scheduled when the scheduler starts","pid":1,"tid":139707373060352,"pri":"INFO","tname":"MainThread","subsys":"apscheduler.scheduler","host":"server-monitor-7f8444fd47-gblcm","pname":"server-monitor","file":{"name":"base.py","line":444}}
{"time":"2024-02-06T13:29:09.253Z","msg":"Connected to mongodb","pid":1,"tid":139707373060352,"pri":"INFO","tname":"MainThread","subsys":"root","host":"server-monitor-7f8444fd47-gblcm","pname":"server-monitor","file":{"name":"connection.py","line":67}}
{"time":"2024-02-06T13:29:09.253Z","msg":"Adding job tentatively -- it will be properly scheduled when the scheduler starts","pid":1,"tid":139707373060352,"pri":"INFO","tname":"MainThread","subsys":"apscheduler.scheduler","host":"server-monitor-7f8444fd47-gblcm","pname":"server-monitor","file":{"name":"base.py","line":444}}
{"time":"2024-02-06T13:29:09.254Z","msg":"Adding job tentatively -- it will be properly scheduled when the scheduler starts","pid":1,"tid":139707373060352,"pri":"INFO","tname":"MainThread","subsys":"apscheduler.scheduler","host":"server-monitor-7f8444fd47-gblcm","pname":"server-monitor","file":{"name":"base.py","line":444}}
{"time":"2024-02-06T13:29:09.256Z","msg":"Added job \"monitor\" to job store \"default\"","pid":1,"tid":139707373060352,"pri":"INFO","tname":"MainThread","subsys":"apscheduler.scheduler","host":"server-monitor-7f8444fd47-gblcm","pname":"server-monitor","file":{"name":"base.py","line":885}}
{"time":"2024-02-06T13:29:09.256Z","msg":"Added job \"send_resync_message\" to job store \"default\"","pid":1,"tid":139707373060352,"pri":"INFO","tname":"MainThread","subsys":"apscheduler.scheduler","host":"server-monitor-7f8444fd47-gblcm","pname":"server-monitor","file":{"name":"base.py","line":885}}
{"time":"2024-02-06T13:29:09.257Z","msg":"Added job \"check_readiness\" to job store \"default\"","pid":1,"tid":139707373060352,"pri":"INFO","tname":"MainThread","subsys":"apscheduler.scheduler","host":"server-monitor-7f8444fd47-gblcm","pname":"server-monitor","file":{"name":"base.py","line":885}}
{"time":"2024-02-06T13:29:09.257Z","msg":"Scheduler started","pid":1,"tid":139707373060352,"pri":"INFO","tname":"MainThread","subsys":"apscheduler.scheduler","host":"server-monitor-7f8444fd47-gblcm","pname":"server-monitor","file":{"name":"base.py","line":171}}
{"time":"2024-02-06T13:29:11.213Z","msg":"Execution of job \"monitor (trigger: interval[0:00:01], next run at: 2024-02-06 13:29:11 UTC)\" skipped: maximum number of running instances reached (1)","pid":1,"tid":139706654238464,"pri":"WARN","tname":"APScheduler","subsys":"apscheduler.scheduler","host":"server-monitor-7f8444fd47-gblcm","pname":"server-monitor","file":{"name":"base.py","line":980}}
{"time":"2024-02-06T13:29:11.234Z","msg":"An error occurred while fetching server statuses","pid":1,"tid":139706645845760,"pri":"WARN","tname":"ThreadPoolExecutor-0_0","subsys":"ericsson.server.monitor.utils","exc_info":"Traceback (most recent call last):\n  File \"/usr/local/lib/python3.9/site-packages/urllib3/connection.py\", line 174, in _new_conn\n    conn = connection.create_connection(\n  File \"/usr/local/lib/python3.9/site-packages/urllib3/util/connection.py\", line 95, in create_connection\n    raise err\n  File \"/usr/local/lib/python3.9/site-packages/urllib3/util/connection.py\", line 85, in create_connection\n    sock.connect(sa)\nConnectionRefusedError: [Errno 111] Connection refused\n\nDuring handling of the above exception, another exception occurred:\n\nTraceback (most recent call last):\n  File \"/usr/local/lib/python3.9/site-packages/urllib3/connectionpool.py\", line 703, in urlopen\n    httplib_response = self._make_request(\n  File \"/usr/local/lib/python3.9/site-packages/urllib3/connectionpool.py\", line 398, in _make_request\n    conn.request(method, url, **httplib_request_kw)\n  File \"/usr/local/lib/python3.9/site-packages/urllib3/connection.py\", line 239, in request\n    super(HTTPConnection, self).request(method, url, body=body, headers=headers)\n  File \"/usr/lib64/python3.9/http/client.py\", line 1257, in request\n    self._send_request(method, url, body, headers, encode_chunked)\n  File \"/usr/lib64/python3.9/http/client.py\", line 1303, in _send_request\n    self.endheaders(body, encode_chunked=encode_chunked)\n  File \"/usr/lib64/python3.9/http/client.py\", line 1252, in endheaders\n    self._send_output(message_body, encode_chunked=encode_chunked)\n  File \"/usr/lib64/python3.9/http/client.py\", line 1012, in _send_output\n    self.send(msg)\n  File \"/usr/lib64/python3.9/http/client.py\", line 952, in send\n    self.connect()\n  File \"/usr/local/lib/python3.9/site-packages/urllib3/connection.py\", line 205, in connect\n    conn = self._new_conn()\n  File \"/usr/local/lib/python3.9/site-packages/urllib3/connection.py\", line 186, in _new_conn\n    raise NewConnectionError(\nurllib3.exceptions.NewConnectionError: <urllib3.connection.HTTPConnection object at 0x7f10204aa040>: Failed to establish a new connection: [Errno 111] Connection refused\n\nDuring handling of the above exception, another exception occurred:\n\nTraceback (most recent call last):\n  File \"/usr/local/lib/python3.9/site-packages/requests/adapters.py\", line 489, in send\n    resp = conn.urlopen(\n  File \"/usr/local/lib/python3.9/site-packages/urllib3/connectionpool.py\", line 787, in urlopen\n    retries = retries.increment(\n  File \"/usr/local/lib/python3.9/site-packages/urllib3/util/retry.py\", line 592, in increment\n    raise MaxRetryError(_pool, url, error or ResponseError(cause))\nurllib3.exceptions.MaxRetryError: HTTPConnectionPool(host='server-api', port=8001): Max retries exceeded with url: /api/servers?fields=status (Caused by NewConnectionError('<urllib3.connection.HTTPConnection object at 0x7f10204aa040>: Failed to establish a new connection: [Errno 111] Connection refused'))\n\nDuring handling of the above exception, another exception occurred:\n\nTraceback (most recent call last):\n  File \"/src/ericsson/server/monitor/utils.py\", line 61, in get_server_status\n    resp = session.get(server_url + \"?fields=status\", timeout=timeout)\n  File \"/usr/local/lib/python3.9/site-packages/requests/sessions.py\", line 600, in get\n    return self.request(\"GET\", url, **kwargs)\n  File \"/usr/local/lib/python3.9/site-packages/requests/sessions.py\", line 587, in request\n    resp = self.send(prep, **send_kwargs)\n  File \"/usr/local/lib/python3.9/site-packages/requests/sessions.py\", line 701, in send\n    r = adapter.send(request, **kwargs)\n  File \"/usr/local/lib/python3.9/site-packages/requests/adapters.py\", line 565, in send\n    raise ConnectionError(e, request=request)\nrequests.exceptions.ConnectionError: HTTPConnectionPool(host='server-api', port=8001): Max retries exceeded with url: /api/servers?fields=status (Caused by NewConnectionError('<urllib3.connection.HTTPConnection object at 0x7f10204aa040>: Failed to establish a new connection: [Errno 111] Connection refused'))","host":"server-monitor-7f8444fd47-gblcm","pname":"server-monitor","file":{"name":"utils.py","line":66}}
{"time":"2024-02-06T13:29:11.235Z","msg":"Job \"monitor (trigger: interval[0:00:01], next run at: 2024-02-06 13:29:12 UTC)\" raised an exception","pid":1,"tid":139706645845760,"pri":"ERROR","tname":"ThreadPoolExecutor-0_0","subsys":"apscheduler.executors.default","exc_info":"Traceback (most recent call last):\n  File \"/usr/local/lib/python3.9/site-packages/urllib3/connection.py\", line 174, in _new_conn\n    conn = connection.create_connection(\n  File \"/usr/local/lib/python3.9/site-packages/urllib3/util/connection.py\", line 95, in create_connection\n    raise err\n  File \"/usr/local/lib/python3.9/site-packages/urllib3/util/connection.py\", line 85, in create_connection\n    sock.connect(sa)\nConnectionRefusedError: [Errno 111] Connection refused\n\nDuring handling of the above exception, another exception occurred:\n\nTraceback (most recent call last):\n  File \"/usr/local/lib/python3.9/site-packages/urllib3/connectionpool.py\", line 703, in urlopen\n    httplib_response = self._make_request(\n  File \"/usr/local/lib/python3.9/site-packages/urllib3/connectionpool.py\", line 398, in _make_request\n    conn.request(method, url, **httplib_request_kw)\n  File \"/usr/local/lib/python3.9/site-packages/urllib3/connection.py\", line 239, in request\n    super(HTTPConnection, self).request(method, url, body=body, headers=headers)\n  File \"/usr/lib64/python3.9/http/client.py\", line 1257, in request\n    self._send_request(method, url, body, headers, encode_chunked)\n  File \"/usr/lib64/python3.9/http/client.py\", line 1303, in _send_request\n    self.endheaders(body, encode_chunked=encode_chunked)\n  File \"/usr/lib64/python3.9/http/client.py\", line 1252, in endheaders\n    self._send_output(message_body, encode_chunked=encode_chunked)\n  File \"/usr/lib64/python3.9/http/client.py\", line 1012, in _send_output\n    self.send(msg)\n  File \"/usr/lib64/python3.9/http/client.py\", line 952, in send\n    self.connect()\n  File \"/usr/local/lib/python3.9/site-packages/urllib3/connection.py\", line 205, in connect\n    conn = self._new_conn()\n  File \"/usr/local/lib/python3.9/site-packages/urllib3/connection.py\", line 186, in _new_conn\n    raise NewConnectionError(\nurllib3.exceptions.NewConnectionError: <urllib3.connection.HTTPConnection object at 0x7f10204aa040>: Failed to establish a new connection: [Errno 111] Connection refused\n\nDuring handling of the above exception, another exception occurred:\n\nTraceback (most recent call last):\n  File \"/usr/local/lib/python3.9/site-packages/requests/adapters.py\", line 489, in send\n    resp = conn.urlopen(\n  File \"/usr/local/lib/python3.9/site-packages/urllib3/connectionpool.py\", line 787, in urlopen\n    retries = retries.increment(\n  File \"/usr/local/lib/python3.9/site-packages/urllib3/util/retry.py\", line 592, in increment\n    raise MaxRetryError(_pool, url, error or ResponseError(cause))\nurllib3.exceptions.MaxRetryError: HTTPConnectionPool(host='server-api', port=8001): Max retries exceeded with url: /api/servers?fields=status (Caused by NewConnectionError('<urllib3.connection.HTTPConnection object at 0x7f10204aa040>: Failed to establish a new connection: [Errno 111] Connection refused'))\n\nDuring handling of the above exception, another exception occurred:\n\nTraceback (most recent call last):\n  File \"/usr/local/lib/python3.9/site-packages/apscheduler/executors/base.py\", line 125, in run_job\n    retval = job.func(*job.args, **job.kwargs)\n  File \"/src/ericsson/server/monitor/features.py\", line 311, in monitor\n    for server_id, status in get_server_status(session, server_url, timeout=timeout):\n  File \"/src/ericsson/server/monitor/utils.py\", line 61, in get_server_status\n    resp = session.get(server_url + \"?fields=status\", timeout=timeout)\n  File \"/usr/local/lib/python3.9/site-packages/requests/sessions.py\", line 600, in get\n    return self.request(\"GET\", url, **kwargs)\n  File \"/usr/local/lib/python3.9/site-packages/requests/sessions.py\", line 587, in request\n    resp = self.send(prep, **send_kwargs)\n  File \"/usr/local/lib/python3.9/site-packages/requests/sessions.py\", line 701, in send\n    r = adapter.send(request, **kwargs)\n  File \"/usr/local/lib/python3.9/site-packages/requests/adapters.py\", line 565, in send\n    raise ConnectionError(e, request=request)\nrequests.exceptions.ConnectionError: HTTPConnectionPool(host='server-api', port=8001): Max retries exceeded with url: /api/servers?fields=status (Caused by NewConnectionError('<urllib3.connection.HTTPConnection object at 0x7f10204aa040>: Failed to establish a new connection: [Errno 111] Connection refused'))","host":"server-monitor-7f8444fd47-gblcm","pname":"server-monitor","file":{"name":"base.py","line":131}}
{"time":"2024-02-06T13:29:13.211Z","msg":"Execution of job \"monitor (trigger: interval[0:00:01], next run at: 2024-02-06 13:29:13 UTC)\" skipped: maximum number of running instances reached (1)","pid":1,"tid":139706654238464,"pri":"WARN","tname":"APScheduler","subsys":"apscheduler.scheduler","host":"server-monitor-7f8444fd47-gblcm","pname":"server-monitor","file":{"name":"base.py","line":980}}
{"time":"2024-02-06T13:29:13.218Z","msg":"An error occurred while fetching server statuses","pid":1,"tid":139706645845760,"pri":"WARN","tname":"ThreadPoolExecutor-0_0","subsys":"ericsson.server.monitor.utils","exc_info":"Traceback (most recent call last):\n  File \"/usr/local/lib/python3.9/site-packages/urllib3/connection.py\", line 174, in _new_conn\n    conn = connection.create_connection(\n  File \"/usr/local/lib/python3.9/site-packages/urllib3/util/connection.py\", line 95, in create_connection\n    raise err\n  File \"/usr/local/lib/python3.9/site-packages/urllib3/util/connection.py\", line 85, in create_connection\n    sock.connect(sa)\nConnectionRefusedError: [Errno 111] Connection refused\n\nDuring handling of the above exception, another exception occurred:\n\nTraceback (most recent call last):\n  File \"/usr/local/lib/python3.9/site-packages/urllib3/connectionpool.py\", line 703, in urlopen\n    httplib_response = self._make_request(\n  File \"/usr/local/lib/python3.9/site-packages/urllib3/connectionpool.py\", line 398, in _make_request\n    conn.request(method, url, **httplib_request_kw)\n  File \"/usr/local/lib/python3.9/site-packages/urllib3/connection.py\", line 239, in request\n    super(HTTPConnection, self).request(method, url, body=body, headers=headers)\n  File \"/usr/lib64/python3.9/http/client.py\", line 1257, in request\n    self._send_request(method, url, body, headers, encode_chunked)\n  File \"/usr/lib64/python3.9/http/client.py\", line 1303, in _send_request\n    self.endheaders(body, encode_chunked=encode_chunked)\n  File \"/usr/lib64/python3.9/http/client.py\", line 1252, in endheaders\n    self._send_output(message_body, encode_chunked=encode_chunked)\n  File \"/usr/lib64/python3.9/http/client.py\", line 1012, in _send_output\n    self.send(msg)\n  File \"/usr/lib64/python3.9/http/client.py\", line 952, in send\n    self.connect()\n  File \"/usr/local/lib/python3.9/site-packages/urllib3/connection.py\", line 205, in connect\n    conn = self._new_conn()\n  File \"/usr/local/lib/python3.9/site-packages/urllib3/connection.py\", line 186, in _new_conn\n    raise NewConnectionError(\nurllib3.exceptions.NewConnectionError: <urllib3.connection.HTTPConnection object at 0x7f1020db0d90>: Failed to establish a new connection: [Errno 111] Connection refused\n\nDuring handling of the above exception, another exception occurred:\n\nTraceback (most recent call last):\n  File \"/usr/local/lib/python3.9/site-packages/requests/adapters.py\", line 489, in send\n    resp = conn.urlopen(\n  File \"/usr/local/lib/python3.9/site-packages/urllib3/connectionpool.py\", line 787, in urlopen\n    retries = retries.increment(\n  File \"/usr/local/lib/python3.9/site-packages/urllib3/util/retry.py\", line 592, in increment\n    raise MaxRetryError(_pool, url, error or ResponseError(cause))\nurllib3.exceptions.MaxRetryError: HTTPConnectionPool(host='server-api', port=8001): Max retries exceeded with url: /api/servers?fields=status (Caused by NewConnectionError('<urllib3.connection.HTTPConnection object at 0x7f1020db0d90>: Failed to establish a new connection: [Errno 111] Connection refused'))\n\nDuring handling of the above exception, another exception occurred:\n\nTraceback (most recent call last):\n  File \"/src/ericsson/server/monitor/utils.py\", line 61, in get_server_status\n    resp = session.get(server_url + \"?fields=status\", timeout=timeout)\n  File \"/usr/local/lib/python3.9/site-packages/requests/sessions.py\", line 600, in get\n    return self.request(\"GET\", url, **kwargs)\n  File \"/usr/local/lib/python3.9/site-packages/requests/sessions.py\", line 587, in request\n    resp = self.send(prep, **send_kwargs)\n  File \"/usr/local/lib/python3.9/site-packages/requests/sessions.py\", line 701, in send\n    r = adapter.send(request, **kwargs)\n  File \"/usr/local/lib/python3.9/site-packages/requests/adapters.py\", line 565, in send\n    raise ConnectionError(e, request=request)\nrequests.exceptions.ConnectionError: HTTPConnectionPool(host='server-api', port=8001): Max retries exceeded with url: /api/servers?fields=status (Caused by NewConnectionError('<urllib3.connection.HTTPConnection object at 0x7f1020db0d90>: Failed to establish a new connection: [Errno 111] Connection refused'))","host":"server-monitor-7f8444fd47-gblcm","pname":"server-monitor","file":{"name":"utils.py","line":66}}
{"time":"2024-02-06T13:29:13.218Z","msg":"Job \"monitor (trigger: interval[0:00:01], next run at: 2024-02-06 13:29:14 UTC)\" raised an exception","pid":1,"tid":139706645845760,"pri":"ERROR","tname":"ThreadPoolExecutor-0_0","subsys":"apscheduler.executors.default","exc_info":"Traceback (most recent call last):\n  File \"/usr/local/lib/python3.9/site-packages/urllib3/connection.py\", line 174, in _new_conn\n    conn = connection.create_connection(\n  File \"/usr/local/lib/python3.9/site-packages/urllib3/util/connection.py\", line 95, in create_connection\n    raise err\n  File \"/usr/local/lib/python3.9/site-packages/urllib3/util/connection.py\", line 85, in create_connection\n    sock.connect(sa)\nConnectionRefusedError: [Errno 111] Connection refused\n\nDuring handling of the above exception, another exception occurred:\n\nTraceback (most recent call last):\n  File \"/usr/local/lib/python3.9/site-packages/urllib3/connectionpool.py\", line 703, in urlopen\n    httplib_response = self._make_request(\n  File \"/usr/local/lib/python3.9/site-packages/urllib3/connectionpool.py\", line 398, in _make_request\n    conn.request(method, url, **httplib_request_kw)\n  File \"/usr/local/lib/python3.9/site-packages/urllib3/connection.py\", line 239, in request\n    super(HTTPConnection, self).request(method, url, body=body, headers=headers)\n  File \"/usr/lib64/python3.9/http/client.py\", line 1257, in request\n    self._send_request(method, url, body, headers, encode_chunked)\n  File \"/usr/lib64/python3.9/http/client.py\", line 1303, in _send_request\n    self.endheaders(body, encode_chunked=encode_chunked)\n  File \"/usr/lib64/python3.9/http/client.py\", line 1252, in endheaders\n    self._send_output(message_body, encode_chunked=encode_chunked)\n  File \"/usr/lib64/python3.9/http/client.py\", line 1012, in _send_output\n    self.send(msg)\n  File \"/usr/lib64/python3.9/http/client.py\", line 952, in send\n    self.connect()\n  File \"/usr/local/lib/python3.9/site-packages/urllib3/connection.py\", line 205, in connect\n    conn = self._new_conn()\n  File \"/usr/local/lib/python3.9/site-packages/urllib3/connection.py\", line 186, in _new_conn\n    raise NewConnectionError(\nurllib3.exceptions.NewConnectionError: <urllib3.connection.HTTPConnection object at 0x7f1020db0d90>: Failed to establish a new connection: [Errno 111] Connection refused\n\nDuring handling of the above exception, another exception occurred:\n\nTraceback (most recent call last):\n  File \"/usr/local/lib/python3.9/site-packages/requests/adapters.py\", line 489, in send\n    resp = conn.urlopen(\n  File \"/usr/local/lib/python3.9/site-packages/urllib3/connectionpool.py\", line 787, in urlopen\n    retries = retries.increment(\n  File \"/usr/local/lib/python3.9/site-packages/urllib3/util/retry.py\", line 592, in increment\n    raise MaxRetryError(_pool, url, error or ResponseError(cause))\nurllib3.exceptions.MaxRetryError: HTTPConnectionPool(host='server-api', port=8001): Max retries exceeded with url: /api/servers?fields=status (Caused by NewConnectionError('<urllib3.connection.HTTPConnection object at 0x7f1020db0d90>: Failed to establish a new connection: [Errno 111] Connection refused'))\n\nDuring handling of the above exception, another exception occurred:\n\nTraceback (most recent call last):\n  File \"/usr/local/lib/python3.9/site-packages/apscheduler/executors/base.py\", line 125, in run_job\n    retval = job.func(*job.args, **job.kwargs)\n  File \"/src/ericsson/server/monitor/features.py\", line 311, in monitor\n    for server_id, status in get_server_status(session, server_url, timeout=timeout):\n  File \"/src/ericsson/server/monitor/utils.py\", line 61, in get_server_status\n    resp = session.get(server_url + \"?fields=status\", timeout=timeout)\n  File \"/usr/local/lib/python3.9/site-packages/requests/sessions.py\", line 600, in get\n    return self.request(\"GET\", url, **kwargs)\n  File \"/usr/local/lib/python3.9/site-packages/requests/sessions.py\", line 587, in request\n    resp = self.send(prep, **send_kwargs)\n  File \"/usr/local/lib/python3.9/site-packages/requests/sessions.py\", line 701, in send\n    r = adapter.send(request, **kwargs)\n  File \"/usr/local/lib/python3.9/site-packages/requests/adapters.py\", line 565, in send\n    raise ConnectionError(e, request=request)\nrequests.exceptions.ConnectionError: HTTPConnectionPool(host='server-api', port=8001): Max retries exceeded with url: /api/servers?fields=status (Caused by NewConnectionError('<urllib3.connection.HTTPConnection object at 0x7f1020db0d90>: Failed to establish a new connection: [Errno 111] Connection refused'))","host":"server-monitor-7f8444fd47-gblcm","pname":"server-monitor","file":{"name":"base.py","line":131}}
{"time":"2024-02-06T13:29:15.212Z","msg":"Execution of job \"monitor (trigger: interval[0:00:01], next run at: 2024-02-06 13:29:15 UTC)\" skipped: maximum number of running instances reached (1)","pid":1,"tid":139706654238464,"pri":"WARN","tname":"APScheduler","subsys":"apscheduler.scheduler","host":"server-monitor-7f8444fd47-gblcm","pname":"server-monitor","file":{"name":"base.py","line":980}}
{"time":"2024-02-06T13:29:15.267Z","msg":"An error occurred while fetching server statuses","pid":1,"tid":139706645845760,"pri":"WARN","tname":"ThreadPoolExecutor-0_0","subsys":"ericsson.server.monitor.utils","exc_info":"Traceback (most recent call last):\n  File \"/usr/local/lib/python3.9/site-packages/urllib3/connection.py\", line 174, in _new_conn\n    conn = connection.create_connection(\n  File \"/usr/local/lib/python3.9/site-packages/urllib3/util/connection.py\", line 95, in create_connection\n    raise err\n  File \"/usr/local/lib/python3.9/site-packages/urllib3/util/connection.py\", line 85, in create_connection\n    sock.connect(sa)\nConnectionRefusedError: [Errno 111] Connection refused\n\nDuring handling of the above exception, another exception occurred:\n\nTraceback (most recent call last):\n  File \"/usr/local/lib/python3.9/site-packages/urllib3/connectionpool.py\", line 703, in urlopen\n    httplib_response = self._make_request(\n  File \"/usr/local/lib/python3.9/site-packages/urllib3/connectionpool.py\", line 398, in _make_request\n    conn.request(method, url, **httplib_request_kw)\n  File \"/usr/local/lib/python3.9/site-packages/urllib3/connection.py\", line 239, in request\n    super(HTTPConnection, self).request(method, url, body=body, headers=headers)\n  File \"/usr/lib64/python3.9/http/client.py\", line 1257, in request\n    self._send_request(method, url, body, headers, encode_chunked)\n  File \"/usr/lib64/python3.9/http/client.py\", line 1303, in _send_request\n    self.endheaders(body, encode_chunked=encode_chunked)\n  File \"/usr/lib64/python3.9/http/client.py\", line 1252, in endheaders\n    self._send_output(message_body, encode_chunked=encode_chunked)\n  File \"/usr/lib64/python3.9/http/client.py\", line 1012, in _send_output\n    self.send(msg)\n  File \"/usr/lib64/python3.9/http/client.py\", line 952, in send\n    self.connect()\n  File \"/usr/local/lib/python3.9/site-packages/urllib3/connection.py\", line 205, in connect\n    conn = self._new_conn()\n  File \"/usr/local/lib/python3.9/site-packages/urllib3/connection.py\", line 186, in _new_conn\n    raise NewConnectionError(\nurllib3.exceptions.NewConnectionError: <urllib3.connection.HTTPConnection object at 0x7f102045a190>: Failed to establish a new connection: [Errno 111] Connection refused\n\nDuring handling of the above exception, another exception occurred:\n\nTraceback (most recent call last):\n  File \"/usr/local/lib/python3.9/site-packages/requests/adapters.py\", line 489, in send\n    resp = conn.urlopen(\n  File \"/usr/local/lib/python3.9/site-packages/urllib3/connectionpool.py\", line 787, in urlopen\n    retries = retries.increment(\n  File \"/usr/local/lib/python3.9/site-packages/urllib3/util/retry.py\", line 592, in increment\n    raise MaxRetryError(_pool, url, error or ResponseError(cause))\nurllib3.exceptions.MaxRetryError: HTTPConnectionPool(host='server-api', port=8001): Max retries exceeded with url: /api/servers?fields=status (Caused by NewConnectionError('<urllib3.connection.HTTPConnection object at 0x7f102045a190>: Failed to establish a new connection: [Errno 111] Connection refused'))\n\nDuring handling of the above exception, another exception occurred:\n\nTraceback (most recent call last):\n  File \"/src/ericsson/server/monitor/utils.py\", line 61, in get_server_status\n    resp = session.get(server_url + \"?fields=status\", timeout=timeout)\n  File \"/usr/local/lib/python3.9/site-packages/requests/sessions.py\", line 600, in get\n    return self.request(\"GET\", url, **kwargs)\n  File \"/usr/local/lib/python3.9/site-packages/requests/sessions.py\", line 587, in request\n    resp = self.send(prep, **send_kwargs)\n  File \"/usr/local/lib/python3.9/site-packages/requests/sessions.py\", line 701, in send\n    r = adapter.send(request, **kwargs)\n  File \"/usr/local/lib/python3.9/site-packages/requests/adapters.py\", line 565, in send\n    raise ConnectionError(e, request=request)\nrequests.exceptions.ConnectionError: HTTPConnectionPool(host='server-api', port=8001): Max retries exceeded with url: /api/servers?fields=status (Caused by NewConnectionError('<urllib3.connection.HTTPConnection object at 0x7f102045a190>: Failed to establish a new connection: [Errno 111] Connection refused'))","host":"server-monitor-7f8444fd47-gblcm","pname":"server-monitor","file":{"name":"utils.py","line":66}}
{"time":"2024-02-06T13:29:15.267Z","msg":"Job \"monitor (trigger: interval[0:00:01], next run at: 2024-02-06 13:29:16 UTC)\" raised an exception","pid":1,"tid":139706645845760,"pri":"ERROR","tname":"ThreadPoolExecutor-0_0","subsys":"apscheduler.executors.default","exc_info":"Traceback (most recent call last):\n  File \"/usr/local/lib/python3.9/site-packages/urllib3/connection.py\", line 174, in _new_conn\n    conn = connection.create_connection(\n  File \"/usr/local/lib/python3.9/site-packages/urllib3/util/connection.py\", line 95, in create_connection\n    raise err\n  File \"/usr/local/lib/python3.9/site-packages/urllib3/util/connection.py\", line 85, in create_connection\n    sock.connect(sa)\nConnectionRefusedError: [Errno 111] Connection refused\n\nDuring handling of the above exception, another exception occurred:\n\nTraceback (most recent call last):\n  File \"/usr/local/lib/python3.9/site-packages/urllib3/connectionpool.py\", line 703, in urlopen\n    httplib_response = self._make_request(\n  File \"/usr/local/lib/python3.9/site-packages/urllib3/connectionpool.py\", line 398, in _make_request\n    conn.request(method, url, **httplib_request_kw)\n  File \"/usr/local/lib/python3.9/site-packages/urllib3/connection.py\", line 239, in request\n    super(HTTPConnection, self).request(method, url, body=body, headers=headers)\n  File \"/usr/lib64/python3.9/http/client.py\", line 1257, in request\n    self._send_request(method, url, body, headers, encode_chunked)\n  File \"/usr/lib64/python3.9/http/client.py\", line 1303, in _send_request\n    self.endheaders(body, encode_chunked=encode_chunked)\n  File \"/usr/lib64/python3.9/http/client.py\", line 1252, in endheaders\n    self._send_output(message_body, encode_chunked=encode_chunked)\n  File \"/usr/lib64/python3.9/http/client.py\", line 1012, in _send_output\n    self.send(msg)\n  File \"/usr/lib64/python3.9/http/client.py\", line 952, in send\n    self.connect()\n  File \"/usr/local/lib/python3.9/site-packages/urllib3/connection.py\", line 205, in connect\n    conn = self._new_conn()\n  File \"/usr/local/lib/python3.9/site-packages/urllib3/connection.py\", line 186, in _new_conn\n    raise NewConnectionError(\nurllib3.exceptions.NewConnectionError: <urllib3.connection.HTTPConnection object at 0x7f102045a190>: Failed to establish a new connection: [Errno 111] Connection refused\n\nDuring handling of the above exception, another exception occurred:\n\nTraceback (most recent call last):\n  File \"/usr/local/lib/python3.9/site-packages/requests/adapters.py\", line 489, in send\n    resp = conn.urlopen(\n  File \"/usr/local/lib/python3.9/site-packages/urllib3/connectionpool.py\", line 787, in urlopen\n    retries = retries.increment(\n  File \"/usr/local/lib/python3.9/site-packages/urllib3/util/retry.py\", line 592, in increment\n    raise MaxRetryError(_pool, url, error or ResponseError(cause))\nurllib3.exceptions.MaxRetryError: HTTPConnectionPool(host='server-api', port=8001): Max retries exceeded with url: /api/servers?fields=status (Caused by NewConnectionError('<urllib3.connection.HTTPConnection object at 0x7f102045a190>: Failed to establish a new connection: [Errno 111] Connection refused'))\n\nDuring handling of the above exception, another exception occurred:\n\nTraceback (most recent call last):\n  File \"/usr/local/lib/python3.9/site-packages/apscheduler/executors/base.py\", line 125, in run_job\n    retval = job.func(*job.args, **job.kwargs)\n  File \"/src/ericsson/server/monitor/features.py\", line 311, in monitor\n    for server_id, status in get_server_status(session, server_url, timeout=timeout):\n  File \"/src/ericsson/server/monitor/utils.py\", line 61, in get_server_status\n    resp = session.get(server_url + \"?fields=status\", timeout=timeout)\n  File \"/usr/local/lib/python3.9/site-packages/requests/sessions.py\", line 600, in get\n    return self.request(\"GET\", url, **kwargs)\n  File \"/usr/local/lib/python3.9/site-packages/requests/sessions.py\", line 587, in request\n    resp = self.send(prep, **send_kwargs)\n  File \"/usr/local/lib/python3.9/site-packages/requests/sessions.py\", line 701, in send\n    r = adapter.send(request, **kwargs)\n  File \"/usr/local/lib/python3.9/site-packages/requests/adapters.py\", line 565, in send\n    raise ConnectionError(e, request=request)\nrequests.exceptions.ConnectionError: HTTPConnectionPool(host='server-api', port=8001): Max retries exceeded with url: /api/servers?fields=status (Caused by NewConnectionError('<urllib3.connection.HTTPConnection object at 0x7f102045a190>: Failed to establish a new connection: [Errno 111] Connection refused'))","host":"server-monitor-7f8444fd47-gblcm","pname":"server-monitor","file":{"name":"base.py","line":131}}
{"time":"2024-02-06T13:29:17.211Z","msg":"Execution of job \"monitor (trigger: interval[0:00:01], next run at: 2024-02-06 13:29:17 UTC)\" skipped: maximum number of running instances reached (1)","pid":1,"tid":139706654238464,"pri":"WARN","tname":"APScheduler","subsys":"apscheduler.scheduler","host":"server-monitor-7f8444fd47-gblcm","pname":"server-monitor","file":{"name":"base.py","line":980}}
{"time":"2024-02-06T13:29:17.250Z","msg":"An error occurred while fetching server statuses","pid":1,"tid":139706150938368,"pri":"WARN","tname":"ThreadPoolExecutor-0_2","subsys":"ericsson.server.monitor.utils","exc_info":"Traceback (most recent call last):\n  File \"/usr/local/lib/python3.9/site-packages/urllib3/connection.py\", line 174, in _new_conn\n    conn = connection.create_connection(\n  File \"/usr/local/lib/python3.9/site-packages/urllib3/util/connection.py\", line 95, in create_connection\n    raise err\n  File \"/usr/local/lib/python3.9/site-packages/urllib3/util/connection.py\", line 85, in create_connection\n    sock.connect(sa)\nConnectionRefusedError: [Errno 111] Connection refused\n\nDuring handling of the above exception, another exception occurred:\n\nTraceback (most recent call last):\n  File \"/usr/local/lib/python3.9/site-packages/urllib3/connectionpool.py\", line 703, in urlopen\n    httplib_response = self._make_request(\n  File \"/usr/local/lib/python3.9/site-packages/urllib3/connectionpool.py\", line 398, in _make_request\n    conn.request(method, url, **httplib_request_kw)\n  File \"/usr/local/lib/python3.9/site-packages/urllib3/connection.py\", line 239, in request\n    super(HTTPConnection, self).request(method, url, body=body, headers=headers)\n  File \"/usr/lib64/python3.9/http/client.py\", line 1257, in request\n    self._send_request(method, url, body, headers, encode_chunked)\n  File \"/usr/lib64/python3.9/http/client.py\", line 1303, in _send_request\n    self.endheaders(body, encode_chunked=encode_chunked)\n  File \"/usr/lib64/python3.9/http/client.py\", line 1252, in endheaders\n    self._send_output(message_body, encode_chunked=encode_chunked)\n  File \"/usr/lib64/python3.9/http/client.py\", line 1012, in _send_output\n    self.send(msg)\n  File \"/usr/lib64/python3.9/http/client.py\", line 952, in send\n    self.connect()\n  File \"/usr/local/lib/python3.9/site-packages/urllib3/connection.py\", line 205, in connect\n    conn = self._new_conn()\n  File \"/usr/local/lib/python3.9/site-packages/urllib3/connection.py\", line 186, in _new_conn\n    raise NewConnectionError(\nurllib3.exceptions.NewConnectionError: <urllib3.connection.HTTPConnection object at 0x7f102169ab20>: Failed to establish a new connection: [Errno 111] Connection refused\n\nDuring handling of the above exception, another exception occurred:\n\nTraceback (most recent call last):\n  File \"/usr/local/lib/python3.9/site-packages/requests/adapters.py\", line 489, in send\n    resp = conn.urlopen(\n  File \"/usr/local/lib/python3.9/site-packages/urllib3/connectionpool.py\", line 787, in urlopen\n    retries = retries.increment(\n  File \"/usr/local/lib/python3.9/site-packages/urllib3/util/retry.py\", line 592, in increment\n    raise MaxRetryError(_pool, url, error or ResponseError(cause))\nurllib3.exceptions.MaxRetryError: HTTPConnectionPool(host='server-api', port=8001): Max retries exceeded with url: /api/servers?fields=status (Caused by NewConnectionError('<urllib3.connection.HTTPConnection object at 0x7f102169ab20>: Failed to establish a new connection: [Errno 111] Connection refused'))\n\nDuring handling of the above exception, another exception occurred:\n\nTraceback (most recent call last):\n  File \"/src/ericsson/server/monitor/utils.py\", line 61, in get_server_status\n    resp = session.get(server_url + \"?fields=status\", timeout=timeout)\n  File \"/usr/local/lib/python3.9/site-packages/requests/sessions.py\", line 600, in get\n    return self.request(\"GET\", url, **kwargs)\n  File \"/usr/local/lib/python3.9/site-packages/requests/sessions.py\", line 587, in request\n    resp = self.send(prep, **send_kwargs)\n  File \"/usr/local/lib/python3.9/site-packages/requests/sessions.py\", line 701, in send\n    r = adapter.send(request, **kwargs)\n  File \"/usr/local/lib/python3.9/site-packages/requests/adapters.py\", line 565, in send\n    raise ConnectionError(e, request=request)\nrequests.exceptions.ConnectionError: HTTPConnectionPool(host='server-api', port=8001): Max retries exceeded with url: /api/servers?fields=status (Caused by NewConnectionError('<urllib3.connection.HTTPConnection object at 0x7f102169ab20>: Failed to establish a new connection: [Errno 111] Connection refused'))","host":"server-monitor-7f8444fd47-gblcm","pname":"server-monitor","file":{"name":"utils.py","line":66}}
{"time":"2024-02-06T13:29:17.250Z","msg":"Job \"monitor (trigger: interval[0:00:01], next run at: 2024-02-06 13:29:18 UTC)\" raised an exception","pid":1,"tid":139706150938368,"pri":"ERROR","tname":"ThreadPoolExecutor-0_2","subsys":"apscheduler.executors.default","exc_info":"Traceback (most recent call last):\n  File \"/usr/local/lib/python3.9/site-packages/urllib3/connection.py\", line 174, in _new_conn\n    conn = connection.create_connection(\n  File \"/usr/local/lib/python3.9/site-packages/urllib3/util/connection.py\", line 95, in create_connection\n    raise err\n  File \"/usr/local/lib/python3.9/site-packages/urllib3/util/connection.py\", line 85, in create_connection\n    sock.connect(sa)\nConnectionRefusedError: [Errno 111] Connection refused\n\nDuring handling of the above exception, another exception occurred:\n\nTraceback (most recent call last):\n  File \"/usr/local/lib/python3.9/site-packages/urllib3/connectionpool.py\", line 703, in urlopen\n    httplib_response = self._make_request(\n  File \"/usr/local/lib/python3.9/site-packages/urllib3/connectionpool.py\", line 398, in _make_request\n    conn.request(method, url, **httplib_request_kw)\n  File \"/usr/local/lib/python3.9/site-packages/urllib3/connection.py\", line 239, in request\n    super(HTTPConnection, self).request(method, url, body=body, headers=headers)\n  File \"/usr/lib64/python3.9/http/client.py\", line 1257, in request\n    self._send_request(method, url, body, headers, encode_chunked)\n  File \"/usr/lib64/python3.9/http/client.py\", line 1303, in _send_request\n    self.endheaders(body, encode_chunked=encode_chunked)\n  File \"/usr/lib64/python3.9/http/client.py\", line 1252, in endheaders\n    self._send_output(message_body, encode_chunked=encode_chunked)\n  File \"/usr/lib64/python3.9/http/client.py\", line 1012, in _send_output\n    self.send(msg)\n  File \"/usr/lib64/python3.9/http/client.py\", line 952, in send\n    self.connect()\n  File \"/usr/local/lib/python3.9/site-packages/urllib3/connection.py\", line 205, in connect\n    conn = self._new_conn()\n  File \"/usr/local/lib/python3.9/site-packages/urllib3/connection.py\", line 186, in _new_conn\n    raise NewConnectionError(\nurllib3.exceptions.NewConnectionError: <urllib3.connection.HTTPConnection object at 0x7f102169ab20>: Failed to establish a new connection: [Errno 111] Connection refused\n\nDuring handling of the above exception, another exception occurred:\n\nTraceback (most recent call last):\n  File \"/usr/local/lib/python3.9/site-packages/requests/adapters.py\", line 489, in send\n    resp = conn.urlopen(\n  File \"/usr/local/lib/python3.9/site-packages/urllib3/connectionpool.py\", line 787, in urlopen\n    retries = retries.increment(\n  File \"/usr/local/lib/python3.9/site-packages/urllib3/util/retry.py\", line 592, in increment\n    raise MaxRetryError(_pool, url, error or ResponseError(cause))\nurllib3.exceptions.MaxRetryError: HTTPConnectionPool(host='server-api', port=8001): Max retries exceeded with url: /api/servers?fields=status (Caused by NewConnectionError('<urllib3.connection.HTTPConnection object at 0x7f102169ab20>: Failed to establish a new connection: [Errno 111] Connection refused'))\n\nDuring handling of the above exception, another exception occurred:\n\nTraceback (most recent call last):\n  File \"/usr/local/lib/python3.9/site-packages/apscheduler/executors/base.py\", line 125, in run_job\n    retval = job.func(*job.args, **job.kwargs)\n  File \"/src/ericsson/server/monitor/features.py\", line 311, in monitor\n    for server_id, status in get_server_status(session, server_url, timeout=timeout):\n  File \"/src/ericsson/server/monitor/utils.py\", line 61, in get_server_status\n    resp = session.get(server_url + \"?fields=status\", timeout=timeout)\n  File \"/usr/local/lib/python3.9/site-packages/requests/sessions.py\", line 600, in get\n    return self.request(\"GET\", url, **kwargs)\n  File \"/usr/local/lib/python3.9/site-packages/requests/sessions.py\", line 587, in request\n    resp = self.send(prep, **send_kwargs)\n  File \"/usr/local/lib/python3.9/site-packages/requests/sessions.py\", line 701, in send\n    r = adapter.send(request, **kwargs)\n  File \"/usr/local/lib/python3.9/site-packages/requests/adapters.py\", line 565, in send\n    raise ConnectionError(e, request=request)\nrequests.exceptions.ConnectionError: HTTPConnectionPool(host='server-api', port=8001): Max retries exceeded with url: /api/servers?fields=status (Caused by NewConnectionError('<urllib3.connection.HTTPConnection object at 0x7f102169ab20>: Failed to establish a new connection: [Errno 111] Connection refused'))","host":"server-monitor-7f8444fd47-gblcm","pname":"server-monitor","file":{"name":"base.py","line":131}}
{"time":"2024-02-06T13:29:19.211Z","msg":"Execution of job \"monitor (trigger: interval[0:00:01], next run at: 2024-02-06 13:29:19 UTC)\" skipped: maximum number of running instances reached (1)","pid":1,"tid":139706654238464,"pri":"WARN","tname":"APScheduler","subsys":"apscheduler.scheduler","host":"server-monitor-7f8444fd47-gblcm","pname":"server-monitor","file":{"name":"base.py","line":980}}
{"time":"2024-02-06T13:29:19.234Z","msg":"An error occurred while fetching server statuses","pid":1,"tid":139706645845760,"pri":"WARN","tname":"ThreadPoolExecutor-0_0","subsys":"ericsson.server.monitor.utils","exc_info":"Traceback (most recent call last):\n  File \"/usr/local/lib/python3.9/site-packages/urllib3/connection.py\", line 174, in _new_conn\n    conn = connection.create_connection(\n  File \"/usr/local/lib/python3.9/site-packages/urllib3/util/connection.py\", line 95, in create_connection\n    raise err\n  File \"/usr/local/lib/python3.9/site-packages/urllib3/util/connection.py\", line 85, in create_connection\n    sock.connect(sa)\nConnectionRefusedError: [Errno 111] Connection refused\n\nDuring handling of the above exception, another exception occurred:\n\nTraceback (most recent call last):\n  File \"/usr/local/lib/python3.9/site-packages/urllib3/connectionpool.py\", line 703, in urlopen\n    httplib_response = self._make_request(\n  File \"/usr/local/lib/python3.9/site-packages/urllib3/connectionpool.py\", line 398, in _make_request\n    conn.request(method, url, **httplib_request_kw)\n  File \"/usr/local/lib/python3.9/site-packages/urllib3/connection.py\", line 239, in request\n    super(HTTPConnection, self).request(method, url, body=body, headers=headers)\n  File \"/usr/lib64/python3.9/http/client.py\", line 1257, in request\n    self._send_request(method, url, body, headers, encode_chunked)\n  File \"/usr/lib64/python3.9/http/client.py\", line 1303, in _send_request\n    self.endheaders(body, encode_chunked=encode_chunked)\n  File \"/usr/lib64/python3.9/http/client.py\", line 1252, in endheaders\n    self._send_output(message_body, encode_chunked=encode_chunked)\n  File \"/usr/lib64/python3.9/http/client.py\", line 1012, in _send_output\n    self.send(msg)\n  File \"/usr/lib64/python3.9/http/client.py\", line 952, in send\n    self.connect()\n  File \"/usr/local/lib/python3.9/site-packages/urllib3/connection.py\", line 205, in connect\n    conn = self._new_conn()\n  File \"/usr/local/lib/python3.9/site-packages/urllib3/connection.py\", line 186, in _new_conn\n    raise NewConnectionError(\nurllib3.exceptions.NewConnectionError: <urllib3.connection.HTTPConnection object at 0x7f101c2caee0>: Failed to establish a new connection: [Errno 111] Connection refused\n\nDuring handling of the above exception, another exception occurred:\n\nTraceback (most recent call last):\n  File \"/usr/local/lib/python3.9/site-packages/requests/adapters.py\", line 489, in send\n    resp = conn.urlopen(\n  File \"/usr/local/lib/python3.9/site-packages/urllib3/connectionpool.py\", line 787, in urlopen\n    retries = retries.increment(\n  File \"/usr/local/lib/python3.9/site-packages/urllib3/util/retry.py\", line 592, in increment\n    raise MaxRetryError(_pool, url, error or ResponseError(cause))\nurllib3.exceptions.MaxRetryError: HTTPConnectionPool(host='server-api', port=8001): Max retries exceeded with url: /api/servers?fields=status (Caused by NewConnectionError('<urllib3.connection.HTTPConnection object at 0x7f101c2caee0>: Failed to establish a new connection: [Errno 111] Connection refused'))\n\nDuring handling of the above exception, another exception occurred:\n\nTraceback (most recent call last):\n  File \"/src/ericsson/server/monitor/utils.py\", line 61, in get_server_status\n    resp = session.get(server_url + \"?fields=status\", timeout=timeout)\n  File \"/usr/local/lib/python3.9/site-packages/requests/sessions.py\", line 600, in get\n    return self.request(\"GET\", url, **kwargs)\n  File \"/usr/local/lib/python3.9/site-packages/requests/sessions.py\", line 587, in request\n    resp = self.send(prep, **send_kwargs)\n  File \"/usr/local/lib/python3.9/site-packages/requests/sessions.py\", line 701, in send\n    r = adapter.send(request, **kwargs)\n  File \"/usr/local/lib/python3.9/site-packages/requests/adapters.py\", line 565, in send\n    raise ConnectionError(e, request=request)\nrequests.exceptions.ConnectionError: HTTPConnectionPool(host='server-api', port=8001): Max retries exceeded with url: /api/servers?fields=status (Caused by NewConnectionError('<urllib3.connection.HTTPConnection object at 0x7f101c2caee0>: Failed to establish a new connection: [Errno 111] Connection refused'))","host":"server-monitor-7f8444fd47-gblcm","pname":"server-monitor","file":{"name":"utils.py","line":66}}
{"time":"2024-02-06T13:29:19.235Z","msg":"Job \"monitor (trigger: interval[0:00:01], next run at: 2024-02-06 13:29:20 UTC)\" raised an exception","pid":1,"tid":139706645845760,"pri":"ERROR","tname":"ThreadPoolExecutor-0_0","subsys":"apscheduler.executors.default","exc_info":"Traceback (most recent call last):\n  File \"/usr/local/lib/python3.9/site-packages/urllib3/connection.py\", line 174, in _new_conn\n    conn = connection.create_connection(\n  File \"/usr/local/lib/python3.9/site-packages/urllib3/util/connection.py\", line 95, in create_connection\n    raise err\n  File \"/usr/local/lib/python3.9/site-packages/urllib3/util/connection.py\", line 85, in create_connection\n    sock.connect(sa)\nConnectionRefusedError: [Errno 111] Connection refused\n\nDuring handling of the above exception, another exception occurred:\n\nTraceback (most recent call last):\n  File \"/usr/local/lib/python3.9/site-packages/urllib3/connectionpool.py\", line 703, in urlopen\n    httplib_response = self._make_request(\n  File \"/usr/local/lib/python3.9/site-packages/urllib3/connectionpool.py\", line 398, in _make_request\n    conn.request(method, url, **httplib_request_kw)\n  File \"/usr/local/lib/python3.9/site-packages/urllib3/connection.py\", line 239, in request\n    super(HTTPConnection, self).request(method, url, body=body, headers=headers)\n  File \"/usr/lib64/python3.9/http/client.py\", line 1257, in request\n    self._send_request(method, url, body, headers, encode_chunked)\n  File \"/usr/lib64/python3.9/http/client.py\", line 1303, in _send_request\n    self.endheaders(body, encode_chunked=encode_chunked)\n  File \"/usr/lib64/python3.9/http/client.py\", line 1252, in endheaders\n    self._send_output(message_body, encode_chunked=encode_chunked)\n  File \"/usr/lib64/python3.9/http/client.py\", line 1012, in _send_output\n    self.send(msg)\n  File \"/usr/lib64/python3.9/http/client.py\", line 952, in send\n    self.connect()\n  File \"/usr/local/lib/python3.9/site-packages/urllib3/connection.py\", line 205, in connect\n    conn = self._new_conn()\n  File \"/usr/local/lib/python3.9/site-packages/urllib3/connection.py\", line 186, in _new_conn\n    raise NewConnectionError(\nurllib3.exceptions.NewConnectionError: <urllib3.connection.HTTPConnection object at 0x7f101c2caee0>: Failed to establish a new connection: [Errno 111] Connection refused\n\nDuring handling of the above exception, another exception occurred:\n\nTraceback (most recent call last):\n  File \"/usr/local/lib/python3.9/site-packages/requests/adapters.py\", line 489, in send\n    resp = conn.urlopen(\n  File \"/usr/local/lib/python3.9/site-packages/urllib3/connectionpool.py\", line 787, in urlopen\n    retries = retries.increment(\n  File \"/usr/local/lib/python3.9/site-packages/urllib3/util/retry.py\", line 592, in increment\n    raise MaxRetryError(_pool, url, error or ResponseError(cause))\nurllib3.exceptions.MaxRetryError: HTTPConnectionPool(host='server-api', port=8001): Max retries exceeded with url: /api/servers?fields=status (Caused by NewConnectionError('<urllib3.connection.HTTPConnection object at 0x7f101c2caee0>: Failed to establish a new connection: [Errno 111] Connection refused'))\n\nDuring handling of the above exception, another exception occurred:\n\nTraceback (most recent call last):\n  File \"/usr/local/lib/python3.9/site-packages/apscheduler/executors/base.py\", line 125, in run_job\n    retval = job.func(*job.args, **job.kwargs)\n  File \"/src/ericsson/server/monitor/features.py\", line 311, in monitor\n    for server_id, status in get_server_status(session, server_url, timeout=timeout):\n  File \"/src/ericsson/server/monitor/utils.py\", line 61, in get_server_status\n    resp = session.get(server_url + \"?fields=status\", timeout=timeout)\n  File \"/usr/local/lib/python3.9/site-packages/requests/sessions.py\", line 600, in get\n    return self.request(\"GET\", url, **kwargs)\n  File \"/usr/local/lib/python3.9/site-packages/requests/sessions.py\", line 587, in request\n    resp = self.send(prep, **send_kwargs)\n  File \"/usr/local/lib/python3.9/site-packages/requests/sessions.py\", line 701, in send\n    r = adapter.send(request, **kwargs)\n  File \"/usr/local/lib/python3.9/site-packages/requests/adapters.py\", line 565, in send\n    raise ConnectionError(e, request=request)\nrequests.exceptions.ConnectionError: HTTPConnectionPool(host='server-api', port=8001): Max retries exceeded with url: /api/servers?fields=status (Caused by NewConnectionError('<urllib3.connection.HTTPConnection object at 0x7f101c2caee0>: Failed to establish a new connection: [Errno 111] Connection refused'))","host":"server-monitor-7f8444fd47-gblcm","pname":"server-monitor","file":{"name":"base.py","line":131}}
{"time":"2024-02-06T13:29:20.218Z","msg":"An error occurred while fetching server statuses","pid":1,"tid":139706645845760,"pri":"WARN","tname":"ThreadPoolExecutor-0_0","subsys":"ericsson.server.monitor.utils","exc_info":"Traceback (most recent call last):\n  File \"/src/ericsson/server/monitor/utils.py\", line 62, in get_server_status\n    resp.raise_for_status()\n  File \"/usr/local/lib/python3.9/site-packages/requests/models.py\", line 1021, in raise_for_status\n    raise HTTPError(http_error_msg, response=self)\nrequests.exceptions.HTTPError: 503 Server Error: Service Unavailable for url: http://server-api:8001/api/servers?fields=status","host":"server-monitor-7f8444fd47-gblcm","pname":"server-monitor","file":{"name":"utils.py","line":66}}
{"time":"2024-02-06T13:29:20.219Z","msg":"Job \"monitor (trigger: interval[0:00:01], next run at: 2024-02-06 13:29:21 UTC)\" raised an exception","pid":1,"tid":139706645845760,"pri":"ERROR","tname":"ThreadPoolExecutor-0_0","subsys":"apscheduler.executors.default","exc_info":"Traceback (most recent call last):\n  File \"/usr/local/lib/python3.9/site-packages/apscheduler/executors/base.py\", line 125, in run_job\n    retval = job.func(*job.args, **job.kwargs)\n  File \"/src/ericsson/server/monitor/features.py\", line 311, in monitor\n    for server_id, status in get_server_status(session, server_url, timeout=timeout):\n  File \"/src/ericsson/server/monitor/utils.py\", line 62, in get_server_status\n    resp.raise_for_status()\n  File \"/usr/local/lib/python3.9/site-packages/requests/models.py\", line 1021, in raise_for_status\n    raise HTTPError(http_error_msg, response=self)\nrequests.exceptions.HTTPError: 503 Server Error: Service Unavailable for url: http://server-api:8001/api/servers?fields=status","host":"server-monitor-7f8444fd47-gblcm","pname":"server-monitor","file":{"name":"base.py","line":131}}
{"time":"2024-02-06T13:29:21.215Z","msg":"An error occurred while fetching server statuses","pid":1,"tid":139706150938368,"pri":"WARN","tname":"ThreadPoolExecutor-0_2","subsys":"ericsson.server.monitor.utils","exc_info":"Traceback (most recent call last):\n  File \"/src/ericsson/server/monitor/utils.py\", line 62, in get_server_status\n    resp.raise_for_status()\n  File \"/usr/local/lib/python3.9/site-packages/requests/models.py\", line 1021, in raise_for_status\n    raise HTTPError(http_error_msg, response=self)\nrequests.exceptions.HTTPError: 503 Server Error: Service Unavailable for url: http://server-api:8001/api/servers?fields=status","host":"server-monitor-7f8444fd47-gblcm","pname":"server-monitor","file":{"name":"utils.py","line":66}}
{"time":"2024-02-06T13:29:21.216Z","msg":"Job \"monitor (trigger: interval[0:00:01], next run at: 2024-02-06 13:29:22 UTC)\" raised an exception","pid":1,"tid":139706150938368,"pri":"ERROR","tname":"ThreadPoolExecutor-0_2","subsys":"apscheduler.executors.default","exc_info":"Traceback (most recent call last):\n  File \"/usr/local/lib/python3.9/site-packages/apscheduler/executors/base.py\", line 125, in run_job\n    retval = job.func(*job.args, **job.kwargs)\n  File \"/src/ericsson/server/monitor/features.py\", line 311, in monitor\n    for server_id, status in get_server_status(session, server_url, timeout=timeout):\n  File \"/src/ericsson/server/monitor/utils.py\", line 62, in get_server_status\n    resp.raise_for_status()\n  File \"/usr/local/lib/python3.9/site-packages/requests/models.py\", line 1021, in raise_for_status\n    raise HTTPError(http_error_msg, response=self)\nrequests.exceptions.HTTPError: 503 Server Error: Service Unavailable for url: http://server-api:8001/api/servers?fields=status","host":"server-monitor-7f8444fd47-gblcm","pname":"server-monitor","file":{"name":"base.py","line":131}}
{"time":"2024-02-06T13:29:22.216Z","msg":"An error occurred while fetching server statuses","pid":1,"tid":139706645845760,"pri":"WARN","tname":"ThreadPoolExecutor-0_0","subsys":"ericsson.server.monitor.utils","exc_info":"Traceback (most recent call last):\n  File \"/src/ericsson/server/monitor/utils.py\", line 62, in get_server_status\n    resp.raise_for_status()\n  File \"/usr/local/lib/python3.9/site-packages/requests/models.py\", line 1021, in raise_for_status\n    raise HTTPError(http_error_msg, response=self)\nrequests.exceptions.HTTPError: 503 Server Error: Service Unavailable for url: http://server-api:8001/api/servers?fields=status","host":"server-monitor-7f8444fd47-gblcm","pname":"server-monitor","file":{"name":"utils.py","line":66}}
{"time":"2024-02-06T13:29:22.216Z","msg":"Job \"monitor (trigger: interval[0:00:01], next run at: 2024-02-06 13:29:23 UTC)\" raised an exception","pid":1,"tid":139706645845760,"pri":"ERROR","tname":"ThreadPoolExecutor-0_0","subsys":"apscheduler.executors.default","exc_info":"Traceback (most recent call last):\n  File \"/usr/local/lib/python3.9/site-packages/apscheduler/executors/base.py\", line 125, in run_job\n    retval = job.func(*job.args, **job.kwargs)\n  File \"/src/ericsson/server/monitor/features.py\", line 311, in monitor\n    for server_id, status in get_server_status(session, server_url, timeout=timeout):\n  File \"/src/ericsson/server/monitor/utils.py\", line 62, in get_server_status\n    resp.raise_for_status()\n  File \"/usr/local/lib/python3.9/site-packages/requests/models.py\", line 1021, in raise_for_status\n    raise HTTPError(http_error_msg, response=self)\nrequests.exceptions.HTTPError: 503 Server Error: Service Unavailable for url: http://server-api:8001/api/servers?fields=status","host":"server-monitor-7f8444fd47-gblcm","pname":"server-monitor","file":{"name":"base.py","line":131}}
{"time":"2024-02-06T13:29:23.217Z","msg":"An error occurred while fetching server statuses","pid":1,"tid":139706150938368,"pri":"WARN","tname":"ThreadPoolExecutor-0_2","subsys":"ericsson.server.monitor.utils","exc_info":"Traceback (most recent call last):\n  File \"/src/ericsson/server/monitor/utils.py\", line 62, in get_server_status\n    resp.raise_for_status()\n  File \"/usr/local/lib/python3.9/site-packages/requests/models.py\", line 1021, in raise_for_status\n    raise HTTPError(http_error_msg, response=self)\nrequests.exceptions.HTTPError: 503 Server Error: Service Unavailable for url: http://server-api:8001/api/servers?fields=status","host":"server-monitor-7f8444fd47-gblcm","pname":"server-monitor","file":{"name":"utils.py","line":66}}
{"time":"2024-02-06T13:29:23.217Z","msg":"Job \"monitor (trigger: interval[0:00:01], next run at: 2024-02-06 13:29:24 UTC)\" raised an exception","pid":1,"tid":139706150938368,"pri":"ERROR","tname":"ThreadPoolExecutor-0_2","subsys":"apscheduler.executors.default","exc_info":"Traceback (most recent call last):\n  File \"/usr/local/lib/python3.9/site-packages/apscheduler/executors/base.py\", line 125, in run_job\n    retval = job.func(*job.args, **job.kwargs)\n  File \"/src/ericsson/server/monitor/features.py\", line 311, in monitor\n    for server_id, status in get_server_status(session, server_url, timeout=timeout):\n  File \"/src/ericsson/server/monitor/utils.py\", line 62, in get_server_status\n    resp.raise_for_status()\n  File \"/usr/local/lib/python3.9/site-packages/requests/models.py\", line 1021, in raise_for_status\n    raise HTTPError(http_error_msg, response=self)\nrequests.exceptions.HTTPError: 503 Server Error: Service Unavailable for url: http://server-api:8001/api/servers?fields=status","host":"server-monitor-7f8444fd47-gblcm","pname":"server-monitor","file":{"name":"base.py","line":131}}
{"time":"2024-02-06T13:29:24.216Z","msg":"An error occurred while fetching server statuses","pid":1,"tid":139706645845760,"pri":"WARN","tname":"ThreadPoolExecutor-0_0","subsys":"ericsson.server.monitor.utils","exc_info":"Traceback (most recent call last):\n  File \"/src/ericsson/server/monitor/utils.py\", line 62, in get_server_status\n    resp.raise_for_status()\n  File \"/usr/local/lib/python3.9/site-packages/requests/models.py\", line 1021, in raise_for_status\n    raise HTTPError(http_error_msg, response=self)\nrequests.exceptions.HTTPError: 503 Server Error: Service Unavailable for url: http://server-api:8001/api/servers?fields=status","host":"server-monitor-7f8444fd47-gblcm","pname":"server-monitor","file":{"name":"utils.py","line":66}}
{"time":"2024-02-06T13:29:24.217Z","msg":"Job \"monitor (trigger: interval[0:00:01], next run at: 2024-02-06 13:29:25 UTC)\" raised an exception","pid":1,"tid":139706645845760,"pri":"ERROR","tname":"ThreadPoolExecutor-0_0","subsys":"apscheduler.executors.default","exc_info":"Traceback (most recent call last):\n  File \"/usr/local/lib/python3.9/site-packages/apscheduler/executors/base.py\", line 125, in run_job\n    retval = job.func(*job.args, **job.kwargs)\n  File \"/src/ericsson/server/monitor/features.py\", line 311, in monitor\n    for server_id, status in get_server_status(session, server_url, timeout=timeout):\n  File \"/src/ericsson/server/monitor/utils.py\", line 62, in get_server_status\n    resp.raise_for_status()\n  File \"/usr/local/lib/python3.9/site-packages/requests/models.py\", line 1021, in raise_for_status\n    raise HTTPError(http_error_msg, response=self)\nrequests.exceptions.HTTPError: 503 Server Error: Service Unavailable for url: http://server-api:8001/api/servers?fields=status","host":"server-monitor-7f8444fd47-gblcm","pname":"server-monitor","file":{"name":"base.py","line":131}}
{"time":"2024-02-06T13:29:25.215Z","msg":"An error occurred while fetching server statuses","pid":1,"tid":139706159331072,"pri":"WARN","tname":"ThreadPoolExecutor-0_1","subsys":"ericsson.server.monitor.utils","exc_info":"Traceback (most recent call last):\n  File \"/src/ericsson/server/monitor/utils.py\", line 62, in get_server_status\n    resp.raise_for_status()\n  File \"/usr/local/lib/python3.9/site-packages/requests/models.py\", line 1021, in raise_for_status\n    raise HTTPError(http_error_msg, response=self)\nrequests.exceptions.HTTPError: 503 Server Error: Service Unavailable for url: http://server-api:8001/api/servers?fields=status","host":"server-monitor-7f8444fd47-gblcm","pname":"server-monitor","file":{"name":"utils.py","line":66}}
{"time":"2024-02-06T13:29:25.216Z","msg":"Job \"monitor (trigger: interval[0:00:01], next run at: 2024-02-06 13:29:26 UTC)\" raised an exception","pid":1,"tid":139706159331072,"pri":"ERROR","tname":"ThreadPoolExecutor-0_1","subsys":"apscheduler.executors.default","exc_info":"Traceback (most recent call last):\n  File \"/usr/local/lib/python3.9/site-packages/apscheduler/executors/base.py\", line 125, in run_job\n    retval = job.func(*job.args, **job.kwargs)\n  File \"/src/ericsson/server/monitor/features.py\", line 311, in monitor\n    for server_id, status in get_server_status(session, server_url, timeout=timeout):\n  File \"/src/ericsson/server/monitor/utils.py\", line 62, in get_server_status\n    resp.raise_for_status()\n  File \"/usr/local/lib/python3.9/site-packages/requests/models.py\", line 1021, in raise_for_status\n    raise HTTPError(http_error_msg, response=self)\nrequests.exceptions.HTTPError: 503 Server Error: Service Unavailable for url: http://server-api:8001/api/servers?fields=status","host":"server-monitor-7f8444fd47-gblcm","pname":"server-monitor","file":{"name":"base.py","line":131}}
{"time":"2024-02-06T13:29:26.216Z","msg":"An error occurred while fetching server statuses","pid":1,"tid":139706150938368,"pri":"WARN","tname":"ThreadPoolExecutor-0_2","subsys":"ericsson.server.monitor.utils","exc_info":"Traceback (most recent call last):\n  File \"/src/ericsson/server/monitor/utils.py\", line 62, in get_server_status\n    resp.raise_for_status()\n  File \"/usr/local/lib/python3.9/site-packages/requests/models.py\", line 1021, in raise_for_status\n    raise HTTPError(http_error_msg, response=self)\nrequests.exceptions.HTTPError: 503 Server Error: Service Unavailable for url: http://server-api:8001/api/servers?fields=status","host":"server-monitor-7f8444fd47-gblcm","pname":"server-monitor","file":{"name":"utils.py","line":66}}
{"time":"2024-02-06T13:29:26.216Z","msg":"Job \"monitor (trigger: interval[0:00:01], next run at: 2024-02-06 13:29:27 UTC)\" raised an exception","pid":1,"tid":139706150938368,"pri":"ERROR","tname":"ThreadPoolExecutor-0_2","subsys":"apscheduler.executors.default","exc_info":"Traceback (most recent call last):\n  File \"/usr/local/lib/python3.9/site-packages/apscheduler/executors/base.py\", line 125, in run_job\n    retval = job.func(*job.args, **job.kwargs)\n  File \"/src/ericsson/server/monitor/features.py\", line 311, in monitor\n    for server_id, status in get_server_status(session, server_url, timeout=timeout):\n  File \"/src/ericsson/server/monitor/utils.py\", line 62, in get_server_status\n    resp.raise_for_status()\n  File \"/usr/local/lib/python3.9/site-packages/requests/models.py\", line 1021, in raise_for_status\n    raise HTTPError(http_error_msg, response=self)\nrequests.exceptions.HTTPError: 503 Server Error: Service Unavailable for url: http://server-api:8001/api/servers?fields=status","host":"server-monitor-7f8444fd47-gblcm","pname":"server-monitor","file":{"name":"base.py","line":131}}
{"time":"2024-02-06T13:29:27.216Z","msg":"An error occurred while fetching server statuses","pid":1,"tid":139706159331072,"pri":"WARN","tname":"ThreadPoolExecutor-0_1","subsys":"ericsson.server.monitor.utils","exc_info":"Traceback (most recent call last):\n  File \"/src/ericsson/server/monitor/utils.py\", line 62, in get_server_status\n    resp.raise_for_status()\n  File \"/usr/local/lib/python3.9/site-packages/requests/models.py\", line 1021, in raise_for_status\n    raise HTTPError(http_error_msg, response=self)\nrequests.exceptions.HTTPError: 503 Server Error: Service Unavailable for url: http://server-api:8001/api/servers?fields=status","host":"server-monitor-7f8444fd47-gblcm","pname":"server-monitor","file":{"name":"utils.py","line":66}}
{"time":"2024-02-06T13:29:27.216Z","msg":"Job \"monitor (trigger: interval[0:00:01], next run at: 2024-02-06 13:29:28 UTC)\" raised an exception","pid":1,"tid":139706159331072,"pri":"ERROR","tname":"ThreadPoolExecutor-0_1","subsys":"apscheduler.executors.default","exc_info":"Traceback (most recent call last):\n  File \"/usr/local/lib/python3.9/site-packages/apscheduler/executors/base.py\", line 125, in run_job\n    retval = job.func(*job.args, **job.kwargs)\n  File \"/src/ericsson/server/monitor/features.py\", line 311, in monitor\n    for server_id, status in get_server_status(session, server_url, timeout=timeout):\n  File \"/src/ericsson/server/monitor/utils.py\", line 62, in get_server_status\n    resp.raise_for_status()\n  File \"/usr/local/lib/python3.9/site-packages/requests/models.py\", line 1021, in raise_for_status\n    raise HTTPError(http_error_msg, response=self)\nrequests.exceptions.HTTPError: 503 Server Error: Service Unavailable for url: http://server-api:8001/api/servers?fields=status","host":"server-monitor-7f8444fd47-gblcm","pname":"server-monitor","file":{"name":"base.py","line":131}}
{"time":"2024-02-06T13:29:28.216Z","msg":"An error occurred while fetching server statuses","pid":1,"tid":139706150938368,"pri":"WARN","tname":"ThreadPoolExecutor-0_2","subsys":"ericsson.server.monitor.utils","exc_info":"Traceback (most recent call last):\n  File \"/src/ericsson/server/monitor/utils.py\", line 62, in get_server_status\n    resp.raise_for_status()\n  File \"/usr/local/lib/python3.9/site-packages/requests/models.py\", line 1021, in raise_for_status\n    raise HTTPError(http_error_msg, response=self)\nrequests.exceptions.HTTPError: 503 Server Error: Service Unavailable for url: http://server-api:8001/api/servers?fields=status","host":"server-monitor-7f8444fd47-gblcm","pname":"server-monitor","file":{"name":"utils.py","line":66}}
{"time":"2024-02-06T13:29:28.216Z","msg":"Job \"monitor (trigger: interval[0:00:01], next run at: 2024-02-06 13:29:29 UTC)\" raised an exception","pid":1,"tid":139706150938368,"pri":"ERROR","tname":"ThreadPoolExecutor-0_2","subsys":"apscheduler.executors.default","exc_info":"Traceback (most recent call last):\n  File \"/usr/local/lib/python3.9/site-packages/apscheduler/executors/base.py\", line 125, in run_job\n    retval = job.func(*job.args, **job.kwargs)\n  File \"/src/ericsson/server/monitor/features.py\", line 311, in monitor\n    for server_id, status in get_server_status(session, server_url, timeout=timeout):\n  File \"/src/ericsson/server/monitor/utils.py\", line 62, in get_server_status\n    resp.raise_for_status()\n  File \"/usr/local/lib/python3.9/site-packages/requests/models.py\", line 1021, in raise_for_status\n    raise HTTPError(http_error_msg, response=self)\nrequests.exceptions.HTTPError: 503 Server Error: Service Unavailable for url: http://server-api:8001/api/servers?fields=status","host":"server-monitor-7f8444fd47-gblcm","pname":"server-monitor","file":{"name":"base.py","line":131}}
{"time":"2024-02-06T13:29:29.217Z","msg":"An error occurred while fetching server statuses","pid":1,"tid":139706159331072,"pri":"WARN","tname":"ThreadPoolExecutor-0_1","subsys":"ericsson.server.monitor.utils","exc_info":"Traceback (most recent call last):\n  File \"/src/ericsson/server/monitor/utils.py\", line 62, in get_server_status\n    resp.raise_for_status()\n  File \"/usr/local/lib/python3.9/site-packages/requests/models.py\", line 1021, in raise_for_status\n    raise HTTPError(http_error_msg, response=self)\nrequests.exceptions.HTTPError: 503 Server Error: Service Unavailable for url: http://server-api:8001/api/servers?fields=status","host":"server-monitor-7f8444fd47-gblcm","pname":"server-monitor","file":{"name":"utils.py","line":66}}
{"time":"2024-02-06T13:29:29.217Z","msg":"Job \"monitor (trigger: interval[0:00:01], next run at: 2024-02-06 13:29:30 UTC)\" raised an exception","pid":1,"tid":139706159331072,"pri":"ERROR","tname":"ThreadPoolExecutor-0_1","subsys":"apscheduler.executors.default","exc_info":"Traceback (most recent call last):\n  File \"/usr/local/lib/python3.9/site-packages/apscheduler/executors/base.py\", line 125, in run_job\n    retval = job.func(*job.args, **job.kwargs)\n  File \"/src/ericsson/server/monitor/features.py\", line 311, in monitor\n    for server_id, status in get_server_status(session, server_url, timeout=timeout):\n  File \"/src/ericsson/server/monitor/utils.py\", line 62, in get_server_status\n    resp.raise_for_status()\n  File \"/usr/local/lib/python3.9/site-packages/requests/models.py\", line 1021, in raise_for_status\n    raise HTTPError(http_error_msg, response=self)\nrequests.exceptions.HTTPError: 503 Server Error: Service Unavailable for url: http://server-api:8001/api/servers?fields=status","host":"server-monitor-7f8444fd47-gblcm","pname":"server-monitor","file":{"name":"base.py","line":131}}
{"time":"2024-02-06T13:29:30.217Z","msg":"An error occurred while fetching server statuses","pid":1,"tid":139706645845760,"pri":"WARN","tname":"ThreadPoolExecutor-0_0","subsys":"ericsson.server.monitor.utils","exc_info":"Traceback (most recent call last):\n  File \"/src/ericsson/server/monitor/utils.py\", line 62, in get_server_status\n    resp.raise_for_status()\n  File \"/usr/local/lib/python3.9/site-packages/requests/models.py\", line 1021, in raise_for_status\n    raise HTTPError(http_error_msg, response=self)\nrequests.exceptions.HTTPError: 503 Server Error: Service Unavailable for url: http://server-api:8001/api/servers?fields=status","host":"server-monitor-7f8444fd47-gblcm","pname":"server-monitor","file":{"name":"utils.py","line":66}}
{"time":"2024-02-06T13:29:30.217Z","msg":"Job \"monitor (trigger: interval[0:00:01], next run at: 2024-02-06 13:29:31 UTC)\" raised an exception","pid":1,"tid":139706645845760,"pri":"ERROR","tname":"ThreadPoolExecutor-0_0","subsys":"apscheduler.executors.default","exc_info":"Traceback (most recent call last):\n  File \"/usr/local/lib/python3.9/site-packages/apscheduler/executors/base.py\", line 125, in run_job\n    retval = job.func(*job.args, **job.kwargs)\n  File \"/src/ericsson/server/monitor/features.py\", line 311, in monitor\n    for server_id, status in get_server_status(session, server_url, timeout=timeout):\n  File \"/src/ericsson/server/monitor/utils.py\", line 62, in get_server_status\n    resp.raise_for_status()\n  File \"/usr/local/lib/python3.9/site-packages/requests/models.py\", line 1021, in raise_for_status\n    raise HTTPError(http_error_msg, response=self)\nrequests.exceptions.HTTPError: 503 Server Error: Service Unavailable for url: http://server-api:8001/api/servers?fields=status","host":"server-monitor-7f8444fd47-gblcm","pname":"server-monitor","file":{"name":"base.py","line":131}}
{"time":"2024-02-06T13:29:31.217Z","msg":"An error occurred while fetching server statuses","pid":1,"tid":139706150938368,"pri":"WARN","tname":"ThreadPoolExecutor-0_2","subsys":"ericsson.server.monitor.utils","exc_info":"Traceback (most recent call last):\n  File \"/src/ericsson/server/monitor/utils.py\", line 62, in get_server_status\n    resp.raise_for_status()\n  File \"/usr/local/lib/python3.9/site-packages/requests/models.py\", line 1021, in raise_for_status\n    raise HTTPError(http_error_msg, response=self)\nrequests.exceptions.HTTPError: 503 Server Error: Service Unavailable for url: http://server-api:8001/api/servers?fields=status","host":"server-monitor-7f8444fd47-gblcm","pname":"server-monitor","file":{"name":"utils.py","line":66}}
{"time":"2024-02-06T13:29:31.217Z","msg":"Job \"monitor (trigger: interval[0:00:01], next run at: 2024-02-06 13:29:32 UTC)\" raised an exception","pid":1,"tid":139706150938368,"pri":"ERROR","tname":"ThreadPoolExecutor-0_2","subsys":"apscheduler.executors.default","exc_info":"Traceback (most recent call last):\n  File \"/usr/local/lib/python3.9/site-packages/apscheduler/executors/base.py\", line 125, in run_job\n    retval = job.func(*job.args, **job.kwargs)\n  File \"/src/ericsson/server/monitor/features.py\", line 311, in monitor\n    for server_id, status in get_server_status(session, server_url, timeout=timeout):\n  File \"/src/ericsson/server/monitor/utils.py\", line 62, in get_server_status\n    resp.raise_for_status()\n  File \"/usr/local/lib/python3.9/site-packages/requests/models.py\", line 1021, in raise_for_status\n    raise HTTPError(http_error_msg, response=self)\nrequests.exceptions.HTTPError: 503 Server Error: Service Unavailable for url: http://server-api:8001/api/servers?fields=status","host":"server-monitor-7f8444fd47-gblcm","pname":"server-monitor","file":{"name":"base.py","line":131}}
{"time":"2024-02-06T13:29:32.217Z","msg":"An error occurred while fetching server statuses","pid":1,"tid":139706645845760,"pri":"WARN","tname":"ThreadPoolExecutor-0_0","subsys":"ericsson.server.monitor.utils","exc_info":"Traceback (most recent call last):\n  File \"/src/ericsson/server/monitor/utils.py\", line 62, in get_server_status\n    resp.raise_for_status()\n  File \"/usr/local/lib/python3.9/site-packages/requests/models.py\", line 1021, in raise_for_status\n    raise HTTPError(http_error_msg, response=self)\nrequests.exceptions.HTTPError: 503 Server Error: Service Unavailable for url: http://server-api:8001/api/servers?fields=status","host":"server-monitor-7f8444fd47-gblcm","pname":"server-monitor","file":{"name":"utils.py","line":66}}
{"time":"2024-02-06T13:29:32.217Z","msg":"Job \"monitor (trigger: interval[0:00:01], next run at: 2024-02-06 13:29:33 UTC)\" raised an exception","pid":1,"tid":139706645845760,"pri":"ERROR","tname":"ThreadPoolExecutor-0_0","subsys":"apscheduler.executors.default","exc_info":"Traceback (most recent call last):\n  File \"/usr/local/lib/python3.9/site-packages/apscheduler/executors/base.py\", line 125, in run_job\n    retval = job.func(*job.args, **job.kwargs)\n  File \"/src/ericsson/server/monitor/features.py\", line 311, in monitor\n    for server_id, status in get_server_status(session, server_url, timeout=timeout):\n  File \"/src/ericsson/server/monitor/utils.py\", line 62, in get_server_status\n    resp.raise_for_status()\n  File \"/usr/local/lib/python3.9/site-packages/requests/models.py\", line 1021, in raise_for_status\n    raise HTTPError(http_error_msg, response=self)\nrequests.exceptions.HTTPError: 503 Server Error: Service Unavailable for url: http://server-api:8001/api/servers?fields=status","host":"server-monitor-7f8444fd47-gblcm","pname":"server-monitor","file":{"name":"base.py","line":131}}
{"time":"2024-02-06T13:29:33.216Z","msg":"An error occurred while fetching server statuses","pid":1,"tid":139706150938368,"pri":"WARN","tname":"ThreadPoolExecutor-0_2","subsys":"ericsson.server.monitor.utils","exc_info":"Traceback (most recent call last):\n  File \"/src/ericsson/server/monitor/utils.py\", line 62, in get_server_status\n    resp.raise_for_status()\n  File \"/usr/local/lib/python3.9/site-packages/requests/models.py\", line 1021, in raise_for_status\n    raise HTTPError(http_error_msg, response=self)\nrequests.exceptions.HTTPError: 503 Server Error: Service Unavailable for url: http://server-api:8001/api/servers?fields=status","host":"server-monitor-7f8444fd47-gblcm","pname":"server-monitor","file":{"name":"utils.py","line":66}}
{"time":"2024-02-06T13:29:33.217Z","msg":"Job \"monitor (trigger: interval[0:00:01], next run at: 2024-02-06 13:29:34 UTC)\" raised an exception","pid":1,"tid":139706150938368,"pri":"ERROR","tname":"ThreadPoolExecutor-0_2","subsys":"apscheduler.executors.default","exc_info":"Traceback (most recent call last):\n  File \"/usr/local/lib/python3.9/site-packages/apscheduler/executors/base.py\", line 125, in run_job\n    retval = job.func(*job.args, **job.kwargs)\n  File \"/src/ericsson/server/monitor/features.py\", line 311, in monitor\n    for server_id, status in get_server_status(session, server_url, timeout=timeout):\n  File \"/src/ericsson/server/monitor/utils.py\", line 62, in get_server_status\n    resp.raise_for_status()\n  File \"/usr/local/lib/python3.9/site-packages/requests/models.py\", line 1021, in raise_for_status\n    raise HTTPError(http_error_msg, response=self)\nrequests.exceptions.HTTPError: 503 Server Error: Service Unavailable for url: http://server-api:8001/api/servers?fields=status","host":"server-monitor-7f8444fd47-gblcm","pname":"server-monitor","file":{"name":"base.py","line":131}}
{"time":"2024-02-06T13:29:34.216Z","msg":"An error occurred while fetching server statuses","pid":1,"tid":139706645845760,"pri":"WARN","tname":"ThreadPoolExecutor-0_0","subsys":"ericsson.server.monitor.utils","exc_info":"Traceback (most recent call last):\n  File \"/src/ericsson/server/monitor/utils.py\", line 62, in get_server_status\n    resp.raise_for_status()\n  File \"/usr/local/lib/python3.9/site-packages/requests/models.py\", line 1021, in raise_for_status\n    raise HTTPError(http_error_msg, response=self)\nrequests.exceptions.HTTPError: 503 Server Error: Service Unavailable for url: http://server-api:8001/api/servers?fields=status","host":"server-monitor-7f8444fd47-gblcm","pname":"server-monitor","file":{"name":"utils.py","line":66}}
{"time":"2024-02-06T13:29:34.216Z","msg":"Job \"monitor (trigger: interval[0:00:01], next run at: 2024-02-06 13:29:35 UTC)\" raised an exception","pid":1,"tid":139706645845760,"pri":"ERROR","tname":"ThreadPoolExecutor-0_0","subsys":"apscheduler.executors.default","exc_info":"Traceback (most recent call last):\n  File \"/usr/local/lib/python3.9/site-packages/apscheduler/executors/base.py\", line 125, in run_job\n    retval = job.func(*job.args, **job.kwargs)\n  File \"/src/ericsson/server/monitor/features.py\", line 311, in monitor\n    for server_id, status in get_server_status(session, server_url, timeout=timeout):\n  File \"/src/ericsson/server/monitor/utils.py\", line 62, in get_server_status\n    resp.raise_for_status()\n  File \"/usr/local/lib/python3.9/site-packages/requests/models.py\", line 1021, in raise_for_status\n    raise HTTPError(http_error_msg, response=self)\nrequests.exceptions.HTTPError: 503 Server Error: Service Unavailable for url: http://server-api:8001/api/servers?fields=status","host":"server-monitor-7f8444fd47-gblcm","pname":"server-monitor","file":{"name":"base.py","line":131}}
{"time":"2024-02-06T13:29:35.216Z","msg":"An error occurred while fetching server statuses","pid":1,"tid":139706645845760,"pri":"WARN","tname":"ThreadPoolExecutor-0_0","subsys":"ericsson.server.monitor.utils","exc_info":"Traceback (most recent call last):\n  File \"/src/ericsson/server/monitor/utils.py\", line 62, in get_server_status\n    resp.raise_for_status()\n  File \"/usr/local/lib/python3.9/site-packages/requests/models.py\", line 1021, in raise_for_status\n    raise HTTPError(http_error_msg, response=self)\nrequests.exceptions.HTTPError: 503 Server Error: Service Unavailable for url: http://server-api:8001/api/servers?fields=status","host":"server-monitor-7f8444fd47-gblcm","pname":"server-monitor","file":{"name":"utils.py","line":66}}
{"time":"2024-02-06T13:29:35.216Z","msg":"Job \"monitor (trigger: interval[0:00:01], next run at: 2024-02-06 13:29:36 UTC)\" raised an exception","pid":1,"tid":139706645845760,"pri":"ERROR","tname":"ThreadPoolExecutor-0_0","subsys":"apscheduler.executors.default","exc_info":"Traceback (most recent call last):\n  File \"/usr/local/lib/python3.9/site-packages/apscheduler/executors/base.py\", line 125, in run_job\n    retval = job.func(*job.args, **job.kwargs)\n  File \"/src/ericsson/server/monitor/features.py\", line 311, in monitor\n    for server_id, status in get_server_status(session, server_url, timeout=timeout):\n  File \"/src/ericsson/server/monitor/utils.py\", line 62, in get_server_status\n    resp.raise_for_status()\n  File \"/usr/local/lib/python3.9/site-packages/requests/models.py\", line 1021, in raise_for_status\n    raise HTTPError(http_error_msg, response=self)\nrequests.exceptions.HTTPError: 503 Server Error: Service Unavailable for url: http://server-api:8001/api/servers?fields=status","host":"server-monitor-7f8444fd47-gblcm","pname":"server-monitor","file":{"name":"base.py","line":131}}
{"time":"2024-02-06T13:29:36.216Z","msg":"An error occurred while fetching server statuses","pid":1,"tid":139706150938368,"pri":"WARN","tname":"ThreadPoolExecutor-0_2","subsys":"ericsson.server.monitor.utils","exc_info":"Traceback (most recent call last):\n  File \"/src/ericsson/server/monitor/utils.py\", line 62, in get_server_status\n    resp.raise_for_status()\n  File \"/usr/local/lib/python3.9/site-packages/requests/models.py\", line 1021, in raise_for_status\n    raise HTTPError(http_error_msg, response=self)\nrequests.exceptions.HTTPError: 503 Server Error: Service Unavailable for url: http://server-api:8001/api/servers?fields=status","host":"server-monitor-7f8444fd47-gblcm","pname":"server-monitor","file":{"name":"utils.py","line":66}}
{"time":"2024-02-06T13:29:36.216Z","msg":"Job \"monitor (trigger: interval[0:00:01], next run at: 2024-02-06 13:29:37 UTC)\" raised an exception","pid":1,"tid":139706150938368,"pri":"ERROR","tname":"ThreadPoolExecutor-0_2","subsys":"apscheduler.executors.default","exc_info":"Traceback (most recent call last):\n  File \"/usr/local/lib/python3.9/site-packages/apscheduler/executors/base.py\", line 125, in run_job\n    retval = job.func(*job.args, **job.kwargs)\n  File \"/src/ericsson/server/monitor/features.py\", line 311, in monitor\n    for server_id, status in get_server_status(session, server_url, timeout=timeout):\n  File \"/src/ericsson/server/monitor/utils.py\", line 62, in get_server_status\n    resp.raise_for_status()\n  File \"/usr/local/lib/python3.9/site-packages/requests/models.py\", line 1021, in raise_for_status\n    raise HTTPError(http_error_msg, response=self)\nrequests.exceptions.HTTPError: 503 Server Error: Service Unavailable for url: http://server-api:8001/api/servers?fields=status","host":"server-monitor-7f8444fd47-gblcm","pname":"server-monitor","file":{"name":"base.py","line":131}}
{"time":"2024-02-06T13:29:37.216Z","msg":"An error occurred while fetching server statuses","pid":1,"tid":139706645845760,"pri":"WARN","tname":"ThreadPoolExecutor-0_0","subsys":"ericsson.server.monitor.utils","exc_info":"Traceback (most recent call last):\n  File \"/src/ericsson/server/monitor/utils.py\", line 62, in get_server_status\n    resp.raise_for_status()\n  File \"/usr/local/lib/python3.9/site-packages/requests/models.py\", line 1021, in raise_for_status\n    raise HTTPError(http_error_msg, response=self)\nrequests.exceptions.HTTPError: 503 Server Error: Service Unavailable for url: http://server-api:8001/api/servers?fields=status","host":"server-monitor-7f8444fd47-gblcm","pname":"server-monitor","file":{"name":"utils.py","line":66}}
{"time":"2024-02-06T13:29:37.216Z","msg":"Job \"monitor (trigger: interval[0:00:01], next run at: 2024-02-06 13:29:38 UTC)\" raised an exception","pid":1,"tid":139706645845760,"pri":"ERROR","tname":"ThreadPoolExecutor-0_0","subsys":"apscheduler.executors.default","exc_info":"Traceback (most recent call last):\n  File \"/usr/local/lib/python3.9/site-packages/apscheduler/executors/base.py\", line 125, in run_job\n    retval = job.func(*job.args, **job.kwargs)\n  File \"/src/ericsson/server/monitor/features.py\", line 311, in monitor\n    for server_id, status in get_server_status(session, server_url, timeout=timeout):\n  File \"/src/ericsson/server/monitor/utils.py\", line 62, in get_server_status\n    resp.raise_for_status()\n  File \"/usr/local/lib/python3.9/site-packages/requests/models.py\", line 1021, in raise_for_status\n    raise HTTPError(http_error_msg, response=self)\nrequests.exceptions.HTTPError: 503 Server Error: Service Unavailable for url: http://server-api:8001/api/servers?fields=status","host":"server-monitor-7f8444fd47-gblcm","pname":"server-monitor","file":{"name":"base.py","line":131}}
{"time":"2024-02-06T13:29:38.216Z","msg":"An error occurred while fetching server statuses","pid":1,"tid":139706150938368,"pri":"WARN","tname":"ThreadPoolExecutor-0_2","subsys":"ericsson.server.monitor.utils","exc_info":"Traceback (most recent call last):\n  File \"/src/ericsson/server/monitor/utils.py\", line 62, in get_server_status\n    resp.raise_for_status()\n  File \"/usr/local/lib/python3.9/site-packages/requests/models.py\", line 1021, in raise_for_status\n    raise HTTPError(http_error_msg, response=self)\nrequests.exceptions.HTTPError: 503 Server Error: Service Unavailable for url: http://server-api:8001/api/servers?fields=status","host":"server-monitor-7f8444fd47-gblcm","pname":"server-monitor","file":{"name":"utils.py","line":66}}
{"time":"2024-02-06T13:29:38.216Z","msg":"Job \"monitor (trigger: interval[0:00:01], next run at: 2024-02-06 13:29:39 UTC)\" raised an exception","pid":1,"tid":139706150938368,"pri":"ERROR","tname":"ThreadPoolExecutor-0_2","subsys":"apscheduler.executors.default","exc_info":"Traceback (most recent call last):\n  File \"/usr/local/lib/python3.9/site-packages/apscheduler/executors/base.py\", line 125, in run_job\n    retval = job.func(*job.args, **job.kwargs)\n  File \"/src/ericsson/server/monitor/features.py\", line 311, in monitor\n    for server_id, status in get_server_status(session, server_url, timeout=timeout):\n  File \"/src/ericsson/server/monitor/utils.py\", line 62, in get_server_status\n    resp.raise_for_status()\n  File \"/usr/local/lib/python3.9/site-packages/requests/models.py\", line 1021, in raise_for_status\n    raise HTTPError(http_error_msg, response=self)\nrequests.exceptions.HTTPError: 503 Server Error: Service Unavailable for url: http://server-api:8001/api/servers?fields=status","host":"server-monitor-7f8444fd47-gblcm","pname":"server-monitor","file":{"name":"base.py","line":131}}
{"time":"2024-02-06T13:29:39.216Z","msg":"An error occurred while fetching server statuses","pid":1,"tid":139706645845760,"pri":"WARN","tname":"ThreadPoolExecutor-0_0","subsys":"ericsson.server.monitor.utils","exc_info":"Traceback (most recent call last):\n  File \"/src/ericsson/server/monitor/utils.py\", line 62, in get_server_status\n    resp.raise_for_status()\n  File \"/usr/local/lib/python3.9/site-packages/requests/models.py\", line 1021, in raise_for_status\n    raise HTTPError(http_error_msg, response=self)\nrequests.exceptions.HTTPError: 503 Server Error: Service Unavailable for url: http://server-api:8001/api/servers?fields=status","host":"server-monitor-7f8444fd47-gblcm","pname":"server-monitor","file":{"name":"utils.py","line":66}}
{"time":"2024-02-06T13:29:39.216Z","msg":"Job \"monitor (trigger: interval[0:00:01], next run at: 2024-02-06 13:29:40 UTC)\" raised an exception","pid":1,"tid":139706645845760,"pri":"ERROR","tname":"ThreadPoolExecutor-0_0","subsys":"apscheduler.executors.default","exc_info":"Traceback (most recent call last):\n  File \"/usr/local/lib/python3.9/site-packages/apscheduler/executors/base.py\", line 125, in run_job\n    retval = job.func(*job.args, **job.kwargs)\n  File \"/src/ericsson/server/monitor/features.py\", line 311, in monitor\n    for server_id, status in get_server_status(session, server_url, timeout=timeout):\n  File \"/src/ericsson/server/monitor/utils.py\", line 62, in get_server_status\n    resp.raise_for_status()\n  File \"/usr/local/lib/python3.9/site-packages/requests/models.py\", line 1021, in raise_for_status\n    raise HTTPError(http_error_msg, response=self)\nrequests.exceptions.HTTPError: 503 Server Error: Service Unavailable for url: http://server-api:8001/api/servers?fields=status","host":"server-monitor-7f8444fd47-gblcm","pname":"server-monitor","file":{"name":"base.py","line":131}}
